Workbook

Sheet Cover Page
C11: EuroBank
C16: ATTACHMENT 4-H
C18: INVOICE SUMMARY SAMPLE
C19: Attachment to Exhibit 4 (Pricing and Financial Provisions)

Sheet Invoice Summary
B2: All charges are shown in Euro, excluding VAT | D2: Invoice Summary
B4: Supplier | D4: Period | E4: YTD | F4: ESTIMATED EOY
D5: 39172 | E5: =Period | F5: 39447
B7: Category of Services | D7: Base Charges | E7: Base Charges | F7: Base Charges
B8: EUC | D8: ='Base Charge'!H55 | E8: ='Base Charge'!M55 | F8: ='Base Charge'!N55
B9: Service Desk | D9: ='Base Charge'!H62 | E9: ='Base Charge'!M62 | F9: ='Base Charge'!N62
B10: LAN Services | D10: ='Base Charge'!H70 | E10: ='Base Charge'!M70 | F10: ='Base Charge'!N70
B11: Voice Services | D11: ='Base Charge'!H136 | E11: ='Base Charge'!M136 | F11: ='Base Charge'!N136
B12: Server Management | D12: ='Base Charge'!H146 | E12: ='Base Charge'!M146 | F12: ='Base Charge'!N146
B13: 2IM | D13: ='Base Charge'!H151 | E13: ='Base Charge'!M151 | F13: ='Base Charge'!N151
B14: Sub total | D14: =SUM(D8:D13) | E14: =SUM(E8:E13) | F14: =SUM(F8:F13)
B16: Category of Services | D16: ARC/RRC | E16: ARC/RRC | F16: ARC/RRC
B17: EUC | D17: ='Base Charge'!J55 | E17: ='Base Charge'!O55 | F17: ='Base Charge'!P55
B18: Service Desk | D18: ='Base Charge'!J62 | E18: ='Base Charge'!O62 | F18: ='Base Charge'!P62
B19: LAN Services | D19: ='Base Charge'!J70 | E19: ='Base Charge'!O70 | F19: ='Base Charge'!P70
B20: Voice Services | D20: ='Base Charge'!J136 | E20: ='Base Charge'!O136 | F20: ='Base Charge'!P136
B21: Server Management | D21: ='Base Charge'!J146 | E21: ='Base Charge'!O146 | F21: ='Base Charge'!P146
B22: Sub total | D22: =SUM(D17:D21) | E22: =SUM(E17:E21) | F22: =SUM(F17:F21)
B24: Category of Services | D24: Pass Through | E24: Pass Through | F24: Pass Through
B25: EUC | D25: =Passthrough!M55 | E25: =Passthrough!N55 | F25: =Passthrough!O55
B26: Service Desk | D26: =Passthrough!M62 | E26: =Passthrough!N62 | F26: =Passthrough!O62
B27: LAN Services | D27: =Passthrough!M70 | E27: =Passthrough!N70 | F27: =Passthrough!O70
B28: Voice Services | D28: =Passthrough!M136 | E28: =Passthrough!N136 | F28: =Passthrough!O136
B29: Server Management | D29: =Passthrough!M146 | E29: =Passthrough!N146 | F29: =Passthrough!O146
B30: Sub total | D30: =SUM(D25:D29) | E30: =SUM(E25:E29) | F30: =SUM(F25:F29)
B32: Category of Services | D32: Retained Assets | E32: Retained Assets | F32: Retained Assets
B33: EUC | D33: ='Retained Assets'!M55 | E33: ='Retained Assets'!N55 | F33: ='Retained Assets'!O55
B34: Service Desk | D34: ='Retained Assets'!M62 | E34: ='Retained Assets'!N62 | F34: ='Retained Assets'!O62
B35: LAN Services | D35: ='Retained Assets'!M70 | E35: ='Retained Assets'!N70 | F35: ='Retained Assets'!O70
B36: Voice Services | D36: ='Retained Assets'!M136 | E36: ='Retained Assets'!N136 | F36: ='Retained Assets'!O136
B37: Server Management | D37: ='Retained Assets'!M153 | E37: ='Retained Assets'!N153 | F37: ='Retained Assets'!O153
B38: Sub total | D38: =SUM(D33:D37) | E38: =SUM(E33:E37) | F38: =SUM(F33:F37)
B40: Category of Services | D40: Others | E40: Others | F40: Others
B41: Projects | D41: =Project!D59 | E41: =Project!D60 | F41: =Project!D61
B42: T&T | D42: ='T&T'!D52+'T&T'!J52 | E42: ='T&T'!E52+'T&T'!K52 | F42: ='T&T'!F52+'T&T'!L52
B43: Retained Contract | D43: ='Ret.Contract'!L14 | E43: ='Ret.Contract'!M14 | F43: ='Ret.Contract'!N14
B44: Service Level Credit | D44: ='Serv.level.credit'!J19 | E44: ='Serv.level.credit'!K19
B45: Sub total | D45: =SUM(D41:D44) | E45: =SUM(E41:E44) | F45: =SUM(F41:F44)
B47: Adjustments/Corrections | D47: =Adjustment!D21
B49: Grand Total | D49: =D14+D22+D30+D38+D45+D47 | E49: =E14+E22+E30+E38+E45+E47 | F49: =F14+F22+F30+F38+F45+F47

Sheet Base Charge
B2: Invoice details - Base Charge
B3: End User Computing - VendorAOrigin
B5: Medium Service Level | D5: Period: | E5: =Period
B7: Category of Service | C7: Units | D7: Baseline/Volume | E7: Actual Volume | F7: Add./Red. Resource | G7: Price/Unit | H7: Period Base Charge | I7: ARC/RRC Rate | J7: Period ARC/RRC Amount | K7: Period Resource Unit Charge | M7: YTD Base Charge | N7: Forecast EOY Base Charge | O7: YTD ARC/RRC Amount | P7: Forecast EOYARC/RRC Amount | Q7: YTD Resource Unit Charge | R7: Forecast EOY Resource Unit Charge
B8: Standard Desktops (CEDS) | C8: Desktops per location code | F8: =D8-E8 | H8: =D8*G8 | J8: =F8*I8 | K8: =H8+J8
B9: Non-Standard Desktops (non CEDS) | C9: Desktops per location code | F9: =D9-E9 | H9: =D9*G9 | J9: =F9*I9 | K9: =H9+J9
B10: Standard Laptops (CEDS) | C10: Laptops per User | F10: =D10-E10 | H10: =D10*G10 | J10: =F10*I10 | K10: =H10+J10
B11: Non-Standard Laptops (non CEDS) | C11: Laptops per User | F11: =D11-E11 | H11: =D11*G11 | J11: =F11*I11 | K11: =H11+J11
B12: Standard Local Printers | C12: Desktops per location code | F12: =D12-E12 | H12: =D12*G12 | J12: =F12*I12 | K12: =H12+J12
B13: Non-Standard Local Printers | C13: Desktops per location code | F13: =D13-E13 | H13: =D13*G13 | J13: =F13*I13 | K13: =H13+J13
B14: Standard Network Printers | C14: Desktops per location code | F14: =D14-E14 | H14: =D14*G14 | J14: =F14*I14 | K14: =H14+J14
B15: Non-Standard Network Printers | C15: Desktops per location code | F15: =D15-E15 | H15: =D15*G15 | J15: =F15*I15 | K15: =H15+J15
B16: Other Peripherals | C16: Desktops per location code | F16: =D16-E16 | H16: =D16*G16 | J16: =F16*I16 | K16: =H16+J16
C17: Subtotal: | D17: =SUM(D8:D16) | E17: =SUM(E8:E16) | F17: =SUM(F8:F16) | H17: =SUM(H8:H16) | J17: =SUM(J8:J16) | K17: =SUM(K8:K16) | M17: =SUM(M8:M16) | N17: =SUM(N8:N16) | O17: =SUM(O8:O16) | P17: =SUM(P8:P16) | Q17: =SUM(Q8:Q16) | R17: =SUM(R8:R16)
B19: Installations
B21: Category of Service | C21: Units | D21: Baseline/Volume | E21: Actual Volume | F21: Add./Red. Resource | G21: Price/Unit | H21: Period Base Charge | I21: ARC/RRC Rate | J21: Period ARC/RRC Amount | K21: Period Resource Unit Charge | M21: YTD Base Charge | N21: Forecast EOY Base Charge | O21: YTD ARC/RRC Amount | P21: Forecast EOYARC/RRC Amount | Q21: YTD Resource Unit Charge | R21: Forecast EOY Resource Unit Charge
B22: Moves | C22: Desktops per location code | F22: =D22-E22 | H22: =D22*G22 | J22: =F22*I22 | K22: =H22+J22
B23: Adds | C23: Desktops per location code | F23: =D23-E23 | H23: =D23*G23 | J23: =F23*I23 | K23: =H23+J23
B24: Changes | C24: Desktops per location code | F24: =D24-E24 | H24: =D24*G24 | J24: =F24*I24 | K24: =H24+J24
C25: Subtotal: | D25: =SUM(D22:D24) | E25: =SUM(E22:E24) | F25: =SUM(F22:F24) | H25: =SUM(H22:H24) | J25: =SUM(J22:J24) | K25: =SUM(K22:K24) | M25: =SUM(M22:M24) | N25: =SUM(N22:N24) | O25: =SUM(O22:O24) | P25: =SUM(P22:P24) | Q25: =SUM(Q22:Q24) | R25: =SUM(R22:R24)
B27: Low Service Level
B29: Category of Service | C29: Units | D29: Baseline/Volume | E29: Actual Volume | F29: Add./Red. Resource | G29: Price/Unit | H29: Period Base Charge | I29: ARC/RRC Rate | J29: Period ARC/RRC Amount | K29: Period Resource Unit Charge | M29: YTD Base Charge | N29: Forecast EOY Base Charge | O29: YTD ARC/RRC Amount | P29: Forecast EOYARC/RRC Amount | Q29: YTD Resource Unit Charge | R29: Forecast EOY Resource Unit Charge
B30: Standard Desktops (CEDS) | C30: Desktops per location code | F30: =D30-E30 | H30: =D30*G30 | J30: =F30*I30 | K30: =H30+J30
B31: Non-Standard Desktops (non CEDS) | C31: Desktops per location code | F31: =D31-E31 | H31: =D31*G31 | J31: =F31*I31 | K31: =H31+J31
B32: Standard Laptops (CEDS) | C32: Laptops per User | F32: =D32-E32 | H32: =D32*G32 | J32: =F32*I32 | K32: =H32+J32
B33: Non-Standard Laptops (non CEDS) | C33: Laptops per User | F33: =D33-E33 | H33: =D33*G33 | J33: =F33*I33 | K33: =H33+J33
B34: Standard Local Printers | C34: Desktops per location code | F34: =D34-E34 | H34: =D34*G34 | J34: =F34*I34 | K34: =H34+J34
B35: Non-Standard Local Printers | C35: Desktops per location code | F35: =D35-E35 | H35: =D35*G35 | J35: =F35*I35 | K35: =H35+J35
B36: Standard Network Printers | C36: Desktops per location code | F36: =D36-E36 | H36: =D36*G36 | J36: =F36*I36 | K36: =H36+J36
B37: Non-Standard Network Printers | C37: Desktops per location code | F37: =D37-E37 | H37: =D37*G37 | J37: =F37*I37 | K37: =H37+J37
B38: Other Peripherals | C38: Desktops per location code | F38: =D38-E38 | H38: =D38*G38 | J38: =F38*I38 | K38: =H38+J38
C39: Subtotal: | D39: =SUM(D30:D38) | E39: =SUM(E30:E38) | F39: =SUM(F30:F38) | H39: =SUM(H30:H38) | J39: =SUM(J30:J38) | K39: =SUM(K30:K38) | M39: =SUM(M30:M38) | N39: =SUM(N30:N38) | O39: =SUM(O30:O38) | P39: =SUM(P30:P38) | Q39: =SUM(Q30:Q38) | R39: =SUM(R30:R38)
B41: Installations
B43: Category of Service | C43: Units | D43: Baseline/Volume | E43: Actual Volume | F43: Add./Red. Resource | G43: Price/Unit | H43: Period Base Charge | I43: ARC/RRC Rate | J43: Period ARC/RRC Amount | K43: Period Resource Unit Charge | M43: YTD Base Charge | N43: Forecast EOY Base Charge | O43: YTD ARC/RRC Amount | P43: Forecast EOYARC/RRC Amount | Q43: YTD Resource Unit Charge | R43: Forecast EOY Resource Unit Charge
B44: Moves | C44: Desktops per location code | F44: =D44-E44 | H44: =D44*G44 | J44: =F44*I44 | K44: =H44+J44
B45: Adds | C45: Desktops per location code | F45: =D45-E45 | H45: =D45*G45 | J45: =F45*I45 | K45: =H45+J45
B46: Changes | C46: Desktops per location code | F46: =D46-E46 | H46: =D46*G46 | J46: =F46*I46 | K46: =H46+J46
C47: Subtotal: | D47: =SUM(D44:D46) | E47: =SUM(E44:E46) | F47: =SUM(F44:F46) | H47: =SUM(H44:H46) | J47: =SUM(J44:J46) | K47: =SUM(K44:K46) | M47: =SUM(M44:M46) | N47: =SUM(N44:N46) | O47: =SUM(O44:O46) | P47: =SUM(P44:P46) | Q47: =SUM(Q44:Q46) | R47: =SUM(R44:R46)
B49: Packaging & Distribution
B51: Category of Service | C51: Units | D51: Baseline/Volume | E51: Actual Volume | F51: Add./Red. Resource | G51: Price/Unit | H51: Period Base Charge | I51: ARC/RRC Rate | J51: Period ARC/RRC Amount | K51: Period Resource Unit Charge | M51: YTD Base Charge | N51: Forecast EOY Base Charge | O51: YTD ARC/RRC Amount | P51: Forecast EOYARC/RRC Amount | Q51: YTD Resource Unit Charge | R51: Forecast EOY Resource Unit Charge
...

Sheet Passthrough
B2: Invoice details - Passthrough | H2: I = Investment
B3: End User Computing - VendorAOrigin | H3: L = Lease
H4: C = Contract
B5: Medium Service Level | D5: Period: | E5: =Period | H5: D = Direct Expense
B7: Category of Service | C7: Units | D7: Contract code | E7: Supplier | F7: Country | G7: Description | H7: I/L/C/D | I7: Start date | J7: Duration | K7: Volume | L7: Investement/Contract amount | M7: Current month | N7: Ytd | O7: Forecast Year 1 | P7: Forecast Year 2 | Q7: Forecast Year 3 | R7: Forecast Year 4 | S7: Forecast Year 5
B8: Standard Desktops (CEDS) | C8: Desktops per location code
B9: Non-Standard Desktops (non CEDS) | C9: Desktops per location code
B10: Standard Laptops (CEDS) | C10: Laptops per User
B11: Non-Standard Laptops (non CEDS) | C11: Laptops per User
B12: Standard Local Printers | C12: Desktops per location code
B13: Non-Standard Local Printers | C13: Desktops per location code
B14: Standard Network Printers | C14: Desktops per location code
B15: Non-Standard Network Printers | C15: Desktops per location code
B16: Other Peripherals | C16: Desktops per location code
C17: Subtotal: | K17: =SUM(K8:K16) | L17: =SUM(L8:L16) | M17: =SUM(M8:M16) | N17: =SUM(N8:N16) | O17: =SUM(O8:O16) | P17: =SUM(P8:P16) | Q17: =SUM(Q8:Q16) | R17: =SUM(R8:R16) | S17: =SUM(S8:S16)
B19: Installations
B21: Category of Service | C21: Units | D21: Contract code | E21: Supplier | F21: Country | G21: Description | H21: I/L/C/D | I21: Start date | J21: Duration | K21: Volume | L21: Investement/Contract amount | M21: Current month | N21: Ytd | O21: Forecast Year 1 | P21: Forecast Year 2 | Q21: Forecast Year 3 | R21: Forecast Year 4 | S21: Forecast Year 5
B22: Moves | C22: Desktops per location code
B23: Adds | C23: Desktops per location code
B24: Changes | C24: Desktops per location code
C25: Subtotal: | K25: =SUM(K22:K24) | L25: =SUM(L22:L24) | M25: =SUM(M22:M24) | N25: =SUM(N22:N24) | O25: =SUM(O22:O24) | P25: =SUM(P22:P24) | Q25: =SUM(Q22:Q24) | R25: =SUM(R22:R24) | S25: =SUM(S22:S24)
B27: Low Service Level
B29: Category of Service | C29: Units | D29: Contract code | E29: Supplier | F29: Country | G29: Description | H29: I/L/C/D | I29: Start date | J29: Duration | K29: Volume | L29: Investement/Contract amount | M29: Current month | N29: Ytd | O29: Forecast Year 1 | P29: Forecast Year 2 | Q29: Forecast Year 3 | R29: Forecast Year 4 | S29: Forecast Year 5
B30: Standard Desktops (CEDS) | C30: Desktops per location code
B31: Non-Standard Desktops (non CEDS) | C31: Desktops per location code
B32: Standard Laptops (CEDS) | C32: Laptops per User
B33: Non-Standard Laptops (non CEDS) | C33: Laptops per User
B34: Standard Local Printers | C34: Desktops per location code
B35: Non-Standard Local Printers | C35: Desktops per location code
B36: Standard Network Printers | C36: Desktops per location code
B37: Non-Standard Network Printers | C37: Desktops per location code
B38: Other Peripherals | C38: Desktops per location code
C39: Subtotal: | K39: =SUM(K30:K38) | L39: =SUM(L30:L38) | M39: =SUM(M30:M38) | N39: =SUM(N30:N38) | O39: =SUM(O30:O38) | P39: =SUM(P30:P38) | Q39: =SUM(Q30:Q38) | R39: =SUM(R30:R38) | S39: =SUM(S30:S38)
B41: Installations
B43: Category of Service | C43: Units | D43: Contract code | E43: Supplier | F43: Country | G43: Description | H43: I/L/C/D | I43: Start date | J43: Duration | K43: Volume | L43: Investement/Contract amount | M43: Current month | N43: Ytd | O43: Forecast Year 1 | P43: Forecast Year 2 | Q43: Forecast Year 3 | R43: Forecast Year 4 | S43: Forecast Year 5
B44: Moves | C44: Desktops per location code
B45: Adds | C45: Desktops per location code
B46: Changes | C46: Desktops per location code
C47: Subtotal: | K47: =SUM(K44:K46) | L47: =SUM(L44:L46) | M47: =SUM(M44:M46) | N47: =SUM(N44:N46) | O47: =SUM(O44:O46) | P47: =SUM(P44:P46) | Q47: =SUM(Q44:Q46) | R47: =SUM(R44:R46) | S47: =SUM(S44:S46)
B49: Packaging & Distribution
...

Sheet Retained Assets
B2: Invoice details - Asset | H2: I = Investment
B3: End User Computing - VendorAOrigin | H3: L = Lease
H4: C = Contract
B5: Medium Service Level | D5: Period: | E5: Period: | F5: =Period | H5: D = Direct Expense
B7: Category of Service | C7: Units | D7: Contract code | E7: Supplier | F7: Country | G7: Description | H7: I/L/C/D | I7: Start date | J7: Duration | K7: Volume | L7: Investement/Contract amount | M7: Current month | N7: Ytd | O7: Forecast Year 1 | P7: Forecast Year 2 | Q7: Forecast Year 3 | R7: Forecast Year 4 | S7: Forecast Year 5
B8: Standard Desktops (CEDS) | C8: Desktops per location code
B9: Non-Standard Desktops (non CEDS) | C9: Desktops per location code
B10: Standard Laptops (CEDS) | C10: Laptops per User
B11: Non-Standard Laptops (non CEDS) | C11: Laptops per User
B12: Standard Local Printers | C12: Desktops per location code
B13: Non-Standard Local Printers | C13: Desktops per location code
B14: Standard Network Printers | C14: Desktops per location code
B15: Non-Standard Network Printers | C15: Desktops per location code
B16: Other Peripherals | C16: Desktops per location code
C17: Subtotal: | K17: =SUM(K8:K16) | L17: =SUM(L8:L16) | M17: =SUM(M8:M16) | N17: =SUM(N8:N16) | O17: =SUM(O8:O16) | P17: =SUM(P8:P16) | Q17: =SUM(Q8:Q16) | R17: =SUM(R8:R16) | S17: =SUM(S8:S16)
B19: Installations
B21: Category of Service | C21: Units | D21: Contract code | E21: Contract code | F21: Country | G21: Description | H21: I/L/C/D | I21: Start date | J21: Duration | K21: Volume | L21: Investement/Contract amount | M21: Current month | N21: Ytd | O21: Year 1 | P21: Year 2 | Q21: Year 3 | R21: Year 4 | S21: Year 5
B22: Moves | C22: Desktops per location code
B23: Adds | C23: Desktops per location code
B24: Changes | C24: Desktops per location code
C25: Subtotal: | K25: =SUM(K22:K24) | L25: =SUM(L22:L24) | M25: =SUM(M22:M24) | N25: =SUM(N22:N24) | O25: =SUM(O22:O24) | P25: =SUM(P22:P24) | Q25: =SUM(Q22:Q24) | R25: =SUM(R22:R24) | S25: =SUM(S22:S24)
B27: Low Service Level
B29: Category of Service | C29: Units | D29: Contract code | E29: Contract code | F29: Country | G29: Description | H29: I/L/C/D | I29: Start date | J29: Duration | K29: Volume | L29: Investement/Contract amount | M29: Current month | N29: Ytd | O29: Year 1 | P29: Year 2 | Q29: Year 3 | R29: Year 4 | S29: Year 5
B30: Standard Desktops (CEDS) | C30: Desktops per location code
B31: Non-Standard Desktops (non CEDS) | C31: Desktops per location code
B32: Standard Laptops (CEDS) | C32: Laptops per User
B33: Non-Standard Laptops (non CEDS) | C33: Laptops per User
B34: Standard Local Printers | C34: Desktops per location code
B35: Non-Standard Local Printers | C35: Desktops per location code
B36: Standard Network Printers | C36: Desktops per location code
B37: Non-Standard Network Printers | C37: Desktops per location code
B38: Other Peripherals | C38: Desktops per location code
C39: Subtotal: | K39: =SUM(K30:K38) | L39: =SUM(L30:L38) | M39: =SUM(M30:M38) | N39: =SUM(N30:N38) | O39: =SUM(O30:O38) | P39: =SUM(P30:P38) | Q39: =SUM(Q30:Q38) | R39: =SUM(R30:R38) | S39: =SUM(S30:S38)
B41: Installations
B43: Category of Service | C43: Units | D43: Contract code | E43: Contract code | F43: Country | G43: Description | H43: I/L/C/D | I43: Start date | J43: Duration | K43: Volume | L43: Investement/Contract amount | M43: Current month | N43: Ytd | O43: Year 1 | P43: Year 2 | Q43: Year 3 | R43: Year 4 | S43: Year 5
B44: Moves | C44: Desktops per location code
B45: Adds | C45: Desktops per location code
B46: Changes | C46: Desktops per location code
C47: Subtotal: | K47: =SUM(K44:K46) | L47: =SUM(L44:L46) | M47: =SUM(M44:M46) | N47: =SUM(N44:N46) | O47: =SUM(O44:O46) | P47: =SUM(P44:P46) | Q47: =SUM(Q44:Q46) | R47: =SUM(R44:R46) | S47: =SUM(S44:S46)
B49: Packaging & Distribution
...

Sheet Ret.Contract
B2: Invoice details - Retained Contract | D2: Period: | E2: =Period
B4: bundle | C4: Contract code / Ref. No. | D4: Agreement Number | E4: Location (NL/Be) | F4: PST member | G4: Third Party Vendor | H4: Description of Services | I4: Start date | J4: Expiration Date | K4: Contract period | L4: Current month | M4: YTD payment | N4: Forecast Year 1 | O4: Forecast Year 2 | P4: Forecast Year 3 | Q4: Forecast Year 4 | R4: Forecast Year 5 | S4: remarks
B14: Total | H14: =SUM(H5:H13) | I14: =SUM(I5:I13) | J14: =SUM(J5:J13) | K14: =SUM(K5:K13) | L14: =SUM(L5:L13) | M14: =SUM(M5:M13) | N14: =SUM(N5:N13) | O14: =SUM(O5:O13) | ... S14: =SUM(S5:S13)

Sheet Project
B2: Invoice details - Projects
B4: Project Name: | D4: Project1 | F4: Project2 | H4: Project3
B5: Project Description: | D5: Project1 | F5: Project2 | H5: Project3 | J5: Definition | K5: Description | L5: Formula/Value
B6: Infra senior supplier: | J6: % Completion Actual YTD (PCA) | K6: Actual % of project total agreed mandays completed during a given period
B7: Bundle: | J7: % Completion Planned YTD (PCP) | K7: Planned % of physical work completed during a given period
B8: Theme: | J8: Earned Value (EV) | K8: Physical work completed during a given period | L8: PCA*BAC
B9: Sponsor: | J9: Actual Cost YTD (AC) | K9: Total costs incurred in completing work during a given period
B10: Infra senior supplier: | J10: Planned Value YTD (PV) | K10: Physical work scheduled for completion during a given period | L10: PCP*BAC
B11: SAMBA nr: | J11: Cost Variance YTD (CV) | K11: Cost overrun during a given period | L11: EV-AC
B12: Start date: | J12: Schedule Variance YTD (SV) | K12: Schedule slipped during a given period | L12: EV-PV
B13: End date: | J13: Cost Performance Index YTD (CPI) | K13: Cost efficiency ratio | L13: EV/AC
B14: Portfolio Category (SAMBA): | J14: Schedule Performance Index YTD (SPI) | K14: Schedule efficiency ratio | L14: EV/PV
B15: Impact: | J15: Estimate to Completion (ETC) | K15: Expected additional cost needed | L15: EAC-AC
B16: Service Group: | J16: Estimate at Completion (EAC) | K16: Expected total cost | L16: BAC/CPI
B17: Service cluster: | J17: Budget at Completion (BAC) | K17: Baseline project cost
B18: Program/project manager: | J18: Variance at Completion (VAC) | K18: Estimated cost overrun at end of project | L18: BAC-EAC
B19: Project Role: | J19: Status Based on AVG. PI | K19: Average of CPI and SPI | L19: (CPI+SPI)/2
B20: PST supplier - TelCo (Y/N):
B21: PST supplier - Vendor Gamma (Y/N): | J21: Status color key: | K21: Value
B22: PST supplier - VendorA (Y/N): | J22: GREEN = On track | K22: ³1.0
B23: PST supplier 2IM (Y/N): | J23: YELLOW = Slightly behind schedule/budget | K23: ³0.85 but <1.0
B24: Costs part of current bill (Y/N): | J24: RED = Needs immediate attention | K24: <0.85
D26: =Period | F26: =Period | H26: =Period
B28: Actual Cost for thePeriod
B29: % Completion Actual YTD | D29: 0.08 | F29: 0.1 | H29: 0.12
B30: % Completion Planned YTD | D30: 0.1 | F30: 0.1 | H30: 0.1
B31: Earned Value YTD | D31: =D29*D40 | F31: =F29*F40 | H31: =H29*H40
B32: Actual Cost YTD | D32: 140 | F32: 170 | H32: 185
B33: Planned Value YTD | D33: =D30*D40 | F33: =F30*F40 | H33: =H30*H40
B34: Cost Variance YTD | D34: =D31-D32 | F34: =F31-F32 | H34: =H31-H32
B35: Schedule Variance YTD | D35: =D31-D33 | F35: =F31-F33 | H35: =H31-H33
B36: Cost Performance Index YTD | D36: =D31/D32 | F36: =F31/F32 | H36: =H31/H32
B37: Schedule Performance Index YTD | D37: =D31/D33 | F37: =F31/F33 | H37: =H31/H33
B38: Estimate to Completion | D38: =D39-D32 | F38: =F39-F32 | H38: =H39-H32
B39: Estimate at Completion | D39: =D40/D36 | F39: =F40/F36 | H39: =H40/H36
B40: Budget at Completion | D40: =1200 | F40: 1500 | H40: 1750
B41: Variance at Completion (VAC) | D41: =D39-D40 | F41: =F39-F40 | H41: =H39-H40
B42: Status based on Average Performance Index | D42: =(D36+D37)/2 | F42: =(F36+F37)/2 | H42: =(H36+H37)/2
B44: No. of FTE Actual - TelCo
B45: No. of FTE Budget - TelCo
...

Sheet T&T
B2: Invoice details - Transition & Transformation
B4: 2IM | D4: Period | E4: YTD | F4: Forecast | H4: 2IM | J4: Period | K4: YTD | L4: Forecast
D5: =Period | E5: =Period | F5: EOY | J5: =Period | K5: =Period | L5: EOY
B6: 1. Transition Program Management Stream | H6: 1. From As to Be
B7: 2. Service Management Stream | H7: 2. Business Continuity Planning (BCP) / Disaster Recovery
B8: 3. Unit Operations Stream | H8: 3. ITIL (CAP €996.000)
B9: 4. Communications Stream | H9: 4. Security/SAS70 (CAP €1.000.000)
B10: 5. Finance and Contract Management Stream | H10: Programme Management & Programme Management Office Staffing
B11: 6. People Transfer Stream
B12: 7. Knowledge Transfer Stream
B13: TOTAL | D13: =SUM(D6:D12) | E13: =SUM(E6:E12) | F13: =SUM(F6:F12) | H13: TOTAL | J13: =SUM(J6:J12) | K13: =SUM(K6:K12) | L13: =SUM(L6:L12)
B15: Vendor Alpha | D15: Period | E15: YTD | F15: Forecast | H15: Vendor Alpha | J15: Period | K15: YTD | L15: Forecast
D16: =Period | E16: =Period | F16: EOY | J16: =Period | K16: =Period | L16: EOY
B17: 1. Transition Program Management Stream | H17: 1. From As to Be
B18: 2. Service Management Stream | H18: 2. Self Service Portal
B19: 3. Unit Operations Stream | H19: 2. Implement MOM monitoring framework
B20: 4. Communications Stream | H20: 4. Client Deployment Rework
B21: 5. Finance and Contract Management Stream | H21: 5. Integrate Metadirectory with Neptune services
B22: 6. People Transfer Stream | H22: 6. Introduction of Vista
B23: 7. Knowledge Transfer Stream | H23: 7. User Self Restore
B24: Communication Expenses | H24: 8. Distributed File system
B25: Expenses | H25: Expenses
B26: TOTAL | D26: =SUM(D17:D25) | E26: =SUM(E17:E25) | F26: =SUM(F17:F25) | H26: TOTAL | J26: =SUM(J17:J25) | K26: =SUM(K17:K25) | L26: =SUM(L17:L25)
B28: Vendor Gamma | D28: Period | E28: YTD | F28: Forecast | H28: Vendor Gamma | J28: Period | K28: YTD | L28: Forecast
D29: =Period | E29: =Period | F29: EOY | J29: =Period | K29: =Period | L29: EOY
B30: 0. asset management licences | H30: 1. From As to Be
B31: 1. Transition Program Management Stream | H31: 2. Consolidation and Near Shore Service Desk
B32: 2. Service Management Stream
B33: 3. Unit Operations Stream
B34: 4. Communications Stream
B35: 5. Finance and Contract Management Stream
B36: 6. People Transfer Stream
B37: 7. Knowledge Transfer Stream
B38: TOTAL | D38: =SUM(D30:D37) | E38: =SUM(E30:E37) | F38: =SUM(F30:F37) | H38: TOTAL | J38: =SUM(J30:J37) | K38: =SUM(K30:K37) | L38: =SUM(L30:L37)
B41: TelCo | D41: Period | E41: YTD | F41: Forecast | H41: TelCo | J41: Period | K41: YTD | L41: Forecast
D42: =Period | E42: =Period | F42: EOY | J42: =Period | K42: =Period | L42: EOY
B43: 1. Transition Program Management Stream | H43: 1. From As to Be
B44: 2. Service Management Stream | H44: 2. Voice N-1
B45: 3. Unit Operations Stream | H45: 1. From As to Be
B46: 4. Communications Stream | H46: 1. From As to Be
...

Sheet Serv.level.credit
B2: Invoice details - Service Level Credit | D2: Period: | E2: =Period
B4: Critical service level -category | C4: Allocation of Pool Percentage | D4: Eff + mos** | E4: Minimum | F4: SL Measured | G4: Allocation* | H4: % of Invoice | I4: SL Default (Y/N) | J4: SL credit amount | K4: # of SL Defaults YTD | L4: Average SL YTD
B5: Desktop Services Availability - Performance Category
B6: Desktop Services Performance - Performance Category
B7: Access Services Performance - Performance Category
B8: Voice Services Availability - Performance Category
B9: Service Desk Services Availability - Performance Category
B10: Base Service Desk Services Performance - Performance Category
B11: IMAC Services Performance - Performance Category
B12: Incident Services Performance - Performance Category
B13: Integrator Services - Performance Category
B14: Transition & Transformation Plan
B15: Policies & Procedures Including Security
B16: First set of critical report (CSL Reporting)
... B18: Exit Plan Framework
B19: Total | J19: =SUM(J5:J18) | K19: =SUM(K5:K18) | L19: =SUM(L5:L18)

Sheet Adjustment
D2: Period
B3: Invoice details - Adjustments/Corrections | D3: =Period
B5: Adjustments -Description | D5: Amount
B21: Total

Sheet Variables
A1: _Example
A2: _Shading
A3: _Series
A4: _Look
