Workbook

Sheet Cover Page
C11: EuroBank
C16: ATTACHMENT 4-A
C18: PST PRICING FORMS
C19: Attachment to Exhibit 4 (Pricing and Financial Provisions)

Sheet Summary Fees
A1: TOTAL | B1: Category of Services | C1: Year 1 | D1: Year 2 | E1: Year 3 | F1: Year 4 | G1: Year 5 | H1: Total 5 Yr
A2: BASE CHARGES
B3: EUC | C3: =+C49+C95 | D3: =+D49+D95 | E3: =+E49+E95 | F3: =+F49+F95 | G3: =+G49+G95 | H3: =SUM(C3:G3)
B5: Service Desk | C5: =+C51+C97 | D5: =+D51+D97 | E5: =+E51+E97 | F5: =+F51+F97 | G5: =+G51+G97 | H5: =SUM(C5:G5)
B7: LAN Services | C7: =+C53+C99 | D7: =+D53+D99 | E7: =+E53+E99 | F7: =+F53+F99 | G7: =+G53+G99 | H7: =SUM(C7:G7)
B9: Voice Services | C9: =+C55+C101 | D9: =+D55+D101 | E9: =+E55+E101 | F9: =+F55+F101 | G9: =+G55+G101 | H9: =SUM(C9:G9)
B11: Desktop Hardware | C11: =+C57+C103 | D11: =+D57+D103 | E11: =+E57+E103 | F11: =+F57+F103 | G11: =+G57+G103 | H11: =SUM(C11:G11)
B13: Server Management | C13: =+C59+C105 | D13: =+D59+D105 | E13: =+E59+E105 | F13: =+F59+F105 | G13: =+G59+G105 | H13: =SUM(C13:G13)
B15: 2IM | C15: =+C61+C107 | D15: =+D61+D107 | E15: =+E61+E107 | F15: =+F61+F107 | G15: =+G61+G107 | H15: =SUM(C15:G15)
A17: TOTAL BASE CHARGES | C17: =SUM(C3:C15) | D17: =SUM(D3:D15) | E17: =SUM(E3:E15) | F17: =SUM(F3:F15) | G17: =SUM(G3:G15) | H17: =SUM(C17:G17)
A20: PASS THROUGH COSTS
B21: EUC | C21: =+C67+C113 | D21: =+D67+D113 | E21: =+E67+E113 | F21: =+F67+F113 | G21: =+G67+G113 | H21: =SUM(C21:G21)
B23: Service Desk | C23: =+C69+C115 | D23: =+D69+D115 | E23: =+E69+E115 | F23: =+F69+F115 | G23: =+G69+G115 | H23: =SUM(C23:G23)
B25: LAN Services | C25: =+C71+C117 | D25: =+D71+D117 | E25: =+E71+E117 | F25: =+F71+F117 | G25: =+G71+G117 | H25: =SUM(C25:G25)
B27: Voice Services | C27: =+C73+C119 | D27: =+D73+D119 | E27: =+E73+E119 | F27: =+F73+F119 | G27: =+G73+G119 | H27: =SUM(C27:G27)
B29: Desktop Hardware | C29: =+C75+C121 | D29: =+D75+D121 | E29: =+E75+E121 | F29: =+F75+F121 | G29: =+G75+G121 | H29: =SUM(C29:G29)
B31: Server Management | C31: =+C77+C123 | D31: =+D77+D123 | E31: =+E77+E123 | F31: =+F77+F123 | G31: =+G77+G123 | H31: =SUM(C31:G31)
B33: 2IM | C33: =+C79+C125 | D33: =+D79+D125 | E33: =+E79+E125 | F33: =+F79+F125 | G33: =+G79+G125 | H33: =SUM(C33:G33)
A35: TOTAL PASS THROUGH | C35: =SUM(C21:C33) | D35: =SUM(D21:D33) | E35: =SUM(E21:E33) | F35: =SUM(F21:F33) | G35: =SUM(G21:G33) | H35: =SUM(C35:G35)
A38: ONE-TIME CHARGES
B39: Transition | C39: =+C85+C131 | D39: =+D85+D131 | E39: =+E85+E131 | F39: =+F85+F131 | G39: =+G85+G131 | H39: =SUM(C39:G39)
B40: Transformation | C40: =+C86+C132 | D40: =+D86+D132 | E40: =+E86+E132 | F40: =+F86+F132 | G40: =+G86+G132 | H40: =SUM(C40:G40)
B41: BCP/ Sercurity (fixed) | C41: =+C87+C133 | D41: =+D87+D133 | E41: =+E87+E133 | F41: =+F87+F133 | G41: =+G87+G133 | H41: =SUM(C41:G41)
B42: extra one time charges | C42: =+C88+C134 | D42: =+D88+D134 | E42: =+E88+E134 | F42: =+F88+F134 | G42: =+G88+G134 | H42: =SUM(C42:G42)
A43: TOTAL ONE-TIME CHARGES | C43: =SUM(C39:C42) | D43: =SUM(D39:D42) | E43: =SUM(E39:E42) | F43: =SUM(F39:F42) | G43: =SUM(G39:G42) | H43: =SUM(C43:G43)
A45: GRAND TOTAL FEES | C45: =SUM(C17,C35,C43) | D45: =SUM(D17,D35,D43) | E45: =SUM(E17,E35,E43) | F45: =SUM(F17,F35,F43) | G45: =SUM(G17,G35,G43) | H45: =SUM(H17,H35,H43)
A47: NETHERLANDS | B47: Category of Services | C47: Year 1 | D47: Year 2 | E47: Year 3 | F47: Year 4 | G47: Year 5 | H47: Total 5 Yr
A48: BASE CHARGES
B49: EUC | C49: =+'Detailed Base Charges NL'!B36 | D49: =+'Detailed Base Charges NL'!C36 | E49: =+'Detailed Base Charges NL'!D36 | F49: =+'Detailed Base Charges NL'!E36 | G49: =+'Detailed Base Charges NL'!F36 | H49: =SUM(C49:G49)
B51: Service Desk | C51: =+'Detailed Base Charges NL'!B46 | D51: =+'Detailed Base Charges NL'!C46 | E51: =+'Detailed Base Charges NL'!D46 | F51: =+'Detailed Base Charges NL'!E46 | G51: =+'Detailed Base Charges NL'!F46 | H51: =SUM(C51:G51)
B53: LAN Services | C53: =+'Detailed Base Charges NL'!B53 | D53: =+'Detailed Base Charges NL'!C53 | E53: =+'Detailed Base Charges NL'!D53 | F53: =+'Detailed Base Charges NL'!E53 | G53: =+'Detailed Base Charges NL'!F53 | H53: =SUM(C53:G53)
B55: Voice Services | C55: =+'Detailed Base Charges NL'!B113 | D55: =+'Detailed Base Charges NL'!C113 | E55: =+'Detailed Base Charges NL'!D113 | F55: =+'Detailed Base Charges NL'!E113 | G55: =+'Detailed Base Charges NL'!F113 | H55: =SUM(C55:G55)
B57: Desktop Hardware | C57: =+'Detailed Base Charges NL'!B117 | D57: =+'Detailed Base Charges NL'!C117 | E57: =+'Detailed Base Charges NL'!D117 | F57: =+'Detailed Base Charges NL'!E117 | G57: =+'Detailed Base Charges NL'!F117 | H57: =SUM(C57:G57)
B59: Server Management | C59: =+'Detailed Base Charges NL'!B133 | D59: =+'Detailed Base Charges NL'!C133 | E59: =+'Detailed Base Charges NL'!D133 | F59: =+'Detailed Base Charges NL'!E133 | G59: =+'Detailed Base Charges NL'!F133 | H59: =SUM(C59:G59)
B61: 2IM | C61: =+'Detailed Base Charges NL'!B137 | D61: =+'Detailed Base Charges NL'!C137 | E61: =+'Detailed Base Charges NL'!D137 | F61: =+'Detailed Base Charges NL'!E137 | G61: =+'Detailed Base Charges NL'!F137 | H61: =SUM(C61:G61)
A63: TOTAL BASE CHARGES | C63: =SUM(C49:C61) | D63: =SUM(D49:D61) | E63: =SUM(E49:E61) | F63: =SUM(F49:F61) | G63: =SUM(G49:G61) | H63: =SUM(C63:G63)
A66: PASS THROUGH COSTS
B67: EUC | H67: =SUM(C67:G67)
B69: Service Desk | H69: =SUM(C69:G69)
B71: LAN Services | C71: ='Pass Through overview'!H3 | D71: ='Pass Through overview'!I3 | E71: ='Pass Through overview'!J3 | F71: ='Pass Through overview'!K3 | G71: ='Pass Through overview'!L3 | H71: =SUM(C71:G71)
...

Sheet Detailed Base Charges Total
A1: Detailed Base Charges - Total | B1: Year 1 | C1: Year 2 | D1: Year 3 | E1: Year 4 | F1: Year 5 | G1: Total 5 Yr
A2: EUC
A3: Support Services
A4: Medium Service Level
A5: Standard Desktops (CEDS) | B5: =+'Detailed Base Charges NL'!B5+'Detailed Base Charges BE'!B5 | C5: =+'Detailed Base Charges NL'!C5+'Detailed Base Charges BE'!C5 | D5: =+'Detailed Base Charges NL'!D5+'Detailed Base Charges BE'!D5 | E5: =+'Detailed Base Charges NL'!E5+'Detailed Base Charges BE'!E5 | F5: =+'Detailed Base Charges NL'!F5+'Detailed Base Charges BE'!F5 | G5: =SUM(B5:F5)
A6: Non-Standard Desktops (non CEDS) | B6: =+'Detailed Base Charges NL'!B6+'Detailed Base Charges BE'!B6 | C6: =+'Detailed Base Charges NL'!C6+'Detailed Base Charges BE'!C6 | D6: =+'Detailed Base Charges NL'!D6+'Detailed Base Charges BE'!D6 | E6: =+'Detailed Base Charges NL'!E6+'Detailed Base Charges BE'!E6 | F6: =+'Detailed Base Charges NL'!F6+'Detailed Base Charges BE'!F6 | G6: =SUM(B6:F6)
A7: Standard Laptops (CEDS) | B7: =+'Detailed Base Charges NL'!B7+'Detailed Base Charges BE'!B7 | C7: =+'Detailed Base Charges NL'!C7+'Detailed Base Charges BE'!C7 | D7: =+'Detailed Base Charges NL'!D7+'Detailed Base Charges BE'!D7 | E7: =+'Detailed Base Charges NL'!E7+'Detailed Base Charges BE'!E7 | F7: =+'Detailed Base Charges NL'!F7+'Detailed Base Charges BE'!F7 | G7: =SUM(B7:F7)
A8: Non-Standard Laptops (non CEDS) | B8: =+'Detailed Base Charges NL'!B8+'Detailed Base Charges BE'!B8 | C8: =+'Detailed Base Charges NL'!C8+'Detailed Base Charges BE'!C8 | D8: =+'Detailed Base Charges NL'!D8+'Detailed Base Charges BE'!D8 | E8: =+'Detailed Base Charges NL'!E8+'Detailed Base Charges BE'!E8 | F8: =+'Detailed Base Charges NL'!F8+'Detailed Base Charges BE'!F8 | G8: =SUM(B8:F8)
A9: Standard Local Printers | B9: =+'Detailed Base Charges NL'!B9+'Detailed Base Charges BE'!B9 | C9: =+'Detailed Base Charges NL'!C9+'Detailed Base Charges BE'!C9 | D9: =+'Detailed Base Charges NL'!D9+'Detailed Base Charges BE'!D9 | E9: =+'Detailed Base Charges NL'!E9+'Detailed Base Charges BE'!E9 | F9: =+'Detailed Base Charges NL'!F9+'Detailed Base Charges BE'!F9 | G9: =SUM(B9:F9)
A10: Non-Standard Local Printers | B10: =+'Detailed Base Charges NL'!B10+'Detailed Base Charges BE'!B10 | C10: =+'Detailed Base Charges NL'!C10+'Detailed Base Charges BE'!C10 | D10: =+'Detailed Base Charges NL'!D10+'Detailed Base Charges BE'!D10 | E10: =+'Detailed Base Charges NL'!E10+'Detailed Base Charges BE'!E10 | F10: =+'Detailed Base Charges NL'!F10+'Detailed Base Charges BE'!F10 | G10: =SUM(B10:F10)
A11: Standard Network Printers | B11: =+'Detailed Base Charges NL'!B11+'Detailed Base Charges BE'!B11 | C11: =+'Detailed Base Charges NL'!C11+'Detailed Base Charges BE'!C11 | D11: =+'Detailed Base Charges NL'!D11+'Detailed Base Charges BE'!D11 | E11: =+'Detailed Base Charges NL'!E11+'Detailed Base Charges BE'!E11 | F11: =+'Detailed Base Charges NL'!F11+'Detailed Base Charges BE'!F11 | G11: =SUM(B11:F11)
A12: Non-Standard Network Printers | B12: =+'Detailed Base Charges NL'!B12+'Detailed Base Charges BE'!B12 | C12: =+'Detailed Base Charges NL'!C12+'Detailed Base Charges BE'!C12 | D12: =+'Detailed Base Charges NL'!D12+'Detailed Base Charges BE'!D12 | E12: =+'Detailed Base Charges NL'!E12+'Detailed Base Charges BE'!E12 | F12: =+'Detailed Base Charges NL'!F12+'Detailed Base Charges BE'!F12 | G12: =SUM(B12:F12)
A13: Other Peripherals | B13: =+'Detailed Base Charges NL'!B13+'Detailed Base Charges BE'!B13 | C13: =+'Detailed Base Charges NL'!C13+'Detailed Base Charges BE'!C13 | D13: =+'Detailed Base Charges NL'!D13+'Detailed Base Charges BE'!D13 | E13: =+'Detailed Base Charges NL'!E13+'Detailed Base Charges BE'!E13 | F13: =+'Detailed Base Charges NL'!F13+'Detailed Base Charges BE'!F13 | G13: =SUM(B13:F13)
A14: Dealing room support | B14: =+'Detailed Base Charges NL'!B14+'Detailed Base Charges BE'!B14 | C14: =+'Detailed Base Charges NL'!C14+'Detailed Base Charges BE'!C14 | D14: =+'Detailed Base Charges NL'!D14+'Detailed Base Charges BE'!D14 | E14: =+'Detailed Base Charges NL'!E14+'Detailed Base Charges BE'!E14 | F14: =+'Detailed Base Charges NL'!F14+'Detailed Base Charges BE'!F14 | G14: =SUM(B14:F14)
A15: Installations | B15: =+'Detailed Base Charges NL'!B15+'Detailed Base Charges BE'!B15 | C15: =+'Detailed Base Charges NL'!C15+'Detailed Base Charges BE'!C15 | D15: =+'Detailed Base Charges NL'!D15+'Detailed Base Charges BE'!D15 | E15: =+'Detailed Base Charges NL'!E15+'Detailed Base Charges BE'!E15 | F15: =+'Detailed Base Charges NL'!F15+'Detailed Base Charges BE'!F15 | G15: =SUM(B15:F15)
A16: Moves | B16: =+'Detailed Base Charges NL'!B16+'Detailed Base Charges BE'!B16 | C16: =+'Detailed Base Charges NL'!C16+'Detailed Base Charges BE'!C16 | D16: =+'Detailed Base Charges NL'!D16+'Detailed Base Charges BE'!D16 | E16: =+'Detailed Base Charges NL'!E16+'Detailed Base Charges BE'!E16 | F16: =+'Detailed Base Charges NL'!F16+'Detailed Base Charges BE'!F16 | G16: =SUM(B16:F16)
... A18: Changes | B18: =+'Detailed Base Charges NL'!B18+'Detailed Base Charges BE'!B18 | C18: =+'Detailed Base Charges NL'!C18+'Detailed Base Charges BE'!C18 | D18: =+'Detailed Base Charges NL'!D18+'Detailed Base Charges BE'!D18 | E18: =+'Detailed Base Charges NL'!E18+'Detailed Base Charges BE'!E18 | F18: =+'Detailed Base Charges NL'!F18+'Detailed Base Charges BE'!F18 | G18: =SUM(B18:F18)
A19: Low Service Level
A20: Standard Desktops | B20: =+'Detailed Base Charges NL'!B20+'Detailed Base Charges BE'!B20 | C20: =+'Detailed Base Charges NL'!C20+'Detailed Base Charges BE'!C20 | D20: =+'Detailed Base Charges NL'!D20+'Detailed Base Charges BE'!D20 | E20: =+'Detailed Base Charges NL'!E20+'Detailed Base Charges BE'!E20 | F20: =+'Detailed Base Charges NL'!F20+'Detailed Base Charges BE'!F20 | G20: =SUM(B20:F20)
A21: Non-Standard Desktops | B21: =+'Detailed Base Charges NL'!B21+'Detailed Base Charges BE'!B21 | C21: =+'Detailed Base Charges NL'!C21+'Detailed Base Charges BE'!C21 | D21: =+'Detailed Base Charges NL'!D21+'Detailed Base Charges BE'!D21 | E21: =+'Detailed Base Charges NL'!E21+'Detailed Base Charges BE'!E21 | F21: =+'Detailed Base Charges NL'!F21+'Detailed Base Charges BE'!F21 | G21: =SUM(B21:F21)
A22: Standard Laptops | B22: =+'Detailed Base Charges NL'!B22+'Detailed Base Charges BE'!B22 | C22: =+'Detailed Base Charges NL'!C22+'Detailed Base Charges BE'!C22 | D22: =+'Detailed Base Charges NL'!D22+'Detailed Base Charges BE'!D22 | E22: =+'Detailed Base Charges NL'!E22+'Detailed Base Charges BE'!E22 | F22: =+'Detailed Base Charges NL'!F22+'Detailed Base Charges BE'!F22 | G22: =SUM(B22:F22)
A23: Non-Standard Laptops | B23: =+'Detailed Base Charges NL'!B23+'Detailed Base Charges BE'!B23 | C23: =+'Detailed Base Charges NL'!C23+'Detailed Base Charges BE'!C23 | D23: =+'Detailed Base Charges NL'!D23+'Detailed Base Charges BE'!D23 | E23: =+'Detailed Base Charges NL'!E23+'Detailed Base Charges BE'!E23 | F23: =+'Detailed Base Charges NL'!F23+'Detailed Base Charges BE'!F23 | G23: =SUM(B23:F23)
A24: Standard Local Printers | B24: =+'Detailed Base Charges NL'!B24+'Detailed Base Charges BE'!B24 | C24: =+'Detailed Base Charges NL'!C24+'Detailed Base Charges BE'!C24 | D24: =+'Detailed Base Charges NL'!D24+'Detailed Base Charges BE'!D24 | E24: =+'Detailed Base Charges NL'!E24+'Detailed Base Charges BE'!E24 | F24: =+'Detailed Base Charges NL'!F24+'Detailed Base Charges BE'!F24 | G24: =SUM(B24:F24)
A25: Non-Standard Local Printers | B25: =+'Detailed Base Charges NL'!B25+'Detailed Base Charges BE'!B25 | C25: =+'Detailed Base Charges NL'!C25+'Detailed Base Charges BE'!C25 | D25: =+'Detailed Base Charges NL'!D25+'Detailed Base Charges BE'!D25 | E25: =+'Detailed Base Charges NL'!E25+'Detailed Base Charges BE'!E25 | F25: =+'Detailed Base Charges NL'!F25+'Detailed Base Charges BE'!F25 | G25: =SUM(B25:F25)
A26: Standard Network Printers | B26: =+'Detailed Base Charges NL'!B26+'Detailed Base Charges BE'!B26 | C26: =+'Detailed Base Charges NL'!C26+'Detailed Base Charges BE'!C26 | D26: =+'Detailed Base Charges NL'!D26+'Detailed Base Charges BE'!D26 | E26: =+'Detailed Base Charges NL'!E26+'Detailed Base Charges BE'!E26 | F26: =+'Detailed Base Charges NL'!F26+'Detailed Base Charges BE'!F26 | G26: =SUM(B26:F26)
A27: Non-Standard Network Printers | B27: =+'Detailed Base Charges NL'!B27+'Detailed Base Charges BE'!B27 | C27: =+'Detailed Base Charges NL'!C27+'Detailed Base Charges BE'!C27 | D27: =+'Detailed Base Charges NL'!D27+'Detailed Base Charges BE'!D27 | E27: =+'Detailed Base Charges NL'!E27+'Detailed Base Charges BE'!E27 | F27: =+'Detailed Base Charges NL'!F27+'Detailed Base Charges BE'!F27 | G27: =SUM(B27:F27)
A28: Other Peripherals | B28: =+'Detailed Base Charges NL'!B28+'Detailed Base Charges BE'!B28 | C28: =+'Detailed Base Charges NL'!C28+'Detailed Base Charges BE'!C28 | D28: =+'Detailed Base Charges NL'!D28+'Detailed Base Charges BE'!D28 | E28: =+'Detailed Base Charges NL'!E28+'Detailed Base Charges BE'!E28 | F28: =+'Detailed Base Charges NL'!F28+'Detailed Base Charges BE'!F28 | G28: =SUM(B28:F28)
A29: UAS POOL & Secondment of 5 FTE | B29: =+'Detailed Base Charges NL'!B29+'Detailed Base Charges BE'!B29 | C29: =+'Detailed Base Charges NL'!C29+'Detailed Base Charges BE'!C29 | D29: =+'Detailed Base Charges NL'!D29+'Detailed Base Charges BE'!D29 | E29: =+'Detailed Base Charges NL'!E29+'Detailed Base Charges BE'!E29 | F29: =+'Detailed Base Charges NL'!F29+'Detailed Base Charges BE'!F29 | G29: =SUM(B29:F29)
A30: Installations | B30: =+'Detailed Base Charges NL'!B30+'Detailed Base Charges BE'!B30 | C30: =+'Detailed Base Charges NL'!C30+'Detailed Base Charges BE'!C30 | D30: =+'Detailed Base Charges NL'!D30+'Detailed Base Charges BE'!D30 | E30: =+'Detailed Base Charges NL'!E30+'Detailed Base Charges BE'!E30 | F30: =+'Detailed Base Charges NL'!F30+'Detailed Base Charges BE'!F30 | G30: =SUM(B30:F30)
A31: Moves | B31: =+'Detailed Base Charges NL'!B31+'Detailed Base Charges BE'!B31 | C31: =+'Detailed Base Charges NL'!C31+'Detailed Base Charges BE'!C31 | D31: =+'Detailed Base Charges NL'!D31+'Detailed Base Charges BE'!D31 | E31: =+'Detailed Base Charges NL'!E31+'Detailed Base Charges BE'!E31 | F31: =+'Detailed Base Charges NL'!F31+'Detailed Base Charges BE'!F31 | G31: =SUM(B31:F31)
... A33: Changes | B33: =+'Detailed Base Charges NL'!B33+'Detailed Base Charges BE'!B33 | C33: =+'Detailed Base Charges NL'!C33+'Detailed Base Charges BE'!C33 | D33: =+'Detailed Base Charges NL'!D33+'Detailed Base Charges BE'!D33 | E33: =+'Detailed Base Charges NL'!E33+'Detailed Base Charges BE'!E33 | F33: =+'Detailed Base Charges NL'!F33+'Detailed Base Charges BE'!F33 | G33: =SUM(B33:F33)
A34: Packaging & Distribution | B34: =+'Detailed Base Charges NL'!B34+'Detailed Base Charges BE'!B34 | C34: =+'Detailed Base Charges NL'!C34+'Detailed Base Charges BE'!C34 | G34: =SUM(B34:F34) | H34: Row used for PST reimbursement for use of EuroBank facilities
A35: Packages Distributed per year | B35: =+'Detailed Base Charges NL'!B35+'Detailed Base Charges BE'!B35 | C35: =+'Detailed Base Charges NL'!C35+'Detailed Base Charges BE'!C35 | D35: =+'Detailed Base Charges NL'!D35+'Detailed Base Charges BE'!D35 | E35: =+'Detailed Base Charges NL'!E35+'Detailed Base Charges BE'!E35 | F35: =+'Detailed Base Charges NL'!F35+'Detailed Base Charges BE'!F35 | G35: =SUM(B35:F35)
A36: TOTAL EUC | B36: =SUM(B5:B35) | C36: =SUM(C5:C35) | D36: =SUM(D5:D35) | E36: =SUM(E5:E35) | F36: =SUM(F5:F35) | G36: =SUM(B36:F36)
A37: Service Desk
A38: Seats | B38: =+'Detailed Base Charges NL'!B38+'Detailed Base Charges BE'!B38 | C38: =+'Detailed Base Charges NL'!C38+'Detailed Base Charges BE'!C38 | D38: =+'Detailed Base Charges NL'!D38+'Detailed Base Charges BE'!D38 | E38: =+'Detailed Base Charges NL'!E38+'Detailed Base Charges BE'!E38 | F38: =+'Detailed Base Charges NL'!F38+'Detailed Base Charges BE'!F38 | G38: =SUM(B38:F38)
G39: =SUM(B39:F39)
G40: =SUM(B40:F40)
G41: =SUM(B41:F41)
G42: =SUM(B42:F42)
...

Sheet Detailed Base Charges NL
A1: Detailed Base Charges - Netherlands | B1: Year 1 | C1: Year 2 | D1: Year 3 | E1: Year 4 | F1: Year 5 | G1: Total 5 Yr
A2: EUC
A3: Support Services
A4: Medium Service Level
A5: Standard Desktops (CEDS) | B5: 2686580.3 | C5: 2431515.9 | D5: 2256759.5 | E5: 2145688.7 | F5: 2066173 | G5: =SUM(B5:F5)
A6: Non-Standard Desktops (non CEDS) | B6: 28967.187 | C6: 26495.484 | D6: 24910.421 | E6: 23855.469 | F6: 23124.263 | G6: =SUM(B6:F6)
A7: Standard Laptops (CEDS) | B7: 738801.52 | C7: 681619.43 | D7: 647554.65 | E7: 625277.62 | F7: 608398.36 | G7: =SUM(B7:F7)
A8: Non-Standard Laptops (non CEDS) | G8: =SUM(B8:F8)
A9: Standard Local Printers | B9: 325875.74 | C9: 320921.91 | D9: 327682.86 | E9: 328432.65 | F9: 330064.73 | G9: =SUM(B9:F9)
A10: Non-Standard Local Printers | G10: =SUM(B10:F10)
A11: Standard Network Printers | G11: =SUM(B11:F11)
A12: Non-Standard Network Printers | G12: =SUM(B12:F12)
A13: Other Peripherals | G13: =SUM(B13:F13)
A14: Dealing room support | B14: =6*90000 | C14: =6*90000 | D14: =6*90000 | E14: =6*90000 | F14: =6*90000 | G14: =SUM(B14:F14)
A15: Installations | B15: 424279.59 | C15: 328394.49 | D15: 336723.18 | E15: 336713.61 | F15: 339817.95 | G15: =SUM(B15:F15)
A16: Moves | B16: 118251.38 | C16: 119512.42 | D16: 125117.57 | E16: 123696.24 | F16: 127443.81 | G16: =SUM(B16:F16)
A17: Adds | B17: 35204.572 | C17: 34780.957 | D17: 35626.293 | E17: 35645.534 | F17: 35936.924 | G17: =SUM(B17:F17)
A18: Changes | B18: 41387.983 | C18: 41829.348 | D18: 43791.148 | E18: 43293.685 | F18: 44605.334 | G18: =SUM(B18:F18)
A19: Low Service Level
A20: Standard Desktops | B20: 7469082.9 | C20: 6721280.1 | D20: 6194069.4 | E20: 5870452.5 | F20: 5629150.6 | G20: =SUM(B20:F20)
A21: Non-Standard Desktops | B21: 136694.53 | C21: 124335.46 | D21: 116113.15 | E21: 110888.48 | F21: 107063.44 | G21: =SUM(B21:F21)
A22: Standard Laptops | B22: 712664.63 | C22: 654316.35 | D22: 618046.2 | E22: 595316.76 | F22: 577376.47 | G22: =SUM(B22:F22)
A23: Non-Standard Laptops | B23: 38985.382 | C23: 36254.538 | D23: 34767.222 | E23: 33794.476 | F23: 33003.218 | G23: =SUM(B23:F23)
A24: Standard Local Printers | B24: 71349.611 | C24: 70209.228 | D24: 71632.066 | E24: 71827.099 | F24: 72126.919 | G24: =SUM(B24:F24)
A25: Non-Standard Local Printers | B25: 102905.81 | C25: 101425.88 | D25: 103647.84 | E25: 103837.88 | F25: 104440.34 | G25: =SUM(B25:F25)
A26: Standard Network Printers | B26: 588318.44 | C26: 562295.52 | D26: 546416.32 | E26: 547568.26 | F26: 547772.78 | G26: =SUM(B26:F26)
A27: Non-Standard Network Printers | B27: 113376.08 | C27: 110208.76 | D27: 110362.51 | E27: 110768.17 | F27: 110854.88 | G27: =SUM(B27:F27)
A28: Other Peripherals | B28: 280600.14 | C28: 274818.76 | D28: 279078.42 | E28: 280563.25 | F28: 280404.86 | G28: =SUM(B28:F28)
A29: UAS POOL | B29: 3750000 | C29: 3750000 | D29: 3750000 | E29: 3750000 | F29: 3750000 | G29: =SUM(B29:F29)
A30: Installations | B30: 397668.18 | C30: 402766.57 | D30: 407892.63 | E30: 405053.17 | F30: 410256.98 | G30: =SUM(B30:F30)
A31: Moves | B31: 500734.38 | C31: 518260.09 | D31: 535880.93 | E31: 526120.27 | F31: 544008.36 | G31: =SUM(B31:F31)
A32: Adds | G32: =SUM(B32:F32)
A33: Changes | B33: 141116.05 | C33: 146055.12 | D33: 151020.99 | E33: 148270.26 | F33: 153311.45 | G33: =SUM(B33:F33)
A34: Packaging & Distribution | B34: =SUM(Facilities!D44,Facilities!D46,Facilities!D48) | C34: =SUM(Facilities!E44,Facilities!E46,Facilities!E48) | G34: =SUM(B34:F34) | H34: Row used for PST reimbursement for use of EuroBank facilities
A35: Packaging | B35: 922016.77 | C35: 921891.98 | D35: 917027.32 | E35: 912162.65 | F35: 920481.65 | G35: =SUM(B35:F35)
A36: TOTAL EUC | B36: =SUM(B5:B35) | C36: =SUM(C5:C35) | D36: =SUM(D5:D35) | E36: =SUM(E5:E35) | F36: =SUM(F5:F35) | G36: =SUM(B36:F36)
A37: Service Desk
A38: Seats | B38: 7602704.5 | C38: 7303292.9 | D38: 5662512.3 | E38: 4262523.4 | F38: 3863518.2 | G38: =SUM(B38:F38)
G39: =SUM(B39:F39)
G40: =SUM(B40:F40)
...

Sheet Detailed Base Charges BE
A1: Detailed Base Charges - Belgium | B1: Year 1 | C1: Year 2 | D1: Year 3 | E1: Year 4 | F1: Year 5 | G1: Total 5 Yr
A2: EUC
A3: Support Services
A4: Medium Service Level
A5: Standard Desktops (CEDS) | B5: 1055346.8 | C5: 1254087 | D5: 1121541 | E5: 1059318.6 | F5: 996578.1 | G5: =SUM(B5:F5)
A6: Non-Standard Desktops (non CEDS) | G6: =SUM(B6:F6)
A7: Standard Laptops (CEDS) | B7: 219999.86 | C7: 302976.32 | D7: 282586.31 | E7: 271739.73 | F7: 260929.55 | G7: =SUM(B7:F7)
A8: Non-Standard Laptops (non CEDS) | G8: =SUM(B8:F8)
A9: Standard Local Printers | B9: 153322.63 | C9: 462410.34 | D9: 454236.1 | E9: 448547.75 | F9: 438282.12 | G9: =SUM(B9:F9)
A10: Non-Standard Local Printers | G10: =SUM(B10:F10)
A11: Standard Network Printers | B11: 24490.295 | C11: 73845.554 | D11: 72829.524 | E11: 71966.601 | F11: 70604.96 | G11: =SUM(B11:F11)
A12: Non-Standard Network Printers | B12: 9852.5579 | C12: 29688.703 | D12: 29516.845 | E12: 29190.478 | F12: 28733.282 | G12: =SUM(B12:F12)
A13: Other Peripherals | G13: =SUM(B13:F13)
A14: Dealing room support | B14: =8*90000 | C14: =8*90000 | D14: =8*90000 | E14: =8*90000 | F14: =8*90000 | G14: =SUM(B14:F14)
A15: Installations | B15: 58096.401 | C15: 177612.12 | D15: 184560.57 | E15: 181456.99 | F15: 184199.69 | G15: =SUM(B15:F15)
A16: Moves | B16: 39457.95 | C16: 122794.25 | D16: 129784.99 | E16: 126439.93 | F16: 130534.06 | G16: =SUM(B16:F16)
A17: Adds | G17: =SUM(B17:F17)
A18: Changes | B18: 32693.73 | C18: 101743.8 | D18: 107536.14 | E18: 104764.51 | F18: 108156.79 | G18: =SUM(B18:F18)
A19: Low Service Level
A20: Standard Desktops | B20: 2382792.8 | C20: 2746253.2 | D20: 2461138 | E20: 2321270 | F20: 2185816.3 | G20: =SUM(B20:F20)
A21: Non-Standard Desktops | G21: =SUM(B21:F21)
A22: Standard Laptops | B22: 260168.32 | C22: 345669.56 | D22: 324284.38 | E22: 312304.91 | F22: 300903.59 | G22: =SUM(B22:F22)
A23: Non-Standard Laptops | G23: =SUM(B23:F23)
A24: Standard Local Printers | B24: 320061.2 | C24: 964786.87 | D24: 954226.31 | E24: 943029.49 | F24: 924969.74 | G24: =SUM(B24:F24)
A25: Non-Standard Local Printers | G25: =SUM(B25:F25)
A26: Standard Network Printers | B26: 86155.428 | C26: 181471.29 | D26: 167111.64 | E26: 165069.65 | F26: 162005.32 | G26: =SUM(B26:F26)
A27: Non-Standard Network Printers | B27: 23236.467 | C27: 64917.637 | D27: 64022.573 | E27: 63340.076 | F27: 62486.195 | G27: =SUM(B27:F27)
A28: Other Peripherals | G28: =SUM(B28:F28)
A29: Secondment of 5 FTE | B29: =560000/12*8 | G29: =SUM(B29:F29) | H29: Delivery of capacity of 5 named FTEs to EuroBank in order to monitor EuroBank Technics and AMSIT contracts on behalf of EuroBank during the period from commencement date until the date the in scope activities of AMSIT and INGTechnics will be taken over by Neptune (planned 11/01/07)
A30: Installations | B30: 87404.831 | C30: 266610.3 | D30: 271029.97 | E30: 268622.13 | F30: 273110.2 | G30: =SUM(B30:F30)
A31: Moves | B31: 59363.669 | C31: 184324.19 | D31: 190591.21 | E31: 187176.93 | F31: 193540.95 | G31: =SUM(B31:F31)
A32: Adds | G32: =SUM(B32:F32)
A33: Changes | B33: 49187.04 | C33: 152725.76 | D33: 157918.43 | E33: 155089.46 | F33: 160362.5 | G33: =SUM(B33:F33)
A34: Packaging & Distribution | B34: =SUM(Facilities!D45,Facilities!D47,Facilities!D49) | C34: =SUM(Facilities!E45,Facilities!E47,Facilities!E49) | G34: =SUM(B34:F34) | H34: Row used for PST reimbursement for use of EuroBank facilities
A35: Packaging | B35: 951790.23 | C35: 931495.02 | D35: 926579.68 | E35: 921664.35 | F35: 930070.01 | G35: =SUM(B35:F35)
A36: TOTAL EUC | B36: =SUM(B5:B35) | C36: =SUM(C5:C35) | D36: =SUM(D5:D35) | E36: =SUM(E5:E35) | F36: =SUM(F5:F35) | G36: =SUM(B36:F36)
A37: Service Desk
A38: Seats | B38: 1246672.5 | C38: 3503392.6 | D38: 2431876.9 | E38: 1905817 | F38: 1520623 | G38: =SUM(B38:F38)
G39: =SUM(B39:F39)
G40: =SUM(B40:F40)
...

Sheet Unit Rates (ARCs & RRCs) NL
A1: ARC'S & RRC'S - NETHERLANDS | B1: Year 1 ARC/RRC | C1: Year 2 ARC/RRC | D1: Year 3 ARC/RRC | E1: Year 4 ARC/RRC | F1: Year 5 ARC/RRC | G1: Resource Unit
A2: EUC
A3: Support Services
A4: Medium Service Level
A5: Standard Desktops (CEDS) | B5: 19.490122 | C5: 17.59544 | D5: 16.191966 | E5: 15.300583 | F5: 14.688882 | G5: per device per month
A6: Non-Standard Desktops (non CEDS) | B6: 22.025331 | C6: 20.083991 | D6: 18.685199 | E6: 17.759803 | F6: 17.155347 | G6: per device per month
A7: Standard Laptops (CEDS) | B7: 25.485917 | C7: 23.429118 | D7: 21.985615 | E7: 21.042926 | F7: 20.397432 | G7: per device per month
A8: Non-Standard Laptops (non CEDS)
A9: Standard Local Printers | B9: 12.218789 | C9: 11.96203 | D9: 11.953119 | E9: 11.807138 | F9: 11.81069 | G9: per device per month
A10: Non-Standard Local Printers
A11: Standard Network Printers
A12: Non-Standard Network Printers
A13: Other Peripherals
A15: Installations | B15: 184.46939 | C15: 143.8452 | D15: 145.67594 | E15: 144.66185 | F15: 146.52035 | G15: per installation
A16: Moves | B16: 59.12569 | C16: 47.114553 | D16: 48.716448 | E16: 47.829116 | F16: 49.455306 | G16: per move
A17: Adds | B17: 176.02286 | C17: 137.11455 | D17: 138.71645 | E17: 137.82912 | F17: 139.45531 | G17: per add
A18: Changes | B18: 59.12569 | C18: 47.114553 | D18: 48.716448 | E18: 47.829116 | F18: 49.455306 | G18: per change
A19: Low Service Level
A20: Standard Desktops (CEDS) | B20: 18.48514 | C20: 16.597617 | D20: 15.181099 | E20: 14.309577 | F20: 13.683852 | G20: per device per month
A21: Non-Standard Desktops (non CEDS) | B21: 20.804274 | C21: 18.870059 | D21: 17.453864 | E21: 16.553486 | F21: 15.930443 | G21: per device per month
A22: Standard Laptops (CEDS) | B22: 23.991999 | C22: 21.953578 | D22: 20.498319 | E22: 19.580801 | F22: 18.92207 | G22: per device per month
A23: Non-Standard Laptops (non CEDS) | B23: 29.538024 | C23: 27.359163 | D23: 25.876268 | E23: 24.90594 | F23: 24.225311 | G23: per device per month
A24: Standard Local Printers | B24: 10.374503 | C24: 10.148439 | D24: 10.132918 | E24: 10.013506 | F24: 10.008594 | G24: per device per month
A25: Non-Standard Local Printers | B25: 11.22217 | C25: 10.995503 | D25: 10.996351 | E25: 10.857128 | F25: 10.869391 | G25: per device per month
A26: Standard Network Printers | B26: 13.247286 | C26: 12.586341 | D26: 11.966514 | E26: 11.825331 | F26: 11.775327 | G26: per device per month
A27: Non-Standard Network Printers | B27: 19.800048 | C27: 19.132895 | D27: 18.748176 | E27: 18.548554 | F27: 18.477114 | G27: per device per month
A28: Other Peripherals | B28: 35.070566 | C28: 34.145279 | D28: 33.933803 | E28: 33.620786 | F28: 33.445712 | G28: per device per month
A30: Installations | B30: 142.02435 | C30: 143.8452 | D30: 145.67594 | E30: 144.66185 | F30: 146.52035 | G30: per installation
A31: Moves | B31: 45.521308 | C31: 47.114553 | D31: 48.716448 | E31: 47.829116 | F31: 49.455306 | G31: per move
A32: Adds | G32: per add
A33: Changes | B33: 45.521308 | C33: 47.114553 | D33: 48.716448 | E33: 47.829116 | F33: 49.455306 | G33: per change
A34: Packaging & Distribution
A35: Packaging | B35: 883.59941 | C35: 883.47981 | D35: 878.81784 | E35: 874.15588 | F35: 882.12825 | G35: per package
A36: TOTAL EUC
A37: Service Desk
A38: Seats Supported
A39: Price per seat | B39: 16.612705 | C39: 15.958459 | D39: 12.373182 | E39: 9.3140595 | F39: 8.4421914 | G39: per seat per month
A47: TOTAL SERVICE DESK (seats supported)
A48: LAN Services
A49: Support Services
...

Sheet Unit Rates (ARCs & RRCs) BE
A1: ARC'S & RRC'S - BELGIUM | B1: Year 1 ARC/RRC | C1: Year 2 ARC/RRC | D1: Year 3 ARC/RRC | E1: Year 4 ARC/RRC | F1: Year 5 ARC/RRC | G1: Resource Unit
A2: EUC
A3: Support Services
A4: Medium Service Level
A5: Standard Desktops (CEDS) | B5: 15.40611 | C5: 18.253015 | D5: 16.211472 | E5: 15.217466 | F5: 14.289316 | G5: per device per month
A6: Non-Standard Desktops (non CEDS)
A7: Standard Laptops (CEDS) | B7: 19.664698 | C7: 26.982629 | D7: 24.936186 | E7: 23.789231 | F7: 22.788477 | G7: per device per month
A8: Non-Standard Laptops (non CEDS)
A9: Standard Local Printers | B9: 4.669959 | C9: 14.049031 | D9: 13.568072 | E9: 13.211122 | F9: 12.861905 | G9: per device per month
A10: Non-Standard Local Printers
A11: Standard Network Printers | B11: 5.1851812 | C11: 15.595752 | D11: 15.121925 | E11: 14.734152 | F11: 14.402898 | G11: per device per month
A12: Non-Standard Network Printers | B12: 8.0524941 | C12: 24.203863 | D12: 23.658164 | E12: 23.069961 | F12: 22.626189 | G12: per device per month
A13: Other Peripherals
A15: Installations | B15: 233.09434 | C15: 236.94409 | D15: 242.0638 | E15: 234.67087 | F15: 237.35309 | G15: per installation
A16: Moves | B16: 99.511129 | C16: 102.96887 | D16: 106.99662 | E16: 102.78373 | F16: 105.72665 | G16: per move
A17: Adds
A18: Changes | B18: 99.511129 | C18: 102.96887 | D18: 106.99662 | E18: 102.78373 | F18: 105.72665 | G18: per change
A19: Low Service Level
A20: Standard Desktops (CEDS) | B20: 15.143977 | C20: 17.405809 | D20: 15.498816 | E20: 14.533839 | F20: 13.660993 | G20: per device per month
A21: Non-Standard Desktops (non CEDS)
A22: Standard Laptops (CEDS) | B22: 20.590327 | C22: 27.263378 | D22: 25.360272 | E22: 24.24555 | F22: 23.309048 | G22: per device per month
A23: Non-Standard Laptops (non CEDS)
A24: Standard Local Printers | B24: 4.3797813 | C24: 13.169304 | D24: 12.805616 | E24: 12.478687 | F24: 12.195277 | G24: per device per month
A25: Non-Standard Local Printers
A26: Standard Network Printers | B26: 6.4726358 | C26: 15.924445 | D26: 14.969315 | E26: 14.59554 | F26: 14.294395 | G26: per device per month
A27: Non-Standard Network Printers | B27: 8.5393805 | C27: 23.784507 | D27: 23.062964 | E27: 22.502588 | F27: 22.119177 | G27: per device per month
A28: Other Peripherals
A30: Installations | B30: 172.73682 | C30: 175.63261 | D30: 178.54412 | E30: 176.95793 | F30: 179.9145 | G30: per installation
A31: Moves | B31: 73.743688 | C31: 76.324717 | D31: 78.919757 | E31: 77.505977 | F31: 80.14118 | G31: per move
A32: Adds
A33: Changes | B33: 73.743688 | C33: 76.324717 | D33: 78.919757 | E33: 77.505977 | F33: 80.14118 | G33: per change
A34: Packaging & Distribution
A35: Packaging | B35: 883.59941 | C35: 883.47981 | D35: 878.81784 | E35: 874.15588 | F35: 882.12825 | G35: per package
A36: TOTAL EUC
A37: Service Desk
A38: Seats Supported
A39: Price per seat | B39: 6.6895925 | C39: 18.799059 | D39: 13.04935 | E39: 10.226535 | F39: 8.1595998 | G39: per seat per month
A47: TOTAL SERVICE DESK (seats supported)
A48: LAN Services
A49: Support Services
...

Sheet One Time Charges
B2: Total Transition phase
E3: HR prep | F3: Prep | H3: Transition
B4: 2IM | D4: Month -2 | E4: Month -1 | F4: Month 0 | G4: Month 1 | H4: Month 2 | I4: Month 3 | J4: Month 4 | K4: Month 5 | L4: Month 6 | M4: Month 7 | N4: Month 8 | O4: Month 9 | P4: Month 10 | Q4: Month 11 | R4: Month 12 | S4: Year 1 | T4: Month 13 | U4: Month 14 | V4: Month 15 | W4: Month 16 | X4: Month 17 | Y4: Month 18 | Z4: Month 19 | AA4: Month 20 | AB4: Month 21 | AC4: Month 22 | AD4: Month 23 | AE4: Month 24 | AF4: Year 2 | AG4: Month 25 | AH4: Month 26 | AI4: Month 27 | AJ4: Month 28 | AK4: Month 29 | AL4: Month 30 | AM4: Month 31 | AN4: Month 32 | AO4: Month 33 | AP4: Month 34 | AQ4: Month 35 | AR4: Month 36 | AS4: Year 3 | AT4: Month 37 | AU4: Month 38 | AV4: Month 39 | AW4: Month 40 | AX4: Month 41 | AY4: Month 42 | AZ4: Month 43 | BA4: Month 44 | BB4: Month 45 | BC4: Month 46 | BD4: Month 47 | BE4: Month 48 | BF4: Year 4 | BG4: Total
D5: (Euro) | E5: (Euro) | F5: (Euro) | G5: (Euro) | H5: (Euro) | I5: (Euro) | J5: (Euro) | K5: (Euro) | L5: (Euro) | M5: (Euro) | N5: (Euro) | O5: (Euro) | P5: (Euro) | Q5: (Euro) | R5: (Euro) | S5: (Euro) | T5: (Euro) | U5: (Euro) | V5: (Euro) | W5: (Euro) | X5: (Euro) | Y5: (Euro) | Z5: (Euro) | AA5: (Euro) | AB5: (Euro) | AC5: (Euro) | AD5: (Euro) | AE5: (Euro) | AF5: (Euro) | AG5: (Euro) | AH5: (Euro) | AI5: (Euro) | AJ5: (Euro) | AK5: (Euro) | AL5: (Euro) | AM5: (Euro) | AN5: (Euro) | AO5: (Euro) | AP5: (Euro) | AQ5: (Euro) | AR5: (Euro) | AS5: (Euro) | AT5: (Euro) | AU5: (Euro) | AV5: (Euro) | AW5: (Euro) | AX5: (Euro) | AY5: (Euro) | AZ5: (Euro) | BA5: (Euro) | BB5: (Euro) | BC5: (Euro) | BD5: (Euro) | BE5: (Euro) | BF5: (Euro) | BG5: (Euro)
B7: 1. Transition Program Management Stream | F7: 97878.137 | G7: 44490.062 | H7: 44490.062 | I7: 44490.062 | J7: 0 | K7: 0 | L7: 0 | M7: 0 | N7: 0 | O7: 0 | P7: 0 | Q7: 0 | R7: 0 | S7: =SUM(F7:R7) | AF7: =SUM(T7:AE7) | AS7: =SUM(AR7) | BF7: =SUM(BE7) | BG7: =SUM(S7,AF7,AS7,BF7)
B8: 2. Service Management Stream | F8: 0 | G8: 101771.02 | H8: 124016.05 | I8: 122903.8 | J8: 0 | K8: 0 | L8: 0 | M8: 0 | N8: 0 | O8: 0 | P8: 0 | Q8: 0 | R8: 0 | S8: =SUM(F8:R8) | AF8: =SUM(T8:AE8) | AS8: =SUM(AR8) | BF8: =SUM(BE8) | BG8: =SUM(S8,AF8,AS8,BF8)
B9: 3. Unit Operations Stream | F9: 0 | G9: 111225.16 | H9: 145148.83 | I9: 144036.58 | J9: 0 | K9: 0 | L9: 0 | M9: 0 | N9: 0 | O9: 0 | P9: 0 | Q9: 0 | R9: 0 | S9: =SUM(F9:R9) | AF9: =SUM(T9:AE9) | AS9: =SUM(AR9) | BF9: =SUM(BE9) | BG9: =SUM(S9,AF9,AS9,BF9)
B10: 4. Communications Stream | F10: 23357.283 | G10: 22245.031 | H10: 11122.516 | I10: 4449.0062 | J10: 0 | K10: 0 | L10: 0 | M10: 0 | N10: 0 | O10: 0 | P10: 0 | Q10: 0 | R10: 0 | S10: =SUM(F10:R10) | AF10: =SUM(T10:AE10) | AS10: =SUM(AR10) | BF10: =SUM(BE10) | BG10: =SUM(S10,AF10,AS10,BF10)
B11: 5. Finance and Contract Management Stream | F11: 16591.086 | G11: 58504.432 | H11: 69070.822 | I11: 69070.822 | J11: 0 | K11: 0 | L11: 0 | M11: 0 | N11: 0 | O11: 0 | P11: 0 | Q11: 0 | R11: 0 | S11: =SUM(F11:R11) | AF11: =SUM(T11:AE11) | AS11: =SUM(AR11) | BF11: =SUM(BE11) | BG11: =SUM(S11,AF11,AS11,BF11)
B12: 6. People Transfer Stream | F12: 0 | G12: 51386.022 | H12: 46714.565 | I12: 28028.739 | J12: 0 | K12: 0 | L12: 0 | M12: 0 | N12: 0 | O12: 0 | P12: 0 | Q12: 0 | R12: 0 | S12: =SUM(F12:R12) | AF12: =SUM(T12:AE12) | AS12: =SUM(AR12) | BF12: =SUM(BE12) | BG12: =SUM(S12,AF12,AS12,BF12)
B13: 7. Knowledge Transfer Stream | F13: 0 | G13: 23357.283 | H13: 23357.283 | I13: 23357.283 | J13: 0 | K13: 0 | L13: 0 | M13: 0 | N13: 0 | O13: 0 | P13: 0 | Q13: 0 | R13: 0 | S13: =SUM(F13:R13) | AF13: =SUM(T13:AE13) | AS13: =SUM(AR13) | BF13: =SUM(BE13) | BG13: =SUM(S13,AF13,AS13,BF13)
B14: TOTAL | E14: 0 | F14: =SUM(F7:F13) | G14: =SUM(G7:G13) | H14: =SUM(H7:H13) | I14: =SUM(I7:I13) | J14: =SUM(J7:J13) | K14: =SUM(K7:K13) | L14: =SUM(L7:L13) | M14: =SUM(M7:M13) | ... R14: =SUM(R7:R13) | S14: =SUM(F14:R14) | T14: =SUM(T7:T13) | U14: =SUM(U7:U13) | V14: =SUM(V7:V13) | W14: =SUM(W7:W13) | X14: =SUM(X7:X13) | Y14: =SUM(Y7:Y13) | Z14: =SUM(Z7:Z13) | AA14: =SUM(AA7:AA13) | ... AE14: =SUM(AE7:AE13) | AF14: =SUM(AE14) | AG14: =SUM(AG7:AG13) | AH14: =SUM(AH7:AH13) | AI14: =SUM(AI7:AI13) | AJ14: =SUM(AJ7:AJ13) | AK14: =SUM(AK7:AK13) | AL14: =SUM(AL7:AL13) | AM14: =SUM(AM7:AM13) | AN14: =SUM(AN7:AN13) | ... AR14: =SUM(AR7:AR13) | AS14: =SUM(AR14) | AT14: =SUM(AT7:AT13) | AU14: =SUM(AU7:AU13) | AV14: =SUM(AV7:AV13) | AW14: =SUM(AW7:AW13) | AX14: =SUM(AX7:AX13) | AY14: =SUM(AY7:AY13) | AZ14: =SUM(AZ7:AZ13) | BA14: =SUM(BA7:BA13) | ... BE14: =SUM(BE7:BE13) | BF14: =SUM(BE14) | BG14: =SUM(BG7:BG13)
E16: HR prep | F16: Prep | H16: Transition
B17: 2IM | E17: Month -1 | F17: Month 0 | G17: Month 1 | H17: Month 2 | I17: Month 3 | J17: Month 4 | K17: Month 5 | L17: Month 6 | M17: Month 7 | N17: Month 8 | O17: Month 9 | P17: Month 10 | Q17: Month 11 | R17: Month 12 | T17: Month 13 | U17: Month 14 | V17: Month 15 | W17: Month 16 | X17: Month 17 | Y17: Month 18 | Z17: Month 19 | AA17: Month 20 | AB17: Month 21 | AC17: Month 22 | AD17: Month 23 | AE17: Month 24 | AG17: Month 25 | AH17: Month 26 | AI17: Month 27 | AJ17: Month 28 | AK17: Month 29 | AL17: Month 30 | AM17: Month 31 | AN17: Month 32 | AO17: Month 33 | AP17: Month 34 | AQ17: Month 35 | AR17: Month 36 | AT17: Month 37 | AU17: Month 38 | AV17: Month 39 | AW17: Month 40 | AX17: Month 41 | AY17: Month 42 | AZ17: Month 43 | BA17: Month 44 | BB17: Month 45 | BC17: Month 46 | BD17: Month 47 | BE17: Month 48
E18: FTE's | F18: FTE's | G18: FTE's | H18: FTE's | I18: FTE's | J18: FTE's | K18: FTE's | L18: FTE's | M18: FTE's | N18: FTE's | O18: FTE's | P18: FTE's | Q18: FTE's | R18: FTE's | T18: FTE's | U18: FTE's | V18: FTE's | W18: FTE's | X18: FTE's | Y18: FTE's | Z18: FTE's | AA18: FTE's | AB18: FTE's | AC18: FTE's | AD18: FTE's | AE18: FTE's | AG18: FTE's | AH18: FTE's | AI18: FTE's | AJ18: FTE's | AK18: FTE's | AL18: FTE's | AM18: FTE's | AN18: FTE's | AO18: FTE's | AP18: FTE's | AQ18: FTE's | AR18: FTE's | AT18: FTE's | AU18: FTE's | AV18: FTE's | AW18: FTE's | AX18: FTE's | AY18: FTE's | AZ18: FTE's | BA18: FTE's | BB18: FTE's | BC18: FTE's | BD18: FTE's | BE18: FTE's
B20: 1. Transition Program Management Stream | E20: 0 | F20: 4.1904762 | G20: 1.9047619 | H20: 1.9047619 | I20: 1.9047619
B21: 2. Service Management Stream | E21: 0 | F21: 0 | G21: 4.3571429 | H21: 5.3095238 | I21: 5.2619048
B22: 3. Unit Operations Stream | E22: 0 | F22: 0 | G22: 4.7619048 | H22: 6.2142857 | I22: 6.1666667
B23: 4. Communications Stream | E23: 0 | F23: 1 | G23: 0.95238095 | H23: 0.47619048 | I23: 0.19047619
B24: 5. Finance and Contract Management Stream | E24: 0 | F24: 0.71031746 | G24: 2.5047619 | H24: 2.9571429 | I24: 2.9571429
B25: 6. People Transfer Stream | E25: 0 | F25: 0 | G25: 2.2 | H25: 2 | I25: 1.2
B26: 7. Knowledge Transfer Stream | E26: 0 | F26: 0 | G26: 1 | H26: 1 | I26: 1
B27: TOTAL | E27: 0 | F27: 5.9007937 | G27: 17.680952 | H27: 19.861905 | I27: 18.680952 | J27: 0 | K27: 0 | L27: 0 | M27: 0 | N27: 0 | O27: 0 | P27: 0 | Q27: 0 | R27: 0 | T27: 0 | U27: 0 | V27: 0 | W27: 0 | X27: 0 | Y27: 0 | Z27: 0 | AA27: 0 | AB27: 0 | AC27: 0 | AD27: 0 | AE27: 0 | AG27: 0 | AH27: 0 | AI27: 0 | AJ27: 0 | AK27: 0 | AL27: 0 | AM27: 0 | AN27: 0 | AO27: 0 | AP27: 0 | AQ27: 0 | AR27: 0 | AT27: 0 | AU27: 0 | AV27: 0 | AW27: 0 | AX27: 0 | AY27: 0 | AZ27: 0 | BA27: 0 | BB27: 0 | BC27: 0 | BD27: 0 | BE27: 0
E29: HR prep | F29: Prep | H29: Transition
B30: Vendor Alpha | D30: Month -2 | E30: Month -1 | F30: Month 0 | G30: Month 1 | H30: Month 2 | I30: Month 3 | J30: Month 4 | K30: Month 5 | L30: Month 6 | M30: Month 7 | N30: Month 8 | O30: Month 9 | P30: Month 10 | Q30: Month 11 | R30: Month 12 | S30: Year 1 | T30: Month 13 | U30: Month 14 | V30: Month 15 | W30: Month 16 | X30: Month 17 | Y30: Month 18 | Z30: Month 19 | AA30: Month 20 | AB30: Month 21 | AC30: Month 22 | AD30: Month 23 | AE30: Month 24 | AF30: Year 2 | AG30: Month 25 | AH30: Month 26 | AI30: Month 27 | AJ30: Month 28 | AK30: Month 29 | AL30: Month 30 | AM30: Month 31 | AN30: Month 32 | AO30: Month 33 | AP30: Month 34 | AQ30: Month 35 | AR30: Month 36 | AS30: Year 3 | AT30: Month 37 | AU30: Month 38 | AV30: Month 39 | AW30: Month 40 | AX30: Month 41 | AY30: Month 42 | AZ30: Month 43 | BA30: Month 44 | BB30: Month 45 | BC30: Month 46 | BD30: Month 47 | BE30: Month 48 | BF30: Year 4 | BG30: Total
D31: (Euro) | E31: (Euro) | F31: (Euro) | G31: (Euro) | H31: (Euro) | I31: (Euro) | J31: (Euro) | K31: (Euro) | L31: (Euro) | M31: (Euro) | N31: (Euro) | O31: (Euro) | P31: (Euro) | Q31: (Euro) | R31: (Euro) | S31: (Euro) | T31: (Euro) | U31: (Euro) | V31: (Euro) | W31: (Euro) | X31: (Euro) | Y31: (Euro) | Z31: (Euro) | AA31: (Euro) | AB31: (Euro) | AC31: (Euro) | AD31: (Euro) | AE31: (Euro) | AF31: (Euro) | AG31: (Euro) | AH31: (Euro) | AI31: (Euro) | AJ31: (Euro) | AK31: (Euro) | AL31: (Euro) | AM31: (Euro) | AN31: (Euro) | AO31: (Euro) | AP31: (Euro) | AQ31: (Euro) | AR31: (Euro) | AS31: (Euro) | AT31: (Euro) | AU31: (Euro) | AV31: (Euro) | AW31: (Euro) | AX31: (Euro) | AY31: (Euro) | AZ31: (Euro) | BA31: (Euro) | BB31: (Euro) | BC31: (Euro) | BD31: (Euro) | BE31: (Euro) | BF31: (Euro) | BG31: (Euro)
B33: 1. Transition Program Management Stream | E33: 0 | F33: 58880 | G33: 58880 | H33: 58880 | I33: 58880 | J33: 0 | K33: 0 | L33: 0 | M33: 0 | N33: 0 | O33: 0 | P33: 0 | Q33: 0 | R33: 0 | S33: =SUM(E33:R33) | AF33: =SUM(T33:AE33) | AS33: 0 | BF33: 0 | BG33: 235520
B34: 2. Service Management Stream | E34: 0 | F34: 47424 | G34: 51072 | H34: 40128 | I34: 25536 | J34: 0 | K34: 0 | L34: 0 | M34: 0 | N34: 0 | O34: 0 | P34: 0 | Q34: 0 | R34: 0 | S34: =SUM(E34:R34) | AF34: =SUM(T34:AE34) | AS34: 0 | BF34: 0 | BG34: 164160
B35: 3. Unit Operations Stream | E35: 0 | F35: 34320 | G35: 137280 | H35: 62400 | I35: 49920 | J35: 0 | K35: 0 | L35: 0 | M35: 0 | N35: 0 | O35: 0 | P35: 0 | Q35: 0 | R35: 0 | S35: =SUM(E35:R35) | AF35: =SUM(T35:AE35) | AS35: 0 | BF35: 0 | BG35: 283920
B36: 4. Communications Stream | E36: 26520 | F36: 18720 | G36: 15600 | H36: 15600 | I36: 15600 | J36: 0 | K36: 0 | L36: 0 | M36: 0 | N36: 0 | O36: 0 | P36: 0 | Q36: 0 | R36: 0 | S36: =SUM(E36:R36) | AF36: =SUM(T36:AE36) | AS36: 0 | BF36: 0 | BG36: 92040
B37: 5. Finance and Contract Management Stream | E37: 0 | F37: 24960 | G37: 51480 | H37: 48360 | I37: 15600 | J37: 0 | K37: 0 | L37: 0 | M37: 0 | N37: 0 | O37: 0 | P37: 0 | Q37: 0 | R37: 0 | S37: =SUM(E37:R37) | AF37: =SUM(T37:AE37) | AS37: 0 | BF37: 0 | BG37: 140400
B38: 6. People Transfer Stream | E38: 56908.8 | F38: 29366.4 | G38: 46694.4 | H38: 79161.6 | I38: 99590.4 | J38: 0 | K38: 0 | L38: 0 | M38: 0 | N38: 0 | O38: 0 | P38: 0 | Q38: 0 | R38: 0 | S38: =SUM(E38:R38) | AF38: =SUM(T38:AE38) | AS38: 0 | BF38: 0 | BG38: 311721.6
B39: 7. Knowledge Transfer Stream | E39: 0 | F39: 3120 | G39: 28080 | H39: 53040 | I39: 28080 | J39: 0 | K39: 0 | L39: 0 | M39: 0 | N39: 0 | O39: 0 | P39: 0 | Q39: 0 | R39: 0 | S39: =SUM(E39:R39) | AF39: =SUM(T39:AE39) | AS39: 0 | BF39: 0 | BG39: 112320
B40: Communication Expenses | E40: 0 | F40: 40000 | G40: 30000 | H40: 20000 | I40: 10000 | J40: 0 | K40: 0 | L40: 0 | M40: 0 | N40: 0 | O40: 0 | P40: 0 | Q40: 0 | R40: 0 | S40: =SUM(E40:R40) | AF40: =SUM(T40:AE40) | AS40: 0 | BF40: 0 | BG40: 100000
B41: Expenses | E41: 20000 | F41: 25000 | G41: 25000 | H41: 25000 | I41: 25000 | J41: 0 | K41: 0 | L41: 0 | M41: 0 | N41: 0 | O41: 0 | P41: 0 | Q41: 0 | R41: 0 | S41: =SUM(E41:R41) | AF41: =SUM(T41:AE41) | AS41: 0 | BF41: 0 | BG41: 120000
B42: TOTAL | E42: =SUM(E33:E41) | F42: =SUM(F33:F41) | G42: =SUM(G33:G41) | H42: =SUM(H33:H41) | I42: =SUM(I33:I41) | J42: =SUM(J33:J41) | K42: =SUM(K33:K41) | L42: =SUM(L33:L41) | ... BG42: =SUM(BG33:BG41)
E44: HR prep | F44: Prep | H44: Transition
B45: Vendor Alpha | E45: Month -1 | F45: Month 0 | G45: Month 1 | H45: Month 2 | I45: Month 3 | J45: Month 4 | K45: Month 5 | L45: Month 6 | M45: Month 7 | N45: Month 8 | O45: Month 9 | P45: Month 10 | Q45: Month 11 | R45: Month 12 | T45: Month 13 | U45: Month 14 | V45: Month 15 | W45: Month 16 | X45: Month 17 | Y45: Month 18 | Z45: Month 19 | AA45: Month 20 | AB45: Month 21 | AC45: Month 22 | AD45: Month 23 | AE45: Month 24 | AG45: Month 25 | AH45: Month 26 | AI45: Month 27 | AJ45: Month 28 | AK45: Month 29 | AL45: Month 30 | AM45: Month 31 | AN45: Month 32 | AO45: Month 33 | AP45: Month 34 | AQ45: Month 35 | AR45: Month 36 | AT45: Month 37 | AU45: Month 38 | AV45: Month 39 | AW45: Month 40 | AX45: Month 41 | AY45: Month 42 | AZ45: Month 43 | BA45: Month 44 | BB45: Month 45 | BC45: Month 46 | BD45: Month 47 | BE45: Month 48
E46: FTE's | F46: FTE's | G46: FTE's | H46: FTE's | I46: FTE's | J46: FTE's | K46: FTE's | L46: FTE's | M46: FTE's | N46: FTE's | O46: FTE's | P46: FTE's | Q46: FTE's | R46: FTE's | T46: FTE's | U46: FTE's | V46: FTE's | W46: FTE's | X46: FTE's | Y46: FTE's | Z46: FTE's | AA46: FTE's | AB46: FTE's | AC46: FTE's | AD46: FTE's | AE46: FTE's | AG46: FTE's | AH46: FTE's | AI46: FTE's | AJ46: FTE's | AK46: FTE's | AL46: FTE's | AM46: FTE's | AN46: FTE's | AO46: FTE's | AP46: FTE's | AQ46: FTE's | AR46: FTE's | AT46: FTE's | AU46: FTE's | AV46: FTE's | AW46: FTE's | AX46: FTE's | AY46: FTE's | AZ46: FTE's | BA46: FTE's | BB46: FTE's | BC46: FTE's | BD46: FTE's | BE46: FTE's
B48: 1. Transition Program Management Stream | E48: 0 | F48: 4.8 | G48: 4.8 | H48: 4.8 | I48: 4.8
...

Sheet Facilities
A6: Neptune - EuroBank located employees
A7: Date: | B7: 38683
A9: The Table below gives an overview of the averageNeptune employees per bundle, per country, working at EuroBank locations. Besides the number per year, also an explanation is given on whether housing costs at PST member premises is already included in our cost
A11: PST member | B11: Bundle | C11: Country | D11: Number of PST Supplier employees, working from EuroBank locations | I11: Did you also include 'm2 costs' for these employees in your pricing?
D12: Year 1 | E12: Year 2 | F12: Year 3 | G12: Year 4 | H12: Year 5
A13: Vendor Beta | B13: 2IM5 | C13: NL | D13: 20 | E13: 20 | F13: 20 | G13: 19 | H13: 18 | I13: No
C14: BE | D14: 4 | E14: 4 | F14: 4 | G14: 4 | H14: 3 | I14: No
A15: TelCo | B15: Voice | C15: NL | D15: 27 | E15: 5 | F15: 5 | G15: 5 | H15: 5 | I15: No
C16: BE | D16: 4 | E16: 2 | F16: 2 | G16: 2 | H16: 2 | I16: No
B17: LAN | C17: NL | D17: 3 | E17: 0 | F17: 0 | G17: 0 | H17: 0 | I17: No
C18: BE | D18: 0.5 | E18: 0 | F18: 0 | G18: 0 | H18: 0 | I18: No
A19: Vendor Alpha | B19: EUC-D&S | C19: NL | D19: 20 | E19: 2 | F19: 0 | G19: 0 | H19: 0 | I19: Yes
C20: BE | D20: 6 | E20: 1 | F20: 0 | G20: 0 | H20: 0 | I20: Yes
B21: EUC-UAS | C21: NL | D21: 28 | E21: 3 | F21: 0 | G21: 0 | H21: 0 | I21: Yes
C22: BE | D22: 9 | E22: 1 | F22: 0 | G22: 0 | H22: 0 | I22: Yes
B23: EUC-AS | C23: NL | D23: 34 | E23: 3 | F23: 0 | G23: 0 | H23: 0 | I23: Yes
C24: BE | D24: 11 | E24: 1 | F24: 0 | G24: 0 | H24: 0 | I24: Yes
B25: Server Management | C25: NL | D25: 26 | E25: 3 | F25: 0 | G25: 0 | H25: 0 | I25: Yes
C26: BE | D26: 8 | E26: 1 | F26: 0 | G26: 0 | H26: 0 | I26: Yes
A27: Vendor Gamma PinkRoccade | B27: Service Desk | C27: NL | D27: 98 | E27: =D27/4 | F27: 0 | G27: 0 | H27: 0 | I27: Yes
C28: BE | D28: 37 | E28: =D28/4 | F28: 0 | G28: 0 | H28: 0 | I28: Yes
B29: EUC-UIS | C29: NL | D29: 1.4 | E29: 1.4 | F29: 1.4 | G29: 1.4 | H29: 1.4 | I29: No
C30: BE | D30: 0 | E30: 0 | F30: 0 | G30: 0 | H30: 0 | I30: No
B31: DT-HW | C31: NL | D31: 0 | E31: 0 | F31: 0 | G31: 0 | H31: 0 | I31: No
C32: BE | D32: 0 | E32: 0 | F32: 0 | G32: 0 | H32: 0 | I32: No
A34: Note 1: Housing costs are only compensated for employees who spend all their working hours at EuroBank locations.
A35: Note 2: FTE's related to projects members, working at EuroBank premises, are not included in this calculation
A36: Note 3: On site transitioned EuroBank FTEs to be rationalized after Effective Date in line with Exhibit 5
A42: Reimbursement of facility costs
A44: Vendor Alpha | B44: EUC-D&S | C44: NL | D44: =D19*-$B$57 | E44: =E19*-$B$57
C45: BE | D45: =D20*-$B$57 | E45: =E20*-$B$57
B46: EUC-UAS | C46: NL | D46: =D21*-$B$57 | E46: =E21*-$B$57
C47: BE | D47: =D22*-$B$57 | E47: =E22*-$B$57
B48: EUC-AS | C48: NL | D48: =D23*-$B$57 | E48: =E23*-$B$57
C49: BE | D49: =D24*-$B$57 | E49: =E24*-$B$57
B50: Server Management | C50: NL | D50: =D25*-$B$57 | E50: =E25*-$B$57
C51: BE | D51: =D26*-$B$57 | E51: =E26*-$B$57
A52: Vendor Gamma | B52: Service Desk | C52: NL | D52: =D27*-$B$56 | E52: =E27*-$B$56
C53: BE | D53: =D28*-$B$56 | E53: =E28*-$B$56
A54: Total | D54: =SUM(D44:D53) | E54: =SUM(E44:E53)
...

Sheet Acquisition of Assets
C1: Acquisition of Legacy Assets
E2: Amounts quoted herein are included in the Base Charges
D3: Initial Asset Purchase excl VAT - aligned with MATA | E3: Year 1 | F3: Year 2 | G3: Year 3 | H3: Year 4 | I3: Year 5 | J3: Total 5 Years including finance costs
C5: Total Assets Acquired - NBV
C6: EUC | J6: =SUM(E6:I6)
C8: Service Desk | J8: =SUM(E8:I8)
C10: LAN Services - NL | D10: 1134100 | E10: 1170044.5 | F10: 0 | G10: 0 | H10: 0 | I10: 0 | J10: =SUM(E10:I10)
C12: Voice Services - NL | D12: 2647120 | E12: 611165.15 | F12: 611165.15 | G12: 611165.15 | H12: 611165.15 | I12: 611165.15 | J12: =SUM(E12:I12)
C13: Voice Services - Be | D13: 956844 | E13: 220915.47 | F13: 220915.47 | G13: 220915.47 | H13: 220915.47 | I13: 220915.47 | J13: =SUM(E13:I13)
C14: Desktop Hardware | J14: =SUM(E14:I14)
C16: Server Management | J16: =SUM(E16:I16)
C18: 2IM | J18: =SUM(E18:I18)
C20: Cost of Money | J20: =SUM(E20:I20)
C22: Overhead | J22: =SUM(E22:I22)
C24: Other | J24: =SUM(E24:I24)
B28: TOTAL Charge | D28: =SUM(D5:D26) | E28: =SUM(E5:E26) | F28: =SUM(F5:F26) | G28: =SUM(G5:G26) | H28: =SUM(H5:H26) | I28: =SUM(I5:I26) | J28: =SUM(E28:I28)

Sheet PST Investments
B1: PST Supplier Investments (incl. refresh)
C3: Initial Asset Purchase | D3: Year 1 | E3: Year 2 | F3: Year 3 | G3: Year 4 | H3: Year 5 | I3: Total 5 Years
B5: EUC Assets | D5: 294000 | I5: =SUM(C5:H5)
B7: Service Desk Assets | I7: =SUM(C7:H7)
B9: LAN Assets | E9: 5440000 | I9: =SUM(C9:H9)
B11: Voice Assets | D11: 4400000 | E11: 1000000 | F11: 1000000 | G11: 1000000 | I11: =SUM(C11:H11)
B13: Desktop Hardware Assets | D13: 22089435 | E13: 8389138.3 | F13: 10641323 | G13: 22089435 | H13: 8389138.3 | I13: =SUM(C13:H13)
B15: Server Management Assets | D15: 2137933.5 | E15: 2128486.5 | F15: 3782288.5 | G15: 2137933.5 | H15: 2128486.5 | I15: =SUM(C15:H15)
B17: 2IM | I17: =SUM(C17:H17)
B19: Other Investments | I19: =SUM(C19:H19)
A21: TOTAL INVESTMENTS | C21: =SUM(C5:C19) | D21: =SUM(D5:D19) | E21: =SUM(E5:E19) | F21: =SUM(F5:F19) | G21: =SUM(G5:G19) | H21: =SUM(H5:H19) | I21: =SUM(C21:H21)

Sheet Pass Through overview
A1: Bundle | B1: Country | C1: Description | D1: I = Investment L = Lease C = Contract D = Direct Expence | E1: Investment amount | F1: Start Date (month) | G1: Duration (months) | H1: Y1 | I1: Y2 | J1: Y3 | K1: Y4 | L1: Y5
C2: Subtotals
C3: LAN | H3: =SUM(H10:H14) | I3: =SUM(I10:I14) | J3: =SUM(J10:J14) | K3: =SUM(K10:K14) | L3: =SUM(L10:L14)
C4: Voice | H4: =SUM(H17:H34) | I4: =SUM(I17:I34) | J4: =SUM(J17:J34) | K4: =SUM(K17:K34) | L4: =SUM(L17:L34)
C5: Desktop HW | H5: =SUM(H36:H149) | I5: =SUM(I36:I149) | J5: =SUM(J36:J149) | K5: =SUM(K36:K149) | L5: =SUM(L36:L149)
C6: Server | H6: =SUM(H151:H201) | I6: =SUM(I151:I201) | J6: =SUM(J151:J201) | K6: =SUM(K151:K201) | L6: =SUM(L151:L201)
C7: 2IM | H7: =SUM(H203:H204) | I7: =SUM(I203:I204) | J7: =SUM(J203:J204) | K7: =SUM(K203:K204) | L7: =SUM(L203:L204)
C8: Grand Total | H8: =SUM(H3:H7) | I8: =SUM(I3:I7) | J8: =SUM(J3:J7) | K8: =SUM(K3:K7) | L8: =SUM(L3:L7)
A10: LAN | B10: NL | D10: I | E10: 0 | H10: 0 | I10: 0 | J10: 0 | K10: 0
A11: LAN | B11: NL | C11: Management connections | D11: C | H11: 196512 | I11: 196512 | J11: 196512 | K11: 196512 | L11: 196512
A13: LAN | B13: BE | D13: I | E13: 0 | H13: 0 | I13: 0 | J13: 0 | K13: 0
A14: LAN | B14: BE
A17: Voice | B17: NL | C17: Refresh | D17: I
A18: Voice | B18: NL | D18: I
A19: Voice | B19: NL | D19: I
A20: Voice | B20: NL | D20: I
A21: Voice | B21: NL | D21: I
A22: Voice | B22: NL | D22: I
A23: Voice | B23: NL | D23: I
A24: Voice | B24: NL | C24: Acquisition assets (excl. Fin costs) | D24: I
A27: Voice | B27: BE | C27: Refresh | D27: I
A28: Voice | B28: BE | D28: I
A29: Voice | B29: BE | D29: I
A30: Voice | B30: BE | D30: I
A31: Voice | B31: BE | D31: I
A32: Voice | B32: BE | D32: I
A33: Voice | B33: BE | D33: I
A34: Voice | B34: BE | C34: Acquisition assets (excl. Fin costs) | D34: I
A36: Desktop HW | B36: NL | C36: Desktop | D36: L | E36: 11735935 | F36: 1 | G36: 36 | H36: 3298267.2 | I36: 3298267.2 | J36: 3298267.2
A37: Desktop HW | B37: NL | C37: Desktop | D37: L | E37: 1117723 | F37: 13 | G37: 36 | I37: 314124.87 | J37: 314124.87 | K37: 314124.87
A38: Desktop HW | B38: NL | C38: Desktop | D38: L | E38: 262607 | F38: 25 | G38: 36 | J38: 73803.071 | K38: 73803.071 | L38: 73803.071
A39: Desktop HW | B39: NL | C39: Desktop | D39: L | E39: 11735935 | F39: 37 | G39: 36 | K39: 3298267.2 | L39: 3298267.2
A40: Desktop HW | B40: NL | C40: Desktop | D40: L | E40: 1117723 | F40: 49 | G40: 36 | L40: 314124.87
A41: Desktop HW | B41: NL | C41: Laptop | D41: L | E41: 705795 | F41: 1 | G41: 36 | H41: 198356.63 | I41: 198356.63 | J41: 198356.63
A42: Desktop HW | B42: NL | C42: Laptop | D42: L | E42: 2010345 | F42: 13 | G42: 36 | I42: 564987.36 | J42: 564987.36 | K42: 564987.36
A43: Desktop HW | B43: NL | C43: Laptop | D43: L | E43: 331824 | F43: 25 | G43: 36 | J43: 93255.817 | K43: 93255.817 | L43: 93255.817
A44: Desktop HW | B44: NL | C44: Laptop | D44: L | E44: 705795 | F44: 37 | G44: 36 | K44: 198356.63 | L44: 198356.63
A45: Desktop HW | B45: NL | C45: Laptop | D45: L | E45: 2010345 | F45: 49 | G45: 36 | L45: 564987.36
A46: Desktop HW | B46: NL | C46: Monitor | D46: L | E46: 4063015 | F46: 1 | G46: 36 | H46: 1141869.7 | I46: 1141869.7 | J46: 1141869.7
A47: Desktop HW | B47: NL | C47: Monitor | D47: L | E47: 973710 | F47: 13 | G47: 36 | I47: 273651.46 | J47: 273651.46 | K47: 273651.46
...

Sheet Retained costs overview
A1: Retained contract values
A2: Amounts x Euro
A3: excluding VAT
A5: Location | B5: NL
A7: PST member | B7: Y1 ret EuroBank | C7: Y2 ret EuroBank | D7: Y3 ret EuroBank | E7: Y4 ret EuroBank | F7: Y5 ret EuroBank | G7: Total`Retained EuroBank
A8: VendorA | B8: 9710096.4 | C8: 9543575.6 | D8: 9543575.6 | E8: 9543575.6 | F8: 9543575.6 | G8: =SUM(B8:F8)
A9: Vendor Gamma | B9: 2081639.2 | C9: 867504.7 | D9: 867504.7 | E9: 867504.7 | F9: 867504.7 | G9: =SUM(B9:F9)
A10: TelCo | B10: 1446048.8 | C10: 180708 | D10: 180708 | E10: 180708 | F10: 180708 | G10: =SUM(B10:F10)
A11: Total | B11: =SUM(B8:B10) | C11: =SUM(C8:C10) | D11: =SUM(D8:D10) | E11: =SUM(E8:E10) | F11: =SUM(F8:F10) | G11: =SUM(G8:G10)
A14: Location | B14: BE
A16: PST member | B16: Y1 ret EuroBank | C16: Y2 ret EuroBank | D16: Y3 ret EuroBank | E16: Y4 ret EuroBank | F16: Y5 ret EuroBank | G16: Total`Retained EuroBank
A17: VendorA | B17: 3312235.7 | C17: 2908620.3 | D17: 2821424.3 | E17: 2821424.3 | F17: 2821424.3 | G17: =SUM(B17:F17)
A18: Vendor Gamma | B18: 7748051.8 | C18: 2821709.2 | D18: 2118037.8 | E18: 2118037.8 | F18: 2118037.8 | G18: =SUM(B18:F18)
A19: TelCo | B19: 2232956.2 | C19: 16912.303 | D19: 16912.303 | E19: 16912.303 | F19: 16912.303 | G19: =SUM(B19:F19)
A20: Total | B20: =SUM(B17:B19) | C20: =SUM(C17:C19) | D20: =SUM(D17:D19) | E20: =SUM(E17:E19) | F20: =SUM(F17:F19) | G20: =SUM(G17:G19)
A23: Location | B23: NL + BE
A25: PST member | B25: Y1 ret EuroBank | C25: Y2 ret EuroBank | D25: Y3 ret EuroBank | E25: Y4 ret EuroBank | F25: Y5 ret EuroBank | G25: Total`Retained EuroBank
A26: VendorA | B26: 13022332 | C26: 12452196 | D26: 12365000 | E26: 12365000 | F26: 12365000 | G26: =SUM(B26:F26)
A27: Vendor Gamma | B27: 9829691 | C27: 3689213.9 | D27: 2985542.5 | E27: 2985542.5 | F27: 2985542.5 | G27: =SUM(B27:F27)
A28: TelCo | B28: 3679005 | C28: 197620.3 | D28: 197620.3 | E28: 197620.3 | F28: 197620.3 | G28: =SUM(B28:F28)
A29: Total | B29: =SUM(B26:B28) | C29: =SUM(C26:C28) | D29: =SUM(D26:D28) | E29: =SUM(E26:E28) | F29: =SUM(F26:F28) | G29: =SUM(G26:G28)
A32: Retained Legacy assets
A34: Location | B34: NL
B36: Y1 ret EuroBank | C36: Y2 ret EuroBank | D36: Y3 ret EuroBank | E36: Y4 ret EuroBank | F36: Y5 ret EuroBank | G36: Total`Retained EuroBank
A37: Server Hardware | B37: 6724727.1 | C37: 1921350.6 | D37: 960675.3 | G37: =SUM(B37:F37)
A38: Desktop related Hardware | B38: 15401996 | C38: 4400570.4 | D38: 2200285.2 | G38: =SUM(B38:F38)
A39: Total | B39: =SUM(B37:B38) | C39: =SUM(C37:C38) | D39: =SUM(D37:D38) | G39: =SUM(G36:G38)
A41: Location | B41: BE
B43: Y1 ret EuroBank | C43: Y2 ret EuroBank | D43: Y3 ret EuroBank | E43: Y4 ret EuroBank | F43: Y5 ret EuroBank | G43: Total`Retained EuroBank
A44: Server Hardware | G44: =SUM(B44:F44)
A45: Desktop related Hardware | B45: 189753.2 | C45: 54215.2 | D45: 27107.6 | G45: =SUM(B45:F45)
A46: Total | B46: =SUM(B43:B45) | C46: =SUM(C43:C45) | D46: =SUM(D43:D45) | E46: =SUM(E43:E45) | F46: =SUM(F43:F45) | G46: =SUM(G43:G45)
A48: Location | B48: Total NL + BE
B50: Y1 ret EuroBank | C50: Y2 ret EuroBank | D50: Y3 ret EuroBank | E50: Y4 ret EuroBank | F50: Y5 ret EuroBank | G50: Total`Retained EuroBank
A51: Server Hardware | B51: =B37+B44 | C51: =C37+C44 | D51: =D37+D44 | E51: =E37+E44 | F51: =F37+F44 | G51: =SUM(B51:F51)
A52: Desktop related Hardware | B52: =B38+B45 | C52: =C38+C45 | D52: =D38+D45 | E52: =E38+E45 | F52: =F38+F45 | G52: =SUM(B52:F52)
A53: Total | B53: =SUM(B50:B52) | C53: =SUM(C50:C52) | D53: =SUM(D50:D52) | E53: =SUM(E50:E52) | F53: =SUM(F50:F52) | G53: =SUM(G50:G52)

Sheet Refresh cycles
B2: Overview of volumes used for refresh
D5: Year 1 Annual Avg. | E5: Year 2 Annual Avg. | F5: Year 3 Annual Avg. | G5: Year 4 Annual Avg. | H5: Year 5 Annual Avg.
B6: NL | C6: Desktop normal | D6: 29996 | E6: 2856.8 | F6: 671.2 | G6: 29996 | H6: 2856.8
C7: Desktop highend | D7: 7499 | E7: 714.2 | F7: 167.8 | G7: 7499 | H7: 714.2
C8: Laptop portable | D8: 844 | E8: 2404 | F8: 396.8 | G8: 844 | H8: 2404
C9: Laptop performance | D9: 211 | E9: 601 | F9: 99.2 | G9: 211 | H9: 601
C10: Monitor | D10: 26213 | E10: 6282 | F10: 9410 | G10: 26213 | H10: 6282
C11: Printer Local Mono | D11: 179.20428 | E11: 179.20428 | F11: 179.20428 | G11: 179.20428 | H11: 179.20428
C12: Printer Local Color | D12: 653.07332 | E12: 653.07332 | F12: 653.07332 | G12: 653.07332 | H12: 653.07332
C13: Printer Network small Mono | D13: 194.14034 | E13: 194.14034 | F13: 194.14034 | G13: 194.14034 | H13: 194.14034
C14: Printer Network small Color | D14: 383.39867 | E14: 383.39867 | F14: 383.39867 | G14: 383.39867 | H14: 383.39867
C15: Printer Network big Mono | D15: 83.203004 | E15: 83.203004 | F15: 83.203004 | G15: 83.203004 | H15: 83.203004
C16: Printer Network big color | D16: 164.31371 | E16: 164.31371 | F16: 164.31371 | G16: 164.31371 | H16: 164.31371
C17: Central 2 way Server | D17: 190.43223 | E17: 193.99225 | F17: 193.99225 | G17: 193.99225 | H17: 193.99225
C18: Central 4 way Server | D18: 215.16368 | E18: 219.18605 | F18: 219.18605 | G18: 219.18605 | H18: 219.18605
... C21: Decentral 2 way Server | D21: 48.638534 | E21: 49.547804 | F21: 49.547804 | G21: 49.547804 | H21: 49.547804
B22: BE | C22: Desktop normal | D22: 5366.4 | E22: 1990.4 | F22: 6478.4 | G22: 5366.4 | H22: 1990.4
C23: Desktop highend | D23: 1341.6 | E23: 497.6 | F23: 1619.6 | G23: 1341.6 | H23: 497.6
C24: Laptop portable | D24: 0 | E24: 164 | F24: 1294.4 | G24: 0 | H24: 164
C25: Laptop performance | D25: 0 | E25: 41 | F25: 323.6 | G25: 0 | H25: 41
C26: Monitor | D26: 2813 | E26: 2080 | F26: 12401 | G26: 2813 | H26: 2080
C27: Printer Local Mono | D27: 422.22216 | E27: 422.22216 | F27: 422.22216 | G27: 422.22216 | H27: 422.22216
C28: Printer Local Color | D28: 1538.7022 | E28: 1538.7022 | F28: 1538.7022 | G28: 1538.7022 | H28: 1538.7022
C29: Printer Network small Mono | D29: 457.41292 | E29: 457.41292 | F29: 457.41292 | G29: 457.41292 | H29: 457.41292
C30: Printer Network small Color | D30: 903.32335 | E30: 903.32335 | F30: 903.32335 | G30: 903.32335 | H30: 903.32335
