Workbook

Sheet Cover Page
C11: EuroBank
C16: ATTACHMENT 4-D
C18: RESOURCE BASELINES
C19: Attachment to Exhibit 4 (Pricing and Financial Provisions)

Sheet Total Resource Baseline Units
A1: TOTAL RESOURCE BASELINE | B1: Resource Units | D1: Year 1 Annual Avg. | E1: Year 2 Annual Avg. | F1: Year 3 Annual Avg. | G1: Year 4 Annual Avg. | H1: Year 5 Annual Avg.
A2: EUC
A3: Support Services
A4: Medium Service Level | I4: 250 Named Users and 2000 Field Agents located in NL and BE, as defined in Exhibit 3 are included in the Resource Baseline and therefore in the Base Charges.
A5: Standard Desktops | D5: =SUM('NL Resource Baseline Units:BE Resource Baseline Units'!D5) | E5: =SUM('NL Resource Baseline Units:BE Resource Baseline Units'!E5) | F5: =SUM('NL Resource Baseline Units:BE Resource Baseline Units'!F5) | G5: =SUM('NL Resource Baseline Units:BE Resource Baseline Units'!G5) | H5: =SUM('NL Resource Baseline Units:BE Resource Baseline Units'!H5)
A6: Non-Standard Desktops | D6: =SUM('NL Resource Baseline Units:BE Resource Baseline Units'!D6) | E6: =SUM('NL Resource Baseline Units:BE Resource Baseline Units'!E6) | F6: =SUM('NL Resource Baseline Units:BE Resource Baseline Units'!F6) | G6: =SUM('NL Resource Baseline Units:BE Resource Baseline Units'!G6) | H6: =SUM('NL Resource Baseline Units:BE Resource Baseline Units'!H6)
A7: Standard Laptops | D7: =SUM('NL Resource Baseline Units:BE Resource Baseline Units'!D7) | E7: =SUM('NL Resource Baseline Units:BE Resource Baseline Units'!E7) | F7: =SUM('NL Resource Baseline Units:BE Resource Baseline Units'!F7) | G7: =SUM('NL Resource Baseline Units:BE Resource Baseline Units'!G7) | H7: =SUM('NL Resource Baseline Units:BE Resource Baseline Units'!H7)
A8: Non-Standard Laptops | D8: =SUM('NL Resource Baseline Units:BE Resource Baseline Units'!D8) | E8: =SUM('NL Resource Baseline Units:BE Resource Baseline Units'!E8) | F8: =SUM('NL Resource Baseline Units:BE Resource Baseline Units'!F8) | G8: =SUM('NL Resource Baseline Units:BE Resource Baseline Units'!G8) | H8: =SUM('NL Resource Baseline Units:BE Resource Baseline Units'!H8)
A9: Standard Local Printers | D9: =SUM('NL Resource Baseline Units:BE Resource Baseline Units'!D9) | E9: =SUM('NL Resource Baseline Units:BE Resource Baseline Units'!E9) | F9: =SUM('NL Resource Baseline Units:BE Resource Baseline Units'!F9) | G9: =SUM('NL Resource Baseline Units:BE Resource Baseline Units'!G9) | H9: =SUM('NL Resource Baseline Units:BE Resource Baseline Units'!H9)
A10: Non-Standard Local Printers | D10: =SUM('NL Resource Baseline Units:BE Resource Baseline Units'!D10) | E10: =SUM('NL Resource Baseline Units:BE Resource Baseline Units'!E10) | F10: =SUM('NL Resource Baseline Units:BE Resource Baseline Units'!F10) | G10: =SUM('NL Resource Baseline Units:BE Resource Baseline Units'!G10) | H10: =SUM('NL Resource Baseline Units:BE Resource Baseline Units'!H10)
A11: Standard Network Printers | D11: =SUM('NL Resource Baseline Units:BE Resource Baseline Units'!D11) | E11: =SUM('NL Resource Baseline Units:BE Resource Baseline Units'!E11) | F11: =SUM('NL Resource Baseline Units:BE Resource Baseline Units'!F11) | G11: =SUM('NL Resource Baseline Units:BE Resource Baseline Units'!G11) | H11: =SUM('NL Resource Baseline Units:BE Resource Baseline Units'!H11)
A12: Non-Standard Network Printers | D12: =SUM('NL Resource Baseline Units:BE Resource Baseline Units'!D12) | E12: =SUM('NL Resource Baseline Units:BE Resource Baseline Units'!E12) | F12: =SUM('NL Resource Baseline Units:BE Resource Baseline Units'!F12) | G12: =SUM('NL Resource Baseline Units:BE Resource Baseline Units'!G12) | H12: =SUM('NL Resource Baseline Units:BE Resource Baseline Units'!H12)
A13: Other Peripherals | D13: =SUM('NL Resource Baseline Units:BE Resource Baseline Units'!D13) | E13: =SUM('NL Resource Baseline Units:BE Resource Baseline Units'!E13) | F13: =SUM('NL Resource Baseline Units:BE Resource Baseline Units'!F13) | G13: =SUM('NL Resource Baseline Units:BE Resource Baseline Units'!G13) | H13: =SUM('NL Resource Baseline Units:BE Resource Baseline Units'!H13)
D14: =SUM('NL Resource Baseline Units:BE Resource Baseline Units'!D14) | E14: =SUM('NL Resource Baseline Units:BE Resource Baseline Units'!E14) | F14: =SUM('NL Resource Baseline Units:BE Resource Baseline Units'!F14) | G14: =SUM('NL Resource Baseline Units:BE Resource Baseline Units'!G14) | H14: =SUM('NL Resource Baseline Units:BE Resource Baseline Units'!H14)
A15: Installations | D15: =SUM('NL Resource Baseline Units:BE Resource Baseline Units'!D15) | E15: =SUM('NL Resource Baseline Units:BE Resource Baseline Units'!E15) | F15: =SUM('NL Resource Baseline Units:BE Resource Baseline Units'!F15) | G15: =SUM('NL Resource Baseline Units:BE Resource Baseline Units'!G15) | H15: =SUM('NL Resource Baseline Units:BE Resource Baseline Units'!H15)
A16: Moves | D16: =SUM('NL Resource Baseline Units:BE Resource Baseline Units'!D16) | E16: =SUM('NL Resource Baseline Units:BE Resource Baseline Units'!E16) | F16: =SUM('NL Resource Baseline Units:BE Resource Baseline Units'!F16) | G16: =SUM('NL Resource Baseline Units:BE Resource Baseline Units'!G16) | H16: =SUM('NL Resource Baseline Units:BE Resource Baseline Units'!H16)
A17: Adds | D17: =SUM('NL Resource Baseline Units:BE Resource Baseline Units'!D17) | E17: =SUM('NL Resource Baseline Units:BE Resource Baseline Units'!E17) | F17: =SUM('NL Resource Baseline Units:BE Resource Baseline Units'!F17) | G17: =SUM('NL Resource Baseline Units:BE Resource Baseline Units'!G17) | H17: =SUM('NL Resource Baseline Units:BE Resource Baseline Units'!H17)
A18: Changes | D18: =SUM('NL Resource Baseline Units:BE Resource Baseline Units'!D18) | E18: =SUM('NL Resource Baseline Units:BE Resource Baseline Units'!E18) | F18: =SUM('NL Resource Baseline Units:BE Resource Baseline Units'!F18) | G18: =SUM('NL Resource Baseline Units:BE Resource Baseline Units'!G18) | H18: =SUM('NL Resource Baseline Units:BE Resource Baseline Units'!H18)
A19: Low Service Level
A20: Standard Desktops | D20: =SUM('NL Resource Baseline Units:BE Resource Baseline Units'!D20) | E20: =SUM('NL Resource Baseline Units:BE Resource Baseline Units'!E20) | F20: =SUM('NL Resource Baseline Units:BE Resource Baseline Units'!F20) | G20: =SUM('NL Resource Baseline Units:BE Resource Baseline Units'!G20) | H20: =SUM('NL Resource Baseline Units:BE Resource Baseline Units'!H20)
A21: Non-Standard Desktops | D21: =SUM('NL Resource Baseline Units:BE Resource Baseline Units'!D21) | E21: =SUM('NL Resource Baseline Units:BE Resource Baseline Units'!E21) | F21: =SUM('NL Resource Baseline Units:BE Resource Baseline Units'!F21) | G21: =SUM('NL Resource Baseline Units:BE Resource Baseline Units'!G21) | H21: =SUM('NL Resource Baseline Units:BE Resource Baseline Units'!H21)
A22: Standard Laptops | D22: =SUM('NL Resource Baseline Units:BE Resource Baseline Units'!D22) | E22: =SUM('NL Resource Baseline Units:BE Resource Baseline Units'!E22) | F22: =SUM('NL Resource Baseline Units:BE Resource Baseline Units'!F22) | G22: =SUM('NL Resource Baseline Units:BE Resource Baseline Units'!G22) | H22: =SUM('NL Resource Baseline Units:BE Resource Baseline Units'!H22)
A23: Non-Standard Laptops | D23: =SUM('NL Resource Baseline Units:BE Resource Baseline Units'!D23) | E23: =SUM('NL Resource Baseline Units:BE Resource Baseline Units'!E23) | F23: =SUM('NL Resource Baseline Units:BE Resource Baseline Units'!F23) | G23: =SUM('NL Resource Baseline Units:BE Resource Baseline Units'!G23) | H23: =SUM('NL Resource Baseline Units:BE Resource Baseline Units'!H23)
A24: Standard Local Printers | D24: =SUM('NL Resource Baseline Units:BE Resource Baseline Units'!D24) | E24: =SUM('NL Resource Baseline Units:BE Resource Baseline Units'!E24) | F24: =SUM('NL Resource Baseline Units:BE Resource Baseline Units'!F24) | G24: =SUM('NL Resource Baseline Units:BE Resource Baseline Units'!G24) | H24: =SUM('NL Resource Baseline Units:BE Resource Baseline Units'!H24)
A25: Non-Standard Local Printers | D25: =SUM('NL Resource Baseline Units:BE Resource Baseline Units'!D25) | E25: =SUM('NL Resource Baseline Units:BE Resource Baseline Units'!E25) | F25: =SUM('NL Resource Baseline Units:BE Resource Baseline Units'!F25) | G25: =SUM('NL Resource Baseline Units:BE Resource Baseline Units'!G25) | H25: =SUM('NL Resource Baseline Units:BE Resource Baseline Units'!H25)
A26: Standard Network Printers | D26: =SUM('NL Resource Baseline Units:BE Resource Baseline Units'!D26) | E26: =SUM('NL Resource Baseline Units:BE Resource Baseline Units'!E26) | F26: =SUM('NL Resource Baseline Units:BE Resource Baseline Units'!F26) | G26: =SUM('NL Resource Baseline Units:BE Resource Baseline Units'!G26) | H26: =SUM('NL Resource Baseline Units:BE Resource Baseline Units'!H26)
A27: Non-Standard Network Printers | D27: =SUM('NL Resource Baseline Units:BE Resource Baseline Units'!D27) | E27: =SUM('NL Resource Baseline Units:BE Resource Baseline Units'!E27) | F27: =SUM('NL Resource Baseline Units:BE Resource Baseline Units'!F27) | G27: =SUM('NL Resource Baseline Units:BE Resource Baseline Units'!G27) | H27: =SUM('NL Resource Baseline Units:BE Resource Baseline Units'!H27)
A28: Other Peripherals | D28: =SUM('NL Resource Baseline Units:BE Resource Baseline Units'!D28) | E28: =SUM('NL Resource Baseline Units:BE Resource Baseline Units'!E28) | F28: =SUM('NL Resource Baseline Units:BE Resource Baseline Units'!F28) | G28: =SUM('NL Resource Baseline Units:BE Resource Baseline Units'!G28) | H28: =SUM('NL Resource Baseline Units:BE Resource Baseline Units'!H28)
D29: =SUM('NL Resource Baseline Units:BE Resource Baseline Units'!D29) | E29: =SUM('NL Resource Baseline Units:BE Resource Baseline Units'!E29) | F29: =SUM('NL Resource Baseline Units:BE Resource Baseline Units'!F29) | G29: =SUM('NL Resource Baseline Units:BE Resource Baseline Units'!G29) | H29: =SUM('NL Resource Baseline Units:BE Resource Baseline Units'!H29)
A30: Installations | D30: =SUM('NL Resource Baseline Units:BE Resource Baseline Units'!D30) | E30: =SUM('NL Resource Baseline Units:BE Resource Baseline Units'!E30) | F30: =SUM('NL Resource Baseline Units:BE Resource Baseline Units'!F30) | G30: =SUM('NL Resource Baseline Units:BE Resource Baseline Units'!G30) | H30: =SUM('NL Resource Baseline Units:BE Resource Baseline Units'!H30)
A31: Moves | D31: =SUM('NL Resource Baseline Units:BE Resource Baseline Units'!D31) | E31: =SUM('NL Resource Baseline Units:BE Resource Baseline Units'!E31) | F31: =SUM('NL Resource Baseline Units:BE Resource Baseline Units'!F31) | G31: =SUM('NL Resource Baseline Units:BE Resource Baseline Units'!G31) | H31: =SUM('NL Resource Baseline Units:BE Resource Baseline Units'!H31)
A32: Adds | D32: =SUM('NL Resource Baseline Units:BE Resource Baseline Units'!D32) | E32: =SUM('NL Resource Baseline Units:BE Resource Baseline Units'!E32) | F32: =SUM('NL Resource Baseline Units:BE Resource Baseline Units'!F32) | G32: =SUM('NL Resource Baseline Units:BE Resource Baseline Units'!G32) | H32: =SUM('NL Resource Baseline Units:BE Resource Baseline Units'!H32)
A33: Changes | D33: =SUM('NL Resource Baseline Units:BE Resource Baseline Units'!D33) | E33: =SUM('NL Resource Baseline Units:BE Resource Baseline Units'!E33) | F33: =SUM('NL Resource Baseline Units:BE Resource Baseline Units'!F33) | G33: =SUM('NL Resource Baseline Units:BE Resource Baseline Units'!G33) | H33: =SUM('NL Resource Baseline Units:BE Resource Baseline Units'!H33)
A35: Packaging & Distribution
A36: Packages Distributed per year | D36: =SUM('NL Resource Baseline Units:BE Resource Baseline Units'!D36) | E36: =SUM('NL Resource Baseline Units:BE Resource Baseline Units'!E36) | F36: =SUM('NL Resource Baseline Units:BE Resource Baseline Units'!F36) | G36: =SUM('NL Resource Baseline Units:BE Resource Baseline Units'!G36) | H36: =SUM('NL Resource Baseline Units:BE Resource Baseline Units'!H36)
A38: Service Desk
A39: Seats Supported | D39: =SUM('NL Resource Baseline Units:BE Resource Baseline Units'!D39) | E39: =SUM('NL Resource Baseline Units:BE Resource Baseline Units'!E39) | F39: =SUM('NL Resource Baseline Units:BE Resource Baseline Units'!F39) | G39: =SUM('NL Resource Baseline Units:BE Resource Baseline Units'!G39) | H39: =SUM('NL Resource Baseline Units:BE Resource Baseline Units'!H39)
A41: No. of actions per annum | D41: =SUM('NL Resource Baseline Units:BE Resource Baseline Units'!D41) | E41: =SUM('NL Resource Baseline Units:BE Resource Baseline Units'!E41) | F41: =SUM('NL Resource Baseline Units:BE Resource Baseline Units'!F41) | G41: =SUM('NL Resource Baseline Units:BE Resource Baseline Units'!G41) | H41: =SUM('NL Resource Baseline Units:BE Resource Baseline Units'!H41)
A42: Thereof registrated:
A43: Incident | D43: =SUM('NL Resource Baseline Units:BE Resource Baseline Units'!D43) | E43: =SUM('NL Resource Baseline Units:BE Resource Baseline Units'!E43) | F43: =SUM('NL Resource Baseline Units:BE Resource Baseline Units'!F43) | G43: =SUM('NL Resource Baseline Units:BE Resource Baseline Units'!G43) | H43: =SUM('NL Resource Baseline Units:BE Resource Baseline Units'!H43)
...

Sheet NL Resource Baseline Units
A1: NETHERLANDS RESOURCE BASELINE | B1: Resource Units | D1: Year 1 Annual Avg. | E1: Year 2 Annual Avg. | F1: Year 3 Annual Avg. | G1: Year 4 Annual Avg. | H1: Year 5 Annual Avg.
A2: EUC
A3: Support Services
A4: Medium Service Level
A5: Standard Desktops | D5: 10500 | E5: 10500 | F5: 10500 | G5: 10500 | H5: 10500
A6: Non-Standard Desktops | D6: 100 | E6: 100 | F6: 100 | G6: 100 | H6: 100
A7: Standard Laptops | D7: 2200 | E7: 2200 | F7: 2200 | G7: 2200 | H7: 2200
A8: Non-Standard Laptops | D8: 0 | E8: 0 | F8: 0 | G8: 0 | H8: 0
A9: Standard Local Printers | D9: 2000 | E9: 2000 | F9: 2000 | G9: 2000 | H9: 2000
A10: Non-Standard Local Printers
A11: Standard Network Printers
A12: Non-Standard Network Printers
A13: Other Peripherals
A15: Installations | D15: 2300 | E15: 1800 | F15: 1800 | G15: 1800 | H15: 1800
A16: Moves | D16: 2000 | E16: 2000 | F16: 2000 | G16: 2000 | H16: 2000
A17: Adds | D17: 200 | E17: 200 | F17: 200 | G17: 200 | H17: 200
A18: Changes | D18: 700 | E18: 700 | F18: 700 | G18: 700 | H18: 700
A19: Low Service Level
A20: Standard Desktops | D20: 30805 | E20: 30805 | F20: 30805 | G20: 30805 | H20: 30805
A21: Non-Standard Desktops | D21: 500 | E21: 500 | F21: 500 | G21: 500 | H21: 500
A22: Standard Laptops | D22: 2256 | E22: 2256 | F22: 2256 | G22: 2256 | H22: 2256
A23: Non-Standard Laptops | D23: 100 | E23: 100 | F23: 100 | G23: 100 | H23: 100
A24: Standard Local Printers | D24: 515.73959 | E24: 515.73959 | F24: 515.73959 | G24: 515.73959 | H24: 515.73959
A25: Non-Standard Local Printers | D25: 687.65278 | E25: 687.65278 | F25: 687.65278 | G25: 687.65278 | H25: 687.65278
A26: Standard Network Printers | D26: 3338.8246 | E26: 3338.8246 | F26: 3338.8246 | G26: 3338.8246 | H26: 3338.8246
A27: Non-Standard Network Printers | D27: 429.78299 | E27: 429.78299 | F27: 429.78299 | G27: 429.78299 | H27: 429.78299
A28: Other Peripherals | D28: 600 | E28: 600 | F28: 600 | G28: 600 | H28: 600
A30: Installations | D30: 2800 | E30: 2800 | F30: 2800 | G30: 2800 | H30: 2800
A31: Moves | D31: 11000 | E31: 11000 | F31: 11000 | G31: 11000 | H31: 11000
A32: Adds
A33: Changes | D33: 3100 | E33: 3100 | F33: 3100 | G33: 3100 | H33: 3100
A35: Packaging & Distribution
A36: Packages Distributed per year | D36: 960 | E36: 960 | F36: 960 | G36: 960 | H36: 960
A39: Seats Supported | D39: 38137 | E39: 38137 | F39: 38137 | G39: 38137 | H39: 38137
A41: No. of actions per annum | D41: 572055 | E41: 533918 | F41: 495781 | G41: 457644 | H41: 419507
A42: Thereof registrated:
A43: Incident | D43: 395810.79 | E43: 369423.4 | F43: 343036.02 | G43: 316648.63 | H43: 290261.25
A44: Question | D44: 62444.491 | E44: 58281.525 | F44: 54118.559 | G44: 49955.593 | H44: 45792.627
A45: Service Request | D45: 113799.72 | E45: 106213.07 | F45: 98626.424 | G45: 91039.776 | H45: 83453.128
A47: LAN Services
...

Sheet BE Resource Baseline Units
A1: BELGIUM RESOURCE BASELINE | B1: Resource Units | D1: Year 1 Annual Avg. | E1: Year 2 Annual Avg. | F1: Year 3 Annual Avg. | G1: Year 4 Annual Avg. | H1: Year 5 Annual Avg.
A2: EUC
A3: Support Services
A4: Medium Service Level
A5: Standard Desktops | D5: 5245 | E5: 5245 | F5: 5245 | G5: 5245 | H5: 5245
A6: Non-Standard Desktops
A7: Standard Laptops | D7: 856 | E7: 856 | F7: 856 | G7: 856 | H7: 856
A8: Non-Standard Laptops
A9: Standard Local Printers | D9: 2495.5 | E9: 2495.5 | F9: 2495.5 | G9: 2495.5 | H9: 2495.5
A10: Non-Standard Local Printers
A11: Standard Network Printers | D11: 359 | E11: 359 | F11: 359 | G11: 359 | H11: 359
A12: Non-Standard Network Printers | D12: 93 | E12: 93 | F12: 93 | G12: 93 | H12: 93
A13: Other Peripherals
A15: Installations | D15: 682 | E15: 682 | F15: 682 | G15: 682 | H15: 682
A16: Moves | D16: 1085 | E16: 1085 | F16: 1085 | G16: 1085 | H16: 1085
A17: Adds
A18: Changes | D18: 899 | E18: 899 | F18: 899 | G18: 899 | H18: 899
A19: Low Service Level
A20: Standard Desktops | D20: 12049 | E20: 12049 | F20: 12049 | G20: 12049 | H20: 12049
A21: Non-Standard Desktops
A22: Standard Laptops | D22: 967 | E22: 967 | F22: 967 | G22: 967 | H22: 967
A23: Non-Standard Laptops
A24: Standard Local Printers | D24: 5554.5 | E24: 5554.5 | F24: 5554.5 | G24: 5554.5 | H24: 5554.5
A25: Non-Standard Local Printers
A26: Standard Network Printers | D26: 800 | E26: 800 | F26: 800 | G26: 800 | H26: 800
A27: Non-Standard Network Printers | D27: 207 | E27: 207 | F27: 207 | G27: 207 | H27: 207
A28: Other Peripherals
A30: Installations | D30: 1518 | E30: 1518 | F30: 1518 | G30: 1518 | H30: 1518
A31: Moves | D31: 2415 | E31: 2415 | F31: 2415 | G31: 2415 | H31: 2415
A32: Adds
A33: Changes | D33: 2001 | E33: 2001 | F33: 2001 | G33: 2001 | H33: 2001
A35: Packaging & Distribution
A36: Packages Distributed per year | D36: 991 | E36: 970 | F36: 970 | G36: 970 | H36: 970
A38: Service Desk
A39: Seats Supported | D39: 15530 | E39: 15530 | F39: 15530 | G39: 15530 | H39: 15530
A41: No. of actions per annum | D41: 232950 | E41: 217420 | F41: 201890 | G41: 186360 | H41: 170830
A42: Thereof registrated:
A43: Incident | D43: 140188.47 | E43: 130842.57 | F43: 121496.68 | G43: 112150.78 | H43: 102804.88
A44: Question | D44: 12554.192 | E44: 11717.246 | F44: 10880.299 | G44: 10043.353 | H44: 9206.4072
A45: Service Request | D45: 80207.335 | E45: 74860.18 | F45: 69513.024 | G45: 64165.868 | H45: 58818.713
...
