Workbook

Sheet Title Sheet
B2: GlobalPharma AG
B5: ATTACHMENT 4-D 1
B7: Volumetrics
B8: Attachment to Exhibit 4 (Pricing and Financial Provisions)
B14: This document contains confidential and proprietary information of GlobalPharma AG. It is furnished for the performance of The Agreements only. Except with the express prior written permission of GlobalPharma AG, this document and the information contained herein may not be published, disclosed, or used for any other purpose.

Sheet Switzerland
A1: Switzerland
A2: Description | B2: Base Year Monthly Avg. | C2: Year 1 Monthly Avg. | D2: Year 2 Monthly Avg. | E2: Year 3 Monthly Avg. | F2: Year 4 Monthly Avg. | G2: Year 5 Monthly Avg. | H2: Year 6 Monthly Avg. | I2: Year 7 Monthly Avg.
A3: Accounts Payable
A4: Invoice Processing | B4: =SUM(B5:B13) | K4: Invoices | L4: FTE | M4: BC
A5: Manual Invoices - Purchase Order | B5: =15400+600 | C5: 15600 | D5: 15600 | E5: 15600 | F5: 15500 | G5: 15500 | H5: 15500 | I5: 15500 | K5: =SUM(I5:I13)
A6: Manual Invoices - Non-Purchase Order | B6: =3700+100 | C6: 3900 | D6: 4000 | E6: 4100 | F6: 4200 | G6: 4300 | H6: 4300 | I6: 4300 | K6: =SUM(USA!I11)
A7: Electronic Invoices - Purchase Order | B7: =3600+600 | C7: 5200 | D7: 5600 | E7: 6000 | F7: 6500 | G7: 7000 | H7: 7000 | I7: 7000 | K7: =SUM(France!I5:I8)
A8: Electronic Invoices - BATCH INPUT PROCESS | B8: 25 | C8: 25 | D8: 25 | E8: 25 | F8: 25 | G8: 25 | H8: 25 | I8: 25 | K8: =SUM(Germany!I5:I14)
A9: Pre-booking | B9: 670 | C9: 680 | D9: 690 | E9: 700 | F9: 710 | G9: 720 | H9: 720 | I9: 720 | K9: =SUM(Italy!I5:I9)
A10: Internal manual postings ( adjustments, corrections, etc...) | B10: 500 | C10: 510 | D10: 520 | E10: 530 | F10: 540 | G10: 550 | H10: 550 | I10: 550 | K10: =SUM(Spain!I5:I9)
A11: Follow up activities for blooked invoices ( no.of pending blooked inv./month) initial pendings / Quantity 3700 = 19 % / Price 750 = 3,8 % | B11: 1700 | C11: 1700 | D11: 1700 | E11: 1700 | F11: 1700 | G11: 1700 | H11: 1700 | I11: 1700 | K11: =SUM(UK!I5:I7)
A12: Electronic Invoices - Non-Purchase Order | K12: 48600 | L12: 44 | M12: 2020058
A13: Consolidated Invoices | B13: 3 | C13: 3 | D13: 3 | E13: 3 | F13: 3 | G13: 3 | H13: 3 | I13: 3 | K13: =SUM(K5:K12)
A14: Payments (Check Printing and Disbursement) | B14: =SUM(B15:B18) | K14: cost per Invoice | M14: =+M12/K13 | N14: Final Yr
A15: Payments - Normal Handling | B15: 10800 | C15: 11050 | D15: 11300 | E15: 11550 | F15: 11800 | G15: 12000 | H15: 12000 | I15: 12000 | K15: inv. Processed per FTE | M15: =(+K13/220)/44
A16: Payments - Checks Requiring Special Handling
A17: Payments - Electronic Disbursement (manual postings of ebanking) | B17: 60 | C17: 60 | D17: 60 | E17: 60 | F17: 60 | G17: 60 | H17: 60 | I17: 60
A18: Payments - Wire Disbursement
A19: Vendor Management | B19: =SUM(B20:B22)
A20: Vendor Set Up (open & maintenance master datas) | B20: 370 | C20: 370 | D20: 370 | E20: 370 | F20: 370 | G20: 370 | H20: 370 | I20: 370
A21: Vendor Inquiry ( reminders & requests) | B21: 1100 | C21: 1130 | D21: 1150 | E21: 1180 | F21: 1200 | G21: 1220 | H21: 1220 | I21: 1220
A22: Year End Vendor Tax Reporting
A23: Order to Cash
A24: Customer Inquiries | B24: =SUM(B25:B27)
A25: Internal Inquiries (aging list / provision / bad debts) | B25: 1 | C25: 1 | D25: 1 | E25: 1 | F25: 1 | G25: 1 | H25: 1 | I25: 1
A26: Internal Inquiries IC | B26: 20 | C26: 20 | D26: 20 | E26: 20 | F26: 20 | G26: 20 | H26: 20 | I26: 20
A27: External Inquiries | B27: 3 | C27: 3 | D27: 3 | E27: 3 | F27: 3 | G27: 3 | H27: 3 | I27: 3
A28: Invoicing | B28: =SUM(B29:B32)
A29: Paper Invoices ( on template /miscellaneous) | B29: 50 | C29: 45 | D29: 40 | E29: 40 | F29: 35 | G29: 35 | H29: 35 | I29: 35
A30: Electronic Invoices ( SCM process)for information purposes only | B30: 4200 | C30: 4200 | D30: 4200 | E30: 4200 | F30: 4200 | G30: 4200 | H30: 4200 | I30: 4200
A31: Electronic Invoices (SUNDRY invoices)for information purposes only | B31: 600 | C31: 620 | D31: 640 | E31: 640 | F31: 640 | G31: 640 | H31: 640 | I31: 640
A32: Customer Statements
A33: Cash Applications | B33: =SUM(B34:B37)
A34: Electronic Payments (bank credit advices) | B34: 290 | C34: 300 | D34: 310 | E34: 310 | F34: 310 | G34: 310 | H34: 310 | I34: 310
A35: Electronic Payments (intercomapy clearing process automated from 07) 70/80 companies | B35: 2500 | C35: 2500 | D35: 2500 | E35: 2500 | F35: 2500 | G35: 2500 | H35: 2500 | I35: 2500
A36: Lockbox Payments
A37: Check Payments
A38: Collections | B38: =SUM(B39:B40)
A39: Actively Managed Accounts (with open balance) | B39: 360 | C39: 360 | D39: 360 | E39: 360 | F39: 360 | G39: 360 | H39: 360 | I39: 360
A40: Dunning letters | B40: 125 | C40: 125 | D40: 125 | E40: 125 | F40: 125 | G40: 125 | H40: 125 | I40: 125
...

Sheet USA
A1: United States
A2: Description | B2: Base Year Monthly Avg. | C2: Year 1 Monthly Avg. | D2: Year 2 Monthly Avg. | E2: Year 3 Monthly Avg. | F2: Year 4 Monthly Avg. | G2: Year 5 Monthly Avg. | H2: Year 6 Monthly Avg. | I2: Year 7 Monthly Avg.
A3: Accounts Payable
A4: Invoice Processing
A5: Manual Invoices - Purchase Order | B5: 4573.5833 | C5: 5305.3567 | D5: 6154.2137 | E5: 7138.8879 | F5: 8281.11 | G5: 9606.0876 | H5: 11143.062 | I5: 12925.951
A6: Manual Invoices - Non-Purchase Order | B6: 2532.8333 | C6: 2938.0867 | D6: 3408.1805 | E6: 3953.4894 | F6: 4586.0477 | G6: 5319.8154 | H6: 6170.9858 | I6: 7158.3436
A7: Electronic Invoices - Purchase Order | B7: 13839.5 | C7: 16053.82 | D7: 18622.431 | E7: 21602.02 | F7: 25058.343 | G7: 29067.678 | H7: 33718.507 | I7: 39113.468
A8: Electronic Invoices - Non-Purchase Order | B8: 3941.5 | C8: 4572.14 | D8: 5303.6824 | E8: 6152.2716 | F8: 7136.635 | G8: 8278.4966 | H8: 9603.0561 | I8: 11139.545
A9: P-Cards | B9: 4633 | C9: 5374.28 | D9: 6234.1648 | E9: 7231.6312 | F9: 8388.6922 | G9: 9730.8829 | H9: 11287.824 | I9: 13093.876
A10: GlobalPharma Events Central (NEC) - Field Sales Force Related Checks (see RTP Key Assumptions) | B10: 6966.1667 | C10: 8777.37 | D10: 11059.486 | E10: 13934.953 | F10: 17558.04 | G10: 22123.131 | H10: 27875.145 | I10: 35122.682
A11: Consolidated Invoices - Including GlobalPharma Events Central (NEC) | B11: 36486.583 | C11: 42324.437 | D11: 49096.347 | E11: 56951.762 | F11: 66064.044 | G11: 76634.291 | H11: 88895.777 | I11: 103119.1
A12: Payments (Check Printing and Disbursement)
A13: Payments - Normal Handling | B13: 12145.5 | C13: 14088.78 | D13: 16342.985 | E13: 18957.862 | F13: 21991.12 | G13: 25509.7 | H13: 29591.252 | I13: 34325.852
A14: Payments - GlobalPharma Events Central (NEC) - Field Sales Force Related Checks (see RTP Key Assumptions) | B14: 6966.1667 | C14: 8777.37 | D14: 11059.486 | E14: 13934.953 | F14: 17558.04 | G14: 22123.131 | H14: 27875.145 | I14: 35122.682
A15: Payments - Checks Requiring Special Handling | B15: 614.33333 | C15: 712.62667 | D15: 826.64693 | E15: 958.91044 | F15: 1112.3361 | G15: 1290.3099 | H15: 1496.7595 | I15: 1736.241
A16: Payments - Electronic Disbursement | B16: 1666.6667 | C16: 1933.3333 | D16: 2242.6667 | E16: 2601.4933 | F16: 3017.7323 | G16: 3500.5694 | H16: 4060.6605 | I16: 4710.3662
A17: Payments - Wire Disbursement | B17: 72.666667 | C17: 84.293333 | D17: 97.780267 | E17: 113.42511 | F17: 131.57313 | G17: 152.62483 | H17: 177.0448 | I17: 205.37197
A18: Vendor Management
A19: Vendor Set Up | B19: 208.16667 | C19: 241.47333 | D19: 280.10907 | E19: 324.92652 | F19: 376.91476 | G19: 437.22112 | H19: 507.1765 | I19: 588.32474
A20: Vendor Inquiry | B20: n/a | C20: n/a | E20: n/a | F20: n/a | G20: n/a | H20: n/a | I20: n/a
A21: Year End Vendor Tax Reporting (2005 - Reported in 2006) | B21: 916.66667 | C21: 1063.3333 | D21: 1233.4667 | E21: 1430.8213 | F21: 1659.7527 | G21: 1925.3132 | H21: 2233.3633 | I21: 2590.7014
A22: Order to Cash
A23: Collections
A24: Actively Managed Accounts
A25: Ophtha OTC Accounts | B25: 835 | C25: 920 | D25: 1000 | E25: 1100 | F25: 1210 | G25: 1330 | H25: 1465 | I25: 1610
A26: Deduction Management (items >$250) | B26: 1270 | C26: 1310 | D26: 1375 | E26: 1500 | F26: 1575 | G26: 1650 | H26: 1730 | I26: 1820
A27: Ophtha Advertising Deduction Management | B27: 100 | C27: 105 | D27: 110 | E27: 116 | F27: 122 | G27: 128 | H27: 134 | I27: 141
A28: Ophtha Coupons Deduction Management | B28: 67 | C28: 70 | D28: 73 | E28: 77 | F28: 80 | G28: 84 | H28: 88 | I28: 92
A29: Fixed Assets
A30: Fixed Assets
A31: Active Assets (Or) | B31: 16500 | C31: 17460 | D31: 17548 | E31: 17644.8 | F31: 17741.6 | G31: 17741.6 | H31: 17741.6 | I31: 17741.6
A32: Asset Record Changes | B32: 80 | C32: 88 | D32: 96.8 | E32: 96.8 | F32: 96.8 | G32: 96.8 | H32: 96.8 | I32: 80
A33: Account to Report
A34: General Ledger Accounting
A35: Chart of Account Change | B35: 27.083333 | C35: 27.083333 | D35: 27.083333 | E35: 27.083333 | F35: 27.083333 | G35: 27.083333 | H35: 27.083333 | I35: 27.083333
A36: Inter-Company Transactions | B36: 1000 | C36: 1000 | D36: 1000 | E36: 1000 | F36: 1000 | G36: 1000 | H36: 1000 | I36: 1000
A37: Cost Center Change | B37: 81.25 | C37: 81.25 | D37: 81.25 | E37: 81.25 | F37: 81.25 | G37: 81.25 | H37: 81.25 | I37: 81.25
A38: Financial Management Services
A39: Bank Reconciliation - Pharma | B39: 13 | C39: 13 | D39: 13 | E39: 13 | F39: 13 | G39: 13 | H39: 13 | I39: 13
A40: Bank Reconciliations - USCO | B40: 13 | C40: 13 | D40: 13 | E40: 13 | F40: 13 | G40: 13 | H40: 13 | I40: 13

Sheet France
A1: France
A2: Description | B2: Base Year Monthly Avg. | C2: Year 1 Monthly Avg. | D2: Year 2 Monthly Avg. | E2: Year 3 Monthly Avg. | F2: Year 4 Monthly Avg. | G2: Year 5 Monthly Avg. | H2: Year 6 Monthly Avg. | I2: Year 7 Monthly Avg.
A3: Accounts Payable
A4: Invoice Processing | K4: 1.03
A5: Manual Invoices - Purchase Order | B5: 725 | C5: =B5*$K$4 | D5: =C5*$K$4 | E5: =D5*$K$4 | F5: =E5*$K$4 | G5: =F5*$K$4 | H5: =G5*$K$4 | I5: =H5*$K$4
A6: Manual Invoices - Non-Purchase Order | B6: 1705 | C6: =B6*$K$4 | D6: =C6*$K$4 | E6: =D6*$K$4 | F6: =E6*$K$4 | G6: =F6*$K$4 | H6: =G6*$K$4 | I6: =H6*$K$4
A7: Electronic Invoices - Purchase Order | B7: 0 | C7: =B7*$K$4 | D7: =C7*$K$4 | E7: =D7*$K$4 | F7: =E7*$K$4 | G7: =F7*$K$4 | H7: =G7*$K$4 | I7: =H7*$K$4
A8: Electronic Invoices - Non-Purchase Order | B8: 70 | C8: =B8*$K$4 | D8: =C8*$K$4 | E8: =D8*$K$4 | F8: =E8*$K$4 | G8: =F8*$K$4 | H8: =G8*$K$4 | I8: =H8*$K$4
A9: Payments (Check Printing and Disbursement)
A10: Payments - Normal Handling (number of SAP payment runs) | B10: 12 | C10: =B10*$K$4 | D10: =C10*$K$4 | E10: =D10*$K$4 | F10: =E10*$K$4 | G10: =F10*$K$4 | H10: =G10*$K$4 | I10: =H10*$K$4
A11: Payments - Checks Requiring Special Handling | B11: 650 | C11: =B11*$K$4 | D11: =C11*$K$4 | E11: =D11*$K$4 | F11: =E11*$K$4 | G11: =F11*$K$4 | H11: =G11*$K$4 | I11: =H11*$K$4
A12: Payments - Electronic Disbursement (number of SAP payment runs) | B12: 16 | C12: =B12*$K$4 | D12: =C12*$K$4 | E12: =D12*$K$4 | F12: =E12*$K$4 | G12: =F12*$K$4 | H12: =G12*$K$4 | I12: =H12*$K$4
A13: Vendor Management
A14: Vendor Set Up | B14: 250 | C14: =B14*$K$4 | D14: =C14*$K$4 | E14: =D14*$K$4 | F14: =E14*$K$4 | G14: =F14*$K$4 | H14: =G14*$K$4 | I14: =H14*$K$4
A15: Vendor Inquiry | B15: 15 | C15: =B15*$K$4 | D15: =C15*$K$4 | E15: =D15*$K$4 | F15: =E15*$K$4 | G15: =F15*$K$4 | H15: =G15*$K$4 | I15: =H15*$K$4
A16: Travel and Entertainment
A17: Employee Expense Reports
A18: Manual Employee Expense Reports | B18: 245 | C18: =B18*$K$4 | D18: =C18*$K$4 | E18: =D18*$K$4 | F18: =E18*$K$4 | G18: =F18*$K$4 | H18: =G18*$K$4 | I18: =H18*$K$4
A19: Electronic Employee Expense Reports (Or) | B19: 3096 | C19: =B19*$K$4 | D19: =C19*$K$4 | E19: =D19*$K$4 | F19: =E19*$K$4 | G19: =F19*$K$4 | H19: =G19*$K$4 | I19: =H19*$K$4
A20: Employees Submitting Expense Reports | B20: 1550 | C20: =B20*$K$4 | D20: =C20*$K$4 | E20: =D20*$K$4 | F20: =E20*$K$4 | G20: =F20*$K$4 | H20: =G20*$K$4 | I20: =H20*$K$4
A21: Order to Cash
A22: Credit
A23: Credit Applications Processed - Standard | B23: 320 | C23: =B23*$K$4 | D23: =C23*$K$4 | E23: =D23*$K$4 | F23: =E23*$K$4 | G23: =F23*$K$4 | H23: =G23*$K$4 | I23: =H23*$K$4
A24: Credit Application Processed - Special/Outside Policy | B24: 25 | C24: =B24*$K$4 | D24: =C24*$K$4 | E24: =D24*$K$4 | F24: =E24*$K$4 | G24: =F24*$K$4 | H24: =G24*$K$4 | I24: =H24*$K$4
A25: Credit Review Processed | B25: 20 | C25: =B25*$K$4 | D25: =C25*$K$4 | E25: =D25*$K$4 | F25: =E25*$K$4 | G25: =F25*$K$4 | H25: =G25*$K$4 | I25: =H25*$K$4
A26: Order Entry
A27: Manual Orders Processed | B27: 5610 | C27: =B27*$K$4 | D27: =C27*$K$4 | E27: =D27*$K$4 | F27: =E27*$K$4 | G27: =F27*$K$4 | H27: =G27*$K$4 | I27: =H27*$K$4
A28: Electronic Orders Processed | B28: 2420 | C28: =B28*$K$4 | D28: =C28*$K$4 | E28: =D28*$K$4 | F28: =E28*$K$4 | G28: =F28*$K$4 | H28: =G28*$K$4 | I28: =H28*$K$4
A29: Customer Inquiries
A30: Internal Inquiries | B30: 277 | C30: =B30*$K$4 | D30: =C30*$K$4 | E30: =D30*$K$4 | F30: =E30*$K$4 | G30: =F30*$K$4 | H30: =G30*$K$4 | I30: =H30*$K$4
A31: External Inquiries | C31: =B31*$K$4 | D31: =C31*$K$4 | E31: =D31*$K$4 | F31: =E31*$K$4 | G31: =F31*$K$4 | H31: =G31*$K$4 | I31: =H31*$K$4
A32: Invoicing
A33: Paper Invoices | B33: 10490 | C33: =B33*$K$4 | D33: =C33*$K$4 | E33: =D33*$K$4 | F33: =E33*$K$4 | G33: =F33*$K$4 | H33: =G33*$K$4 | I33: =H33*$K$4
A34: Electronic Invoices | B34: 0 | C34: =B34*$K$4 | D34: =C34*$K$4 | E34: =D34*$K$4 | F34: =E34*$K$4 | G34: =F34*$K$4 | H34: =G34*$K$4 | I34: =H34*$K$4
A35: Customer Statements | B35: 900 | C35: =B35*$K$4 | D35: =C35*$K$4 | E35: =D35*$K$4 | F35: =E35*$K$4 | G35: =F35*$K$4 | H35: =G35*$K$4 | I35: =H35*$K$4
A36: Cash Applications
A37: Electronic Payments | B37: 680 | C37: =B37*$K$4 | D37: =C37*$K$4 | E37: =D37*$K$4 | F37: =E37*$K$4 | G37: =F37*$K$4 | H37: =G37*$K$4 | I37: =H37*$K$4
A38: Lockbox Payments | B38: 0 | C38: =B38*$K$4 | D38: =C38*$K$4 | E38: =D38*$K$4 | F38: =E38*$K$4 | G38: =F38*$K$4 | H38: =G38*$K$4 | I38: =H38*$K$4
A39: Check Payments | B39: 6100 | C39: =B39*$K$4 | D39: =C39*$K$4 | E39: =D39*$K$4 | F39: =E39*$K$4 | G39: =F39*$K$4 | H39: =G39*$K$4 | I39: =H39*$K$4
A40: Collections
...

Sheet Germany
A1: Germany
A2: Description | B2: Base Year Monthly Avg. | C2: Year 1 Monthly Avg. | D2: Year 2 Monthly Avg. | E2: Year 3 Monthly Avg. | F2: Year 4 Monthly Avg. | G2: Year 5 Monthly Avg. | H2: Year 6 Monthly Avg. | I2: Year 7 Monthly Avg.
A3: Accounts Payable
A4: Invoice Processing | B4: =SUM(B5:B14)
A5: Manual Invoices - Purchase Order | B5: 1583 | C5: =B5*1.02 | D5: =C5*1.02 | E5: =D5*1.02 | F5: =E5*1.02 | G5: =F5*1.02 | H5: =G5*1.02 | I5: =H5*1.02
A6: Manual Invoices - Purchase Order by line items | B6: 6511 | C6: =B6*1.02 | D6: =C6*1.02 | E6: =D6*1.02 | F6: =E6*1.02 | G6: =F6*1.02 | H6: =G6*1.02 | I6: =H6*1.02
A7: Manual Invoices - Non-Purchase Order | B7: =(2288+926)*1.3 | C7: =B7*1.02 | D7: =C7*1.02 | E7: =D7*1.02 | F7: =E7*1.02 | G7: =F7*1.02 | H7: =G7*1.02 | I7: =H7*1.02
A8: Manual Invoices - Non-Purchase Order by line items | B8: =(7679+2976)*1.3 | C8: =B8*1.02 | D8: =C8*1.02 | E8: =D8*1.02 | F8: =E8*1.02 | G8: =F8*1.02 | H8: =G8*1.02 | I8: =H8*1.02
A9: Electronic Invoices - Purchase Order | B9: 736 | C9: =B9*1.02 | D9: =C9*1.02 | E9: =D9*1.02 | F9: =E9*1.02 | G9: =F9*1.02 | H9: =G9*1.02 | I9: =H9*1.02
A10: Electronic Invoices - Purchase Order by line item | B10: 4788 | C10: =B10*1.02 | D10: =C10*1.02 | E10: =D10*1.02 | F10: =E10*1.02 | G10: =F10*1.02 | H10: =G10*1.02 | I10: =H10*1.02
A11: Electronic Invoices - Non-Purchase Order | B11: 1070 | C11: =B11*1.02 | D11: =C11*1.02 | E11: =D11*1.02 | F11: =E11*1.02 | G11: =F11*1.02 | H11: =G11*1.02 | I11: =H11*1.02
A12: Electronic Invoices - Non-Purchase Order by line item | B12: 9533 | C12: =B12*1.02 | D12: =C12*1.02 | E12: =D12*1.02 | F12: =E12*1.02 | G12: =F12*1.02 | H12: =G12*1.02 | I12: =H12*1.02
A13: Batch Input | B13: 1412 | C13: =B13*1.02 | D13: =C13*1.02 | E13: =D13*1.02 | F13: =E13*1.02 | G13: =F13*1.02 | H13: =G13*1.02 | I13: =H13*1.02
A14: Batch Input by line item | B14: 4231 | C14: =B14*1.02 | D14: =C14*1.02 | E14: =D14*1.02 | F14: =E14*1.02 | G14: =F14*1.02 | H14: =G14*1.02 | I14: =H14*1.02
A15: Payments (Check Printing and Disbursement) | B15: =SUM(B16:B20)
A16: Payments - Normal Handling | B16: 613 | C16: =B16*1.02 | D16: =C16*1.02 | E16: =D16*1.02 | F16: =E16*1.02 | G16: =F16*1.02 | H16: =G16*1.02 | I16: =H16*1.02
A17: Payments - Normal Handling | B17: 1231 | C17: =B17*1.02 | D17: =C17*1.02 | E17: =D17*1.02 | F17: =E17*1.02 | G17: =F17*1.02 | H17: =G17*1.02 | I17: =H17*1.02
A18: Payments - Electronic Disbursement | B18: 4497 | C18: =B18*1.02 | D18: =C18*1.02 | E18: =D18*1.02 | F18: =E18*1.02 | G18: =F18*1.02 | H18: =G18*1.02 | I18: =H18*1.02
A19: Payments - Electronic Disbursement by line item | B19: 9123 | C19: =B19*1.02 | D19: =C19*1.02 | E19: =D19*1.02 | F19: =E19*1.02 | G19: =F19*1.02 | H19: =G19*1.02 | I19: =H19*1.02
A20: Payments - Wire Disbursement
A21: Vendor Management | B21: =SUM(B22:B25)
A22: Vendor Set Up | B22: 175 | C22: =B22 | D22: =C22 | E22: =D22 | F22: =E22 | G22: =F22 | H22: =G22 | I22: =H22
A23: Vendor Inquiry | B23: 300 | C23: =B23 | D23: =C23 | E23: =D23 | F23: =E23 | G23: =F23 | H23: =G23 | I23: =H23
A24: Internal Inquiries re. Vendors and payments | B24: 700 | C24: =B24 | D24: =C24 | E24: =D24 | F24: =E24 | G24: =F24 | H24: =G24 | I24: =H24
A25: Year End Vendor Tax Reporting | B25: 0 | C25: =B25 | D25: =C25 | E25: =D25 | F25: =E25 | G25: =F25 | H25: =G25 | I25: =H25
A26: Travel and Entertainment
A27: Employee Expense Reports | B27: =SUM(B28:B31)
A28: Manual Employee Expense Reports | B28: 15 | C28: 15 | D28: 15 | E28: 15 | F28: 15 | G28: 15 | H28: 15 | I28: 15
A29: Electronic Employee Expense Reports | B29: 1622 | C29: 1622 | D29: 1622 | E29: 1622 | F29: 1622 | G29: 1622 | H29: 1622 | I29: 1622
A30: Electronic Employee Expense Reports | B30: 10276 | C30: 10276 | D30: 10276 | E30: 10276 | F30: 10276 | G30: 10276 | H30: 10276 | I30: 10276
A31: Employees Submitting Expense Reports | B31: =1100+250 | C31: =1100+250 | D31: =1100+250 | E31: =1100+250 | F31: =1100+250 | G31: =1100+250 | H31: =1100+250 | I31: =1100+250
A32: Order to Cash
A33: Credit | B33: =SUM(B34:B36)
A34: Credit Applications Processed - Standard | B34: 60 | C34: =B34 | D34: =C34 | E34: =D34 | F34: =E34 | G34: =F34 | H34: =G34 | I34: =H34
A35: Credit Application Processed - Special/Outside Policy | B35: 350 | C35: =B35 | D35: =C35 | E35: =D35 | F35: =E35 | G35: =F35 | H35: =G35 | I35: =H35
A36: Credit Review Processed | B36: 300 | C36: =B36 | D36: =C36 | E36: =D36 | F36: =E36 | G36: =F36 | H36: =G36 | I36: =H36
A37: Customer Inquiries | B37: =SUM(B38:B39)
A38: Internal Inquiries | B38: 1300 | C38: =B38 | D38: =C38 | E38: =D38 | F38: =E38 | G38: =F38 | H38: =G38 | I38: =H38
A39: External Inquiries | B39: 1450 | C39: =B39 | D39: =C39 | E39: =D39 | F39: =E39 | G39: =F39 | H39: =G39 | I39: =H39
A40: Invoicing | B40: =SUM(B41:B44)
...

Sheet Italy
A1: Italy
A2: Description | B2: Base Year Monthly Avg. | C2: Year 1 Monthly Avg. | D2: Year 2 Monthly Avg. | E2: Year 3 Monthly Avg. | F2: Year 4 Monthly Avg. | G2: Year 5 Monthly Avg. | H2: Year 6 Monthly Avg. | I2: Year 7 Monthly Avg.
A3: Accounts Payable
A4: Invoice Processing
A5: Manual Invoices - Purchase Order | B5: =2450-601 | C5: =+B5*1.02 | D5: =+C5*1.02 | E5: =+D5*1.02 | F5: =+E5*1.02 | G5: =+F5*1.02 | H5: =+G5*1.02 | I5: =+H5*1.02
A6: Manual Invoices - Non-Purchase Order | B6: 601 | C6: =+B6*1.02 | D6: =+C6*1.02 | E6: =+D6*1.02 | F6: =+E6*1.02 | G6: =+F6*1.02 | H6: =+G6*1.02 | I6: =+H6*1.02
A7: Electronic Invoices - Purchase Order | B7: 3 | C7: =+B7 | D7: =+C7 | E7: =+D7 | F7: =+E7 | G7: =+F7 | H7: =+G7 | I7: =+H7
A8: Electronic Invoices - Non-Purchase Order | B8: 0 | C8: =+B8 | D8: =+C8 | E8: =+D8 | F8: =+E8 | G8: =+F8 | H8: =+G8 | I8: =+H8
A9: Consolidated Invoices
A10: Payments (Check Printing and Disbursement)
A11: Payments - Normal Handling | B11: 150 | C11: =+B11*1.02 | D11: =+C11*1.02 | E11: =+D11*1.02 | F11: =+E11*1.02 | G11: =+F11*1.02 | H11: =+G11*1.02 | I11: =+H11*1.02
A12: Payments - Checks Requiring Special Handling | B12: 0 | C12: =+B12 | D12: =+C12 | E12: =+D12 | F12: =+E12 | G12: =+F12 | H12: =+G12 | I12: =+H12
A13: Payments - Electronic Disbursement | B13: 1800 | C13: =+B13*1.02 | D13: =+C13*1.02 | E13: =+D13*1.02 | F13: =+E13*1.02 | G13: =+F13*1.02 | H13: =+G13*1.02 | I13: =+H13*1.02
A14: Payments - Wire Disbursement | B14: 0 | C14: =+B14 | D14: =+C14 | E14: =+D14 | F14: =+E14 | G14: =+F14 | H14: =+G14 | I14: =+H14
A15: Vendor Management
A16: Vendor Set Up | B16: =+(1300+300)/12 | C16: =+(1300+300)/12 | D16: =+(1300+300)/12 | E16: =+(1300+300)/12 | F16: =+(1300+300)/12 | G16: =+(1300+300)/12 | H16: =+(1300+300)/12 | I16: =+(1300+300)/12
A17: Vendor Inquiry | B17: 400 | C17: =+B17 | D17: =+C17 | E17: =+D17 | F17: =+E17 | G17: =+F17 | H17: =+G17 | I17: =+H17
A18: Travel and Entertainment
A19: Employee Expense Reports
A20: Manual Employee Expense Reports | B20: =440/6 | C20: =+B20/2 | D20: 0 | E20: =+D20 | F20: =+E20 | G20: =+F20 | H20: =+G20 | I20: =+H20
A21: Electronic Employee Expense Reports | B21: =1550-B20 | C21: =1550-C20 | D21: =1550-D20 | E21: =1550-E20 | F21: =1550-F20 | G21: =1550-G20 | H21: =1550-H20 | I21: =1550-I20
A22: Employees Submitting Expense Reports
A23: Order to Cash
A24: Credit
A25: Credit Applications Processed - Standard | B25: =+(532+389+391+2162+30204+1566+86+4127+789+1626+533+84+226+31+20+9+184+14+66+612+4+1+1+198+1+5+42+55)/12 | C25: =+B25 | D25: =+C25 | E25: =+D25 | F25: =+E25 | G25: =+F25 | H25: =+G25 | I25: =+H25
A26: Credit Review Processed | B26: =+(121+97+2+3+16)/12 | C26: =+B26 | D26: =+C26 | E26: =+D26 | F26: =+E26 | G26: =+F26 | H26: =+G26 | I26: =+H26
A27: Invoicing
A28: Paper Invoices | B28: =7194+118 | C28: =7709-C29 | D28: =7709-D29 | E28: =7709-E29 | F28: =7709-F29 | G28: =7709-G29 | H28: =7709-H29 | I28: =7709-I29
A29: Electronic Invoices | B29: 397.41667 | C29: =+B29*1.1 | D29: =+C29*1.1 | E29: =+D29*1.1 | F29: =+E29*1.1 | G29: =+F29*1.1 | H29: =+G29*1.1 | I29: =+H29*1.1
A30: Customer Statements | B30: =(76592-26620-9240)/12+2574/12 | C30: =+B30 | D30: =+C30 | E30: =+D30 | F30: =+E30 | G30: =+F30 | H30: =+G30 | I30: =+H30
A31: Cash Applications
A32: Electronic Payments | B32: =1854-18+1385 | C32: =+B32 | D32: =+C32 | E32: =+D32 | F32: =+E32 | G32: =+F32 | H32: =+G32 | I32: =+H32
A33: Lockbox Payments
A34: Check Payments | B34: =+(197+6+7+1)/12 | C34: =+B34 | D34: =+C34 | E34: =+D34 | F34: =+E34 | G34: =+F34 | H34: =+G34 | I34: =+H34
A35: Collections
A36: Actively Managed Accounts | B36: =1149+23 | C36: =+B36 | D36: =+C36 | E36: =+D36 | F36: =+E36 | G36: =+F36 | H36: =+G36 | I36: =+H36
A37: Inquiries
A38: customer external inquiries | B38: 300
A39: customer internal inquiries | B39: 1000
A40: manual order processed | B40: 118
...

Sheet Spain
A1: Spain
A2: Description | B2: Base Year Monthly Avg. | C2: Year 1 Monthly Avg. | D2: Year 2 Monthly Avg. | E2: Year 3 Monthly Avg. | F2: Year 4 Monthly Avg. | G2: Year 5 Monthly Avg. | H2: Year 6 Monthly Avg. | I2: Year 7 Monthly Avg.
A3: Accounts Payable
A4: Invoice Processing
A5: Manual Invoices - Purchase Order (RE) | B5: 1932 | C5: 1932 | D5: 1932 | E5: 1932 | F5: 1932 | G5: 1932 | H5: 1932 | I5: 1932
A6: Manual Invoices - Non-Purchase Order (KG/KR) | B6: 1246 | C6: 1246 | D6: 1246 | E6: 1246 | F6: 1246 | G6: 1246 | H6: 1246 | I6: 1246
A7: Electronic Invoices - Purchase Order (Autofacturas - RB) | B7: 131 | C7: 131 | D7: 131 | E7: 131 | F7: 131 | G7: 131 | H7: 131 | I7: 131
A8: Electronic Invoices - Purchase Order (Basilea - RN) | B8: 151 | C8: 151 | D8: 151 | E8: 151 | F8: 151 | G8: 151 | H8: 151 | I8: 151
A9: Consolidated Invoices
A10: Payments (Check Printing and Disbursement)
A11: Payments - Normal Handling (confirming) | B11: 998 | C11: 998 | D11: 998 | E11: 998 | F11: 998 | G11: 998 | H11: 998 | I11: 998
A12: Payments - Checks Requiring Special Handling | B12: 381 | C12: 381 | D12: 381 | E12: 381 | F12: 381 | G12: 381 | H12: 381 | I12: 381
A13: Payments - Electronic Disbursement | B13: 861 | C13: 861 | D13: 861 | E13: 861 | F13: 861 | G13: 861 | H13: 861 | I13: 861
A14: Payments - Wire Disbursement (Extranjero) | B14: 55 | C14: 55 | D14: 55 | E14: 55 | F14: 55 | G14: 55 | H14: 55 | I14: 55
A15: Vendor Management
A16: Vendor Set Up (altas) | B16: 144 | C16: 144 | D16: 144 | E16: 120 | F16: 100 | G16: 80 | H16: 80 | I16: 80
A17: Vendor Inquiry (modificaciones) | B17: 114 | C17: 114 | D17: 114 | E17: 114 | F17: 114 | G17: 114 | H17: 114 | I17: 114
A18: Year End Vendor Tax Reporting | B18: 7200 | C18: =+B18+C16*12 | D18: =+C18+D16*12 | E18: =+D18+E16*12 | F18: =+E18+F16*12 | G18: =+F18+G16*12 | H18: =+G18+H16*12 | I18: =+H18+I16*12
A19: Travel and Entertainment
A20: Employee Expense Reports
A21: Manual Employee Expense Reports | B21: 622 | C21: 622 | D21: 622 | E21: 622 | F21: 622 | G21: 622 | H21: 622 | I21: 622
A22: Electronic Employee Expense Reports (Or)
A23: Employees Submitting Expense Reports | B23: 1285 | C23: 1285 | D23: 1285 | E23: 1285 | F23: 1285 | G23: 1285 | H23: 1285 | I23: 1285
A24: Order to Cash
A25: Credit
A26: Credit Applications Processed - Standard | B26: 563 | C26: 563 | D26: 563 | E26: 563 | F26: 563 | G26: 563 | H26: 563 | I26: 563
A27: Order Entry
A28: Manual Orders Processed (SIEBEL) | B28: 3936 | C28: 3936 | D28: 3936 | E28: 3936 | F28: 3936 | G28: 3936 | H28: 3936 | I28: 3936
A29: Electronic Orders Processed (SAP +EDI) | B29: =243+438 | C29: =243+438 | D29: =243+438 | E29: =243+438 | F29: =243+438 | G29: =243+438 | H29: =243+438 | I29: =243+438
A30: Customer Inquiries
A31: Internal Inquiries | B31: 6 | C31: 6 | D31: 6 | E31: 6 | F31: 6 | G31: 6 | H31: 6 | I31: 6
A32: External Inquiries | B32: 1025 | C32: 1025 | D32: 1025 | E32: 1025 | F32: 1025 | G32: 1025 | H32: 1025 | I32: 1025
A33: Invoicing
A34: Paper Invoices (SAP-SD) | B34: 5321 | C34: 5321 | D34: 5321 | E34: 5321 | F34: 5321 | G34: 5321 | H34: 5321 | I34: 5321
A35: Electronic Invoices (SAP-FI) | B35: 76 | C35: 76 | D35: 76 | E35: 76 | F35: 76 | G35: 76 | H35: 76 | I35: 76
A36: Customer Statements | B36: 15 | C36: 15 | D36: 15 | E36: 15 | F36: 15 | G36: 15 | H36: 15 | I36: 15
A37: Cash Applications
A38: Electronic Payments | B38: 1166 | C38: 1166 | D38: 1166 | E38: 1166 | F38: 1166 | G38: 1166 | H38: 1166 | I38: 1166
A39: Lockbox Payments (Domiciliados) | B39: 2258 | C39: 2258 | D39: 2258 | E39: 2258 | F39: 2258 | G39: 2258 | H39: 2258 | I39: 2258
A40: Check Payments | B40: 42 | C40: 42 | D40: 42 | E40: 42 | F40: 42 | G40: 42 | H40: 42 | I40: 42
...

Sheet UK
A1: United Kingdom
A2: Description | B2: Base Year Monthly Avg. | C2: Year 1 Monthly Avg. | D2: Year 2 Monthly Avg. | E2: Year 3 Monthly Avg. | F2: Year 4 Monthly Avg. | G2: Year 5 Monthly Avg. | H2: Year 6 Monthly Avg. | I2: Year 7 Monthly Avg.
A3: Accounts Payable
A4: Invoice Processing
A5: Manual Invoices - Purchase Order | B5: 1415 | C5: 1489.995 | D5: 1595.7846 | E5: 1624.5088 | F5: 1635.8803 | G5: 1688.2285 | H5: 1742.2518 | I5: 1798.0039
A6: Manual Invoices - Non-Purchase Order | B6: 1415 | C6: 1489.995 | D6: 1595.7846 | E6: 1624.5088 | F6: 1635.8803 | G6: 1688.2285 | H6: 1742.2518 | I6: 1798.0039
A7: Consolidated Invoices | B7: 8 | C7: 8.424 | D7: 9.022104 | E7: 9.1845019 | F7: 9.2487934 | G7: 9.5447548 | H7: 9.8501869 | I7: 10.165393
A8: Payments (Check Printing and Disbursement)
A9: Payments - Normal Handling | B9: 350 | C9: 368.55 | D9: 394.71705 | E9: 401.82196 | F9: 404.63471 | G9: 417.58302 | H9: 430.94568 | I9: 444.73594
A10: Payments - Electronic Disbursement | B10: 1356 | C10: 1427.868 | D10: 1529.2466 | E10: 1556.7731 | F10: 1567.6705 | G10: 1617.8359 | H10: 1669.6067 | I10: 1723.0341
A11: Payments - Wire Disbursement | B11: 60 | C11: 63.18 | D11: 67.66578 | E11: 68.883764 | F11: 69.36595 | G11: 71.585661 | H11: 73.876402 | I11: 76.240447
A12: Vendor Management
A13: Vendor Set Up | B13: =(4+177+410+19)/12 | C13: 53.5275 | D13: 57.327953 | E13: 58.359856 | F13: 58.768375 | G13: 60.648963 | H13: 62.589729 | I13: 64.592601
A14: Vendor changes for bank details (done by GA) | B14: 332 | C14: 349.596 | D14: 374.41732 | E14: 381.15683 | F14: 383.82493 | G14: 396.10732 | H14: 408.78276 | I14: 421.86381
A15: Vendor Inquiry | B15: =150*260/12 | C15: 3422.25 | D15: 3665.2297 | E15: 3731.2039 | F15: 3757.3223 | G15: 3877.5566 | H15: 4001.6384 | I15: 4129.6909
A16: Travel and Entertainment
A17: Employee Expense Reports
A18: Manual Employee Expense Reports (Including T&E & payroll adj's and P-cards) | B18: 49 | C18: 51.597 | D18: 55.260387 | E18: 56.255074 | F18: 56.648859 | G18: 58.461623 | H18: 60.332395 | I18: 62.263032
A19: Electronic Employee Expense Reports | B19: 690 | C19: 726.57 | D19: 778.15647 | E19: 792.16329 | F19: 797.70843 | G19: 823.2351 | H19: 849.57862 | I19: 876.76514
A20: No. Credit Cards Administered | B20: 572 | C20: 602.316 | D20: 645.08044 | E20: 656.69188 | F20: 661.28873 | G20: 682.44997 | H20: 704.28837 | I20: 726.82559
A21: No. Purchasing Cards Administered | B21: 9 | C21: 9.477 | D21: 10.149867 | E21: 10.332565 | F21: 10.404893 | G21: 10.737849 | H21: 11.08146 | I21: 11.436067
A22: EmployeesWith active Boomerang (T&E system) accounts | B22: 837 | C22: 881.361 | D22: 943.93763 | E22: 960.92851 | F22: 967.65501 | G22: 998.61997 | H22: 1030.5758 | I22: 1063.5542
A24: Employee Expense Reports
A25: Manual Employee Expense Reports (Including T&E & payroll adj's and P-cards) | C25: =IF(B18=0,0,+C18/B18-1) | D25: =IF(C18=0,0,+D18/C18-1) | E25: =IF(D18=0,0,+E18/D18-1) | F25: =IF(E18=0,0,+F18/E18-1) | G25: =IF(F18=0,0,+G18/F18-1) | H25: =IF(G18=0,0,+H18/G18-1) | I25: =IF(H18=0,0,+I18/H18-1)
A26: Electronic Employee Expense Reports | C26: =IF(B19=0,0,+C19/B19-1) | D26: =IF(C19=0,0,+D19/C19-1) | E26: =IF(D19=0,0,+E19/D19-1) | F26: =IF(E19=0,0,+F19/E19-1) | G26: =IF(F19=0,0,+G19/F19-1) | H26: =IF(G19=0,0,+H19/G19-1) | I26: =IF(H19=0,0,+I19/H19-1)
A27: No. Credit Cards Administered | C27: =IF(B20=0,0,+C20/B20-1) | D27: =IF(C20=0,0,+D20/C20-1) | E27: =IF(D20=0,0,+E20/D20-1) | F27: =IF(E20=0,0,+F20/E20-1) | G27: =IF(F20=0,0,+G20/F20-1) | H27: =IF(G20=0,0,+H20/G20-1) | I27: =IF(H20=0,0,+I20/H20-1)
A28: No. Purchasing Cards Administered | C28: =IF(B21=0,0,+C21/B21-1) | D28: =IF(C21=0,0,+D21/C21-1) | E28: =IF(D21=0,0,+E21/D21-1) | F28: =IF(E21=0,0,+F21/E21-1) | G28: =IF(F21=0,0,+G21/F21-1) | H28: =IF(G21=0,0,+H21/G21-1) | I28: =IF(H21=0,0,+I21/H21-1)
A29: EmployeesWith active Boomerang (T&E system) accounts | C29: =IF(B22=0,0,+C22/B22-1) | D29: =IF(C22=0,0,+D22/C22-1) | E29: =IF(D22=0,0,+E22/D22-1) | F29: =IF(E22=0,0,+F22/E22-1) | G29: =IF(F22=0,0,+G22/F22-1) | H29: =IF(G22=0,0,+H22/G22-1) | I29: =IF(H22=0,0,+I22/H22-1)
A30: Order to Cash
A31: Credit
A32: Credit Applications Processed - Standard | B32: 40 | C32: 39.28 | D32: 43.0116 | E32: 48.086969 | F32: 51.501144 | G32: 56.084745 | H32: 61.076288 | I32: 66.512077
A33: Credit Application Processed - Special/Outside Policy | B33: 10 | C33: 9.82 | D33: 10.7529 | E33: 12.021742 | F33: 12.875286 | G33: 14.021186 | H33: 15.269072 | I33: 16.628019
A34: Credit Review Processed | B34: 291 | C34: 285.762 | D34: 312.90939 | E34: 349.8327 | F34: 374.67082 | G34: 408.01652 | H34: 444.32999 | I34: 483.87536
A35: Order Entry
A36: Manual Orders Processed | B36: 3687 | C36: 3620.634 | D36: 3964.5942 | E36: 4432.4163 | F36: 4747.1179 | G36: 5169.6114 | H36: 5629.7068 | I36: 6130.7507
A37: Electronic Orders Processed | B37: 1028 | C37: 1009.496 | D37: 1105.3981 | E37: 1235.8351 | F37: 1323.5794 | G37: 1441.378 | H37: 1569.6606 | I37: 1709.3604
A38: Customer Inquiries
A39: Internal Inquiries | B39: 1260 | C39: 1237.32 | D39: 1354.8654 | E39: 1514.7395 | F39: 1622.286 | G39: 1766.6695 | H39: 1923.9031 | I39: 2095.1304
A40: External Inquiries | B40: 126 | C40: 123.732 | D40: 135.48654 | E40: 151.47395 | F40: 162.2286 | G40: 176.66695 | H40: 192.39031 | I40: 209.51304
A41: Invoicing
...

Sheet Procurement Data
A1: Key Procurement Transactional Data
A2: Key Processes and Metrics | B2: Switzerland | C2: US | D2: Germany | F2: UK | H2: Italy | J2: Spain | L2: France
D3: CPO | E3: TechOps | F3: CPO | G3: TechOps | H3: CPO | I3: TechOps | J3: CPO | K3: TechOps | L3: CPO | M3: TechOps
A4: Requisitions and orders
A5: Number of catalog PO's per year | B5: 130000 | C5: 85000 | D5: 4500 | E5: 500 | F5: 3000 | G5: 2000 | H5: 1000 | I5: 0 | J5: 2500 | K5: 400 | L5: no catalogs
A6: Number of non-catalog PO's per year | B6: 70000 | C6: 65000 | D6: 12600 | E6: 4700 | F6: 4000 | G6: 3000 | H6: 13000 | I6: 2300 | J6: 10500 | K6: 5000 | L6: 5600 | M6: 5300
A7: Number of catalog line items per year | B7: 200000 | C7: 250000 | D7: 12100 | E7: 1500 | F7: 15000 | G7: 12000 | H7: 2000 | I7: 0 | K7: 600 | L7: no catalogs
A8: Number of non catalog line items per year | B8: 100000 | C8: 400000 | D8: 15700 | E8: 2400 | F8: 5000 | G8: 4000 | H8: 21000 | I8: 5500 | J8: 19500 | K8: 7500 | L8: 12200 | M8: 14600
A9: Number of orders to be manually transmitted (faxed, mailed) | B9: none | C9: 30000* | D9: none | E9: 4700 | F9: none | G9: 1000 | H9: 400 | I9: 1000 | J9: none | K9: 6000 | L9: 5600 | M9: 5300
A10: Master Data Management
A11: Number of active suppliers | B11: 10000 | C11: 25000** | D11: 7800 | E11: 100 | F11: 3000 | G11: 2000 | H11: 10000 | I11: incl. in CPO | J11: 3500 | K11: 400 | L11: 13800 | M11: 700
A12: Number of new suppliers per year | B12: 4000 | C12: 2500** | D12: 420 | E12: 120 | F12: 400 | G12: 200 | H12: 1000 | I12: incl. in CPO | J12: 1600 | K12: 40 | L12: 3000
A13: Numbers of requests for DUNS number | B13: 4000 | D13: no DUNS input yet | F13: no DUNS input yet | H13: no DUNS input yet | J13: 1600 | K13: 40 | L13: no DUNS input yet
A14: Hotline and Helpdesk
A15: number of daily 1st line and help desk support requests per mail | B15: 50 | C15: 50 | D15: 10-30 | E15: 5 | F15: 10-20 | G15: 5-10 | H15: 3 | I15: incl. in CPO | J15: 16 | L15: 40 | M15: 20
A16: number of daily 1st line and help desk support requests per phone | B16: 50-100 | C16: 50-100 | D16: 10-40 | E16: 10 | F16: 5-10 | G16: 5-10 | H16: 5 | I16: incl. in CPO | J16: 10-20 | L16: 40 | M16: 20
A17: Initiation, management and testing of system change requests per year | B17: 50 | C17: 50 | D17: 5 | E17: 2 | H17: 8 | I17: incl. in CPO | J17: 16 | L17: 20 | M17: 14
A18: Time required to monitor system error messages and to follow up (in hrs per day) | B18: 4 | C18: 6 | D18: 2 | E18: 1 | F18: 3 | G18: 2 | H18: 1 | I18: incl. in CPO | J18: 1 | K18: 3 | L18: 1 | M18: 0
A19: CC5 - supplier onboarding process
A20: Hours per quarter to drive the supplier onboarding process | B20: 50 | C20: 30 | D20: 35 | E20: 18 | F20: 60 | G20: 25 | H20: 8 | I20: 10 | J20: 6 | K20: 10 | L20: 50 | M20: 2
A21: Reporting
A22: Number of adhoc reporting requests per month | B22: 30 | C22: 15 | D22: 5 | E22: 5 | F22: 4 | G22: 4 | H22: 10 | I22: 4 | J22: 15 | K22: 4 | L22: 20 | M22: 2
A23: Estimated time required to provide standard reporting (in hrs per month) | B23: 16 | C23: 5 | D23: 3 | E23: 3 | F23: 0 | G23: 0 | H23: 12 | I23: 8 | J23: 40 | K23: 24 | L23: 70 | M23: 20
A24: Goods Receipt
A25: Number of line items for goods receipt booking per year | B25: out of scope | C25: out of scope | D25: 6000 | E25: 4800 | F25: out of scope | G25: out of scope | H25: out of scope | I25: out of scope | J25: 12800 | K25: 7500 | L25: 12200 | M25: 14600
A26: e-RFx
A27: Number of e-RFx and e-bidding events per year | B27: 2000 | C27: 70 | D27: 7 | E27: 0 | F27: 15 | G27: 1 | H27: 60 | I27: 0 | J27: 380 | K27: 20 | L27: 40 | M27: 3
A28: Catalog Management
A29: Uploading and inactivation of new/modified catalogs (no. of catalogs per year) | B29: 160 | C29: 15 | D29: 11 | E29: 2 | F29: 1 | G29: 1 | H29: 6 | I29: 0 | J29: 5 | K29: 0 | L29: no catalogs
A30: number of new punchout catalogs per year | B30: 2 | C30: 1-2 | D30: 2 | E30: 2 | F30: 1 | G30: 1 | H30: 1 | I30: 0 | J30: 2 | K30: 0 | L30: no catalogs
A31: Spend Information
A32: Annual indirect spend with third partis in billion USD | B32: 1.5 | C32: 1.5 | D32: 0.11 | F32: 0.08 | H32: 0.09 | J32: 0.07 | L32: 0.11
A33: Estimated share of spend managed through contracts (e.g. frame agreements) | B33: 0.45 | C33: 0.85 | D33: 0.85 | F33: 0.65 | H33: 0.45 | J33: 0.6
A37: * These order transmissions will be eliminated by the Fax Server project currently underway
A38: ** These include all active suppliers including Doctors (active supplier without doctors are 10-12 k, new suppliers 1-1.2 k every year)
