Workbook

Sheet Title Sheet
B2: GlobalPharma AG
B5: ATTACHMENT 4-C
B7: FINANCIAL BASE CASE
B8: Attachment to Exhibit 4 (Pricing and Financial Provisions)
B15: This document contains confidential and proprietary information of GlobalPharma AG. It is furnished for the performance of The Agreements only. Except with the express prior written permission of GlobalPharma AG, this document and the information contained herein may not be published, disclosed, or used for any other purpose.

Sheet Consolidated 
C1: Consolidated Summary
C2: TOTAL COSTS (US$ excl. VAT) | D2: BASE YEAR | E2: YEAR 1 | F2: YEAR 2 | G2: YEAR 3 | H2: YEAR 4 | I2: YEAR 5 | J2: 5 Year Total | L2: 5 YEAR + 1 | M2: 5 YEAR + 2 | N2: 7 Year Total
C3: Internal FTE | D3: =D46+D90+D133 | E3: =E46+E90+E133 | F3: =F46+F90+F133 | G3: =G46+G90+G133 | H3: =H46+H90+H133 | I3: =I46+I90+I133 | L3: =L46+L90+L133 | M3: =M46+M90+M133
C4: External FTE | D4: =D47+D91+D134 | E4: =E47+E91+E134 | F4: =F47+F91+F134 | G4: =G47+G91+G134 | H4: =H47+H91+H134 | I4: =I47+I91+I134 | L4: =L47+L91+L134 | M4: =M47+M91+M134
C5: Total FTE | D5: =SUM(D3:D4) | E5: =SUM(E3:E4) | F5: =SUM(F3:F4) | G5: =SUM(G3:G4) | H5: =SUM(H3:H4) | I5: =SUM(I3:I4) | L5: =SUM(L3:L4) | M5: =SUM(M3:M4)
C7: Salaries | D7: =D50+D94+D137 | E7: =E50+E94+E137 | F7: =F50+F94+F137 | G7: =G50+G94+G137 | H7: =H50+H94+H137 | I7: =I50+I94+I137 | J7: =SUM(E7:I7) | L7: =L50+L94+L137 | M7: =M50+M94+M137 | N7: =+J7+SUM(L7:M7)
C8: Bonuses | D8: =D51+D95+D138 | E8: =E51+E95+E138 | F8: =F51+F95+F138 | G8: =G51+G95+G138 | H8: =H51+H95+H138 | I8: =I51+I95+I138 | J8: =SUM(E8:I8) | L8: =L51+L95+L138 | M8: =M51+M95+M138 | N8: =+J8+SUM(L8:M8)
C9: Third party staff, ex IT | D9: =D52+D96+D139 | E9: =E52+E96+E139 | F9: =F52+F96+F139 | G9: =G52+G96+G139 | H9: =H52+H96+H139 | I9: =I52+I96+I139 | J9: =SUM(E9:I9) | L9: =L52+L96+L139 | M9: =M52+M96+M139 | N9: =+J9+SUM(L9:M9)
C10: Third party IT staff | D10: =D53+D97+D140 | E10: =E53+E97+E140 | F10: =F53+F97+F140 | G10: =G53+G97+G140 | H10: =H53+H97+H140 | I10: =I53+I97+I140 | J10: =SUM(E10:I10) | L10: =L53+L97+L140 | M10: =M53+M97+M140 | N10: =+J10+SUM(L10:M10)
C11: Employee education | D11: =D54+D98+D141 | E11: =E54+E98+E141 | F11: =F54+F98+F141 | G11: =G54+G98+G141 | H11: =H54+H98+H141 | I11: =I54+I98+I141 | J11: =SUM(E11:I11) | L11: =L54+L98+L141 | M11: =M54+M98+M141 | N11: =+J11+SUM(L11:M11)
C12: Other staff expenses | D12: =D55+D99+D142 | E12: =E55+E99+E142 | F12: =F55+F99+F142 | G12: =G55+G99+G142 | H12: =H55+H99+H142 | I12: =I55+I99+I142 | J12: =SUM(E12:I12) | L12: =L55+L99+L142 | M12: =M55+M99+M142 | N12: =+J12+SUM(L12:M12)
C13: Staff expenses | D13: =SUM(D7:D12) | E13: =SUM(E7:E12) | F13: =SUM(F7:F12) | G13: =SUM(G7:G12) | H13: =SUM(H7:H12) | I13: =SUM(I7:I12) | J13: =SUM(E13:I13) | L13: =SUM(L7:L12) | M13: =SUM(M7:M12) | N13: =SUM(N7:N12)
C14: Hardware expenses | D14: =D57+D101+D144 | E14: =E57+E101+E144 | F14: =F57+F101+F144 | G14: =G57+G101+G144 | H14: =H57+H101+H144 | I14: =I57+I101+I144 | J14: =SUM(E14:I14) | L14: =L57+L101+L144 | M14: =M57+M101+M144 | N14: =+J14+SUM(L14:M14)
C15: Leasing/renting hardware | D15: =D58+D102+D145 | E15: =E58+E102+E145 | F15: =F58+F102+F145 | G15: =G58+G102+G145 | H15: =H58+H102+H145 | I15: =I58+I102+I145 | J15: =SUM(E15:I15) | L15: =L58+L102+L145 | M15: =M58+M102+M145 | N15: =+J15+SUM(L15:M15)
C16: Software expenses | D16: =D59+D103+D146 | E16: =E59+E103+E146 | F16: =F59+F103+F146 | G16: =G59+G103+G146 | H16: =H59+H103+H146 | I16: =I59+I103+I146 | J16: =SUM(E16:I16) | L16: =L59+L103+L146 | M16: =M59+M103+M146 | N16: =+J16+SUM(L16:M16)
C17: Leasing/renting/licenses sw | D17: =D60+D104+D147 | E17: =E60+E104+E147 | F17: =F60+F104+F147 | G17: =G60+G104+G147 | H17: =H60+H104+H147 | I17: =I60+I104+I147 | J17: =SUM(E17:I17) | L17: =L60+L104+L147 | M17: =M60+M104+M147 | N17: =+J17+SUM(L17:M17)
C18: Depreciation hardware | D18: =D61+D105+D148 | E18: =E61+E105+E148 | F18: =F61+F105+F148 | G18: =G61+G105+G148 | H18: =H61+H105+H148 | I18: =I61+I105+I148 | J18: =SUM(E18:I18) | L18: =L61+L105+L148 | M18: =M61+M105+M148 | N18: =+J18+SUM(L18:M18)
C19: Depreciation software | D19: =D62+D106+D149 | E19: =E62+E106+E149 | F19: =F62+F106+F149 | G19: =G62+G106+G149 | H19: =H62+H106+H149 | I19: =I62+I106+I149 | J19: =SUM(E19:I19) | L19: =L62+L106+L149 | M19: =M62+M106+M149 | N19: =+J19+SUM(L19:M19)
C20: Outsourcing IT activities | D20: =D63+D107+D150 | E20: =E63+E107+E150 | F20: =F63+F107+F150 | G20: =G63+G107+G150 | H20: =H63+H107+H150 | I20: =I63+I107+I150 | J20: =SUM(E20:I20) | L20: =L63+L107+L150 | M20: =M63+M107+M150 | N20: =+J20+SUM(L20:M20)
C21: Other IT expenses | D21: =D64+D108+D151 | E21: =E64+E108+E151 | F21: =F64+F108+F151 | G21: =G64+G108+G151 | H21: =H64+H108+H151 | I21: =I64+I108+I151 | J21: =SUM(E21:I21) | L21: =L64+L108+L151 | M21: =M64+M108+M151 | N21: =+J21+SUM(L21:M21)
C22: EDP expenses | D22: =SUM(D14:D21) | E22: =SUM(E14:E21) | F22: =SUM(F14:F21) | G22: =SUM(G14:G21) | H22: =SUM(H14:H21) | I22: =SUM(I14:I21) | J22: =SUM(E22:I22) | L22: =SUM(L14:L21) | M22: =SUM(M14:M21) | N22: =SUM(N14:N21)
C23: Telecom expenses | D23: =D66+D110+D153 | E23: =E66+E110+E153 | F23: =F66+F110+F153 | G23: =G66+G110+G153 | H23: =H66+H110+H153 | I23: =I66+I110+I153 | J23: =SUM(E23:I23) | L23: =L66+L110+L153 | M23: =M66+M110+M153 | N23: =+J23+SUM(L23:M23)
C24: Office equipment and supplies | D24: =D67+D111+D154 | E24: =E67+E111+E154 | F24: =F67+F111+F154 | G24: =G67+G111+G154 | H24: =H67+H111+H154 | I24: =I67+I111+I154 | J24: =SUM(E24:I24) | L24: =L67+L111+L154 | M24: =M67+M111+M154 | N24: =+J24+SUM(L24:M24)
C25: Accomodation expenses | D25: =D68+D112+D155 | E25: =E68+E112+E155 | F25: =F68+F112+F155 | G25: =G68+G112+G155 | H25: =H68+H112+H155 | I25: =I68+I112+I155 | J25: =SUM(E25:I25) | L25: =L68+L112+L155 | M25: =M68+M112+M155 | N25: =+J25+SUM(L25:M25)
C26: Travel costs | D26: =D69+D113+D156 | E26: =E69+E113+E156 | F26: =F69+F113+F156 | G26: =G69+G113+G156 | H26: =H69+H113+H156 | I26: =I69+I113+I156 | J26: =SUM(E26:I26) | L26: =L69+L113+L156 | M26: =M69+M113+M156 | N26: =+J26+SUM(L26:M26)
C27: Postal and freight charges | D27: =D70+D114+D157 | E27: =E70+E114+E157 | F27: =F70+F114+F157 | G27: =G70+G114+G157 | H27: =H70+H114+H157 | I27: =I70+I114+I157 | J27: =SUM(E27:I27) | L27: =L70+L114+L157 | M27: =M70+M114+M157 | N27: =+J27+SUM(L27:M27)
C28: Prof serv and ext advisory fee | D28: =D71+D115+D158 | E28: =E71+E115+E158 | F28: =F71+F115+F158 | G28: =G71+G115+G158 | H28: =H71+H115+H158 | I28: =I71+I115+I158 | J28: =SUM(E28:I28) | L28: =L71+L115+L158 | M28: =M71+M115+M158 | N28: =+J28+SUM(L28:M28)
C29: Payment transfer expenses | D29: =D72+D116+D159 | E29: =E72+E116+E159 | F29: =F72+F116+F159 | G29: =G72+G116+G159 | H29: =H72+H116+H159 | I29: =I72+I116+I159 | J29: =SUM(E29:I29) | L29: =L72+L116+L159 | M29: =M72+M116+M159 | N29: =+J29+SUM(L29:M29)
C30: Other costs | D30: =D73+D117+D160 | E30: =E73+E117+E160 | F30: =F73+F117+F160 | G30: =G73+G117+G160 | H30: =H73+H117+H160 | I30: =I73+I117+I160 | J30: =SUM(E30:I30) | L30: =L73+L117+L160 | M30: =M73+M117+M160 | N30: =+J30+SUM(L30:M30)
C31: General expenses | D31: =SUM(D23:D30) | E31: =SUM(E23:E30) | F31: =SUM(F23:F30) | G31: =SUM(G23:G30) | H31: =SUM(H23:H30) | I31: =SUM(I23:I30) | J31: =SUM(E31:I31) | L31: =SUM(L23:L30) | M31: =SUM(M23:M30) | N31: =SUM(N23:N30)
C32: Own expenses | D32: =D31+D22+D13 | E32: =E31+E22+E13 | F32: =F31+F22+F13 | G32: =G31+G22+G13 | H32: =H31+H22+H13 | I32: =I31+I22+I13 | J32: =SUM(E32:I32) | L32: =L31+L22+L13 | M32: =M31+M22+M13 | N32: =+N13+N22+N31
C33: Other expenses | D33: =D76+D120+D163 | E33: =E76+E120+E163 | F33: =F76+F120+F163 | G33: =G76+G120+G163 | H33: =H76+H120+H163 | I33: =I76+I120+I163 | J33: =SUM(E33:I33) | L33: =L76+L120+L163 | M33: =M76+M120+M163 | N33: =+J33+SUM(L33:M33)
C34: Operating expenses | D34: =SUM(D32:D33) | E34: =SUM(E32:E33) | F34: =SUM(F32:F33) | G34: =SUM(G32:G33) | H34: =SUM(H32:H33) | I34: =SUM(I32:I33) | J34: =SUM(J32:J33) | L34: =SUM(L32:L33) | M34: =SUM(M32:M33) | N34: =SUM(N32:N33)
C36: HR & Comms | D36: =D79+D123+D166 | E36: =E79+E123+E166 | F36: =F79+F123+F166 | G36: =G79+G123+G166 | H36: =H79+H123+H166 | I36: =I79+I123+I166 | J36: =SUM(E36:I36) | L36: =L79+L123+L166 | M36: =M79+M123+M166 | N36: =+J36+SUM(L36:M36)
C37: Finance & Business Support | D37: =D80+D124+D167 | E37: =E80+E124+E167 | F37: =F80+F124+F167 | G37: =G80+G124+G167 | H37: =H80+H124+H167 | I37: =I80+I124+I167 | J37: =SUM(E37:I37) | L37: =L80+L124+L167 | M37: =M80+M124+M167 | N37: =+J37+SUM(L37:M37)
C38: HRN | D38: =D81+D125+D168 | E38: =E81+E125+E168 | F38: =F81+F125+F168 | G38: =G81+G125+G168 | H38: =H81+H125+H168 | I38: =I81+I125+I168 | J38: =SUM(E38:I38) | L38: =L81+L125+L168 | M38: =M81+M125+M168 | N38: =+J38+SUM(L38:M38)
C39: Facilities Management | D39: =D82+D126+D169 | E39: =E82+E126+E169 | F39: =F82+F126+F169 | G39: =G82+G126+G169 | H39: =H82+H126+H169 | I39: =I82+I126+I169 | J39: =SUM(E39:I39) | L39: =L82+L126+L169 | M39: =M82+M126+M169 | N39: =+J39+SUM(L39:M39)
C40: Overheads | D40: =SUM(D36:D39) | E40: =SUM(E36:E39) | F40: =SUM(F36:F39) | G40: =SUM(G36:G39) | H40: =SUM(H36:H39) | I40: =SUM(I36:I39) | J40: =SUM(J36:J39) | L40: =SUM(L36:L39) | M40: =SUM(M36:M39) | N40: =SUM(N36:N39)
C42: Total Operating Costs (incl. O/H) | D42: =D34+D40 | E42: =E34+E40 | F42: =F34+F40 | G42: =G34+G40 | H42: =H34+H40 | I42: =I34+I40 | J42: =J34+J40 | L42: =L34+L40 | M42: =M34+M40 | N42: =N34+N40
J43: =J42-J85-J129-J172
...

Sheet UK
C1: United Kingdom
C2: TOTAL COSTS (US$ excl. VAT) | D2: BASE YEAR | E2: YEAR 1 | F2: YEAR 2 | G2: YEAR 3 | H2: YEAR 4 | I2: YEAR 5 | J2: 5 Year Total | L2: 5 YEAR + 1 | M2: 5 YEAR + 2 | N2: 7 Year Total
C3: Internal FTE | D3: =[1]Consolidated!D3 | E3: =[1]Consolidated!E3 | F3: =[1]Consolidated!F3 | G3: =[1]Consolidated!G3 | H3: =[1]Consolidated!H3 | I3: =[1]Consolidated!I3 | L3: =[1]Consolidated!L3 | M3: =[1]Consolidated!M3 | N3: =[1]Consolidated!N3
C4: External FTE | D4: =[1]Consolidated!D4 | E4: =[1]Consolidated!E4 | F4: =[1]Consolidated!F4 | G4: =[1]Consolidated!G4 | H4: =[1]Consolidated!H4 | I4: =[1]Consolidated!I4 | L4: =[1]Consolidated!L4 | M4: =[1]Consolidated!M4 | N4: =[1]Consolidated!N4
C5: Total FTE | D5: =[1]Consolidated!D5 | E5: =[1]Consolidated!E5 | F5: =[1]Consolidated!F5 | G5: =[1]Consolidated!G5 | H5: =[1]Consolidated!H5 | I5: =[1]Consolidated!I5 | L5: =[1]Consolidated!L5 | M5: =[1]Consolidated!M5 | N5: =[1]Consolidated!N5
C7: Salaries | D7: =(([1]Consolidated!D7)*1000)*(1/0.79941) | E7: =(([1]Consolidated!E7)*1000)*(1/0.79941) | F7: =(([1]Consolidated!F7)*1000)*(1/0.79941) | G7: =(([1]Consolidated!G7)*1000)*(1/0.79941) | H7: =(([1]Consolidated!H7)*1000)*(1/0.79941) | I7: =(([1]Consolidated!I7)*1000)*(1/0.79941) | J7: =(([1]Consolidated!J7)*1000)*(1/0.79941) | L7: =(([1]Consolidated!L7)*1000)*(1/0.79941) | M7: =(([1]Consolidated!M7)*1000)*(1/0.79941) | N7: =(([1]Consolidated!N7)*1000)*(1/0.79941) | P7: 1000
C8: Bonuses | D8: =(([1]Consolidated!D8)*1000)*(1/0.79941) | E8: =(([1]Consolidated!E8)*1000)*(1/0.79941) | F8: =(([1]Consolidated!F8)*1000)*(1/0.79941) | G8: =(([1]Consolidated!G8)*1000)*(1/0.79941) | H8: =(([1]Consolidated!H8)*1000)*(1/0.79941) | I8: =(([1]Consolidated!I8)*1000)*(1/0.79941) | J8: =(([1]Consolidated!J8)*1000)*(1/0.79941) | L8: =(([1]Consolidated!L8)*1000)*(1/0.79941) | M8: =(([1]Consolidated!M8)*1000)*(1/0.79941) | N8: =(([1]Consolidated!N8)*1000)*(1/0.79941) | P8: =1/0.79941 | Q8: Euro to dollar
C9: Third party staff, ex IT | D9: =(([1]Consolidated!D9)*1000)*(1/0.79941) | E9: =(([1]Consolidated!E9)*1000)*(1/0.79941) | F9: =(([1]Consolidated!F9)*1000)*(1/0.79941) | G9: =(([1]Consolidated!G9)*1000)*(1/0.79941) | H9: =(([1]Consolidated!H9)*1000)*(1/0.79941) | I9: =(([1]Consolidated!I9)*1000)*(1/0.79941) | J9: =(([1]Consolidated!J9)*1000)*(1/0.79941) | L9: =(([1]Consolidated!L9)*1000)*(1/0.79941) | M9: =(([1]Consolidated!M9)*1000)*(1/0.79941) | N9: =(([1]Consolidated!N9)*1000)*(1/0.79941)
C10: Third party IT staff | D10: =(([1]Consolidated!D10)*1000)*(1/0.79941) | E10: =(([1]Consolidated!E10)*1000)*(1/0.79941) | F10: =(([1]Consolidated!F10)*1000)*(1/0.79941) | G10: =(([1]Consolidated!G10)*1000)*(1/0.79941) | H10: =(([1]Consolidated!H10)*1000)*(1/0.79941) | I10: =(([1]Consolidated!I10)*1000)*(1/0.79941) | J10: =(([1]Consolidated!J10)*1000)*(1/0.79941) | L10: =(([1]Consolidated!L10)*1000)*(1/0.79941) | M10: =(([1]Consolidated!M10)*1000)*(1/0.79941) | N10: =(([1]Consolidated!N10)*1000)*(1/0.79941)
C11: Employee education | D11: =(([1]Consolidated!D11)*1000)*(1/0.79941) | E11: =(([1]Consolidated!E11)*1000)*(1/0.79941) | F11: =(([1]Consolidated!F11)*1000)*(1/0.79941) | G11: =(([1]Consolidated!G11)*1000)*(1/0.79941) | H11: =(([1]Consolidated!H11)*1000)*(1/0.79941) | I11: =(([1]Consolidated!I11)*1000)*(1/0.79941) | J11: =(([1]Consolidated!J11)*1000)*(1/0.79941) | L11: =(([1]Consolidated!L11)*1000)*(1/0.79941) | M11: =(([1]Consolidated!M11)*1000)*(1/0.79941) | N11: =(([1]Consolidated!N11)*1000)*(1/0.79941)
C12: Other staff expenses | D12: =(([1]Consolidated!D12)*1000)*(1/0.79941) | E12: =(([1]Consolidated!E12)*1000)*(1/0.79941) | F12: =(([1]Consolidated!F12)*1000)*(1/0.79941) | G12: =(([1]Consolidated!G12)*1000)*(1/0.79941) | H12: =(([1]Consolidated!H12)*1000)*(1/0.79941) | I12: =(([1]Consolidated!I12)*1000)*(1/0.79941) | J12: =(([1]Consolidated!J12)*1000)*(1/0.79941) | L12: =(([1]Consolidated!L12)*1000)*(1/0.79941) | M12: =(([1]Consolidated!M12)*1000)*(1/0.79941) | N12: =(([1]Consolidated!N12)*1000)*(1/0.79941)
C13: Staff expenses | D13: =(([1]Consolidated!D13)*1000)*(1/0.79941) | E13: =(([1]Consolidated!E13)*1000)*(1/0.79941) | F13: =(([1]Consolidated!F13)*1000)*(1/0.79941) | G13: =(([1]Consolidated!G13)*1000)*(1/0.79941) | H13: =(([1]Consolidated!H13)*1000)*(1/0.79941) | I13: =(([1]Consolidated!I13)*1000)*(1/0.79941) | J13: =(([1]Consolidated!J13)*1000)*(1/0.79941) | L13: =(([1]Consolidated!L13)*1000)*(1/0.79941) | M13: =(([1]Consolidated!M13)*1000)*(1/0.79941) | N13: =(([1]Consolidated!N13)*1000)*(1/0.79941)
C14: Hardware expenses | D14: =(([1]Consolidated!D14)*1000)*(1/0.79941) | E14: =(([1]Consolidated!E14)*1000)*(1/0.79941) | F14: =(([1]Consolidated!F14)*1000)*(1/0.79941) | G14: =(([1]Consolidated!G14)*1000)*(1/0.79941) | H14: =(([1]Consolidated!H14)*1000)*(1/0.79941) | I14: =(([1]Consolidated!I14)*1000)*(1/0.79941) | J14: =(([1]Consolidated!J14)*1000)*(1/0.79941) | L14: =(([1]Consolidated!L14)*1000)*(1/0.79941) | M14: =(([1]Consolidated!M14)*1000)*(1/0.79941) | N14: =(([1]Consolidated!N14)*1000)*(1/0.79941)
C15: Leasing/renting hardware | D15: =(([1]Consolidated!D15)*1000)*(1/0.79941) | E15: =(([1]Consolidated!E15)*1000)*(1/0.79941) | F15: =(([1]Consolidated!F15)*1000)*(1/0.79941) | G15: =(([1]Consolidated!G15)*1000)*(1/0.79941) | H15: =(([1]Consolidated!H15)*1000)*(1/0.79941) | I15: =(([1]Consolidated!I15)*1000)*(1/0.79941) | J15: =(([1]Consolidated!J15)*1000)*(1/0.79941) | L15: =(([1]Consolidated!L15)*1000)*(1/0.79941) | M15: =(([1]Consolidated!M15)*1000)*(1/0.79941) | N15: =(([1]Consolidated!N15)*1000)*(1/0.79941)
C16: Software expenses | D16: =(([1]Consolidated!D16)*1000)*(1/0.79941) | E16: =(([1]Consolidated!E16)*1000)*(1/0.79941) | F16: =(([1]Consolidated!F16)*1000)*(1/0.79941) | G16: =(([1]Consolidated!G16)*1000)*(1/0.79941) | H16: =(([1]Consolidated!H16)*1000)*(1/0.79941) | I16: =(([1]Consolidated!I16)*1000)*(1/0.79941) | J16: =(([1]Consolidated!J16)*1000)*(1/0.79941) | L16: =(([1]Consolidated!L16)*1000)*(1/0.79941) | M16: =(([1]Consolidated!M16)*1000)*(1/0.79941) | N16: =(([1]Consolidated!N16)*1000)*(1/0.79941)
C17: Leasing/renting/licenses sw | D17: =(([1]Consolidated!D17)*1000)*(1/0.79941) | E17: =(([1]Consolidated!E17)*1000)*(1/0.79941) | F17: =(([1]Consolidated!F17)*1000)*(1/0.79941) | G17: =(([1]Consolidated!G17)*1000)*(1/0.79941) | H17: =(([1]Consolidated!H17)*1000)*(1/0.79941) | I17: =(([1]Consolidated!I17)*1000)*(1/0.79941) | J17: =(([1]Consolidated!J17)*1000)*(1/0.79941) | L17: =(([1]Consolidated!L17)*1000)*(1/0.79941) | M17: =(([1]Consolidated!M17)*1000)*(1/0.79941) | N17: =(([1]Consolidated!N17)*1000)*(1/0.79941)
C18: Depreciation hardware | D18: =(([1]Consolidated!D18)*1000)*(1/0.79941) | E18: =(([1]Consolidated!E18)*1000)*(1/0.79941) | F18: =(([1]Consolidated!F18)*1000)*(1/0.79941) | G18: =(([1]Consolidated!G18)*1000)*(1/0.79941) | H18: =(([1]Consolidated!H18)*1000)*(1/0.79941) | I18: =(([1]Consolidated!I18)*1000)*(1/0.79941) | J18: =(([1]Consolidated!J18)*1000)*(1/0.79941) | L18: =(([1]Consolidated!L18)*1000)*(1/0.79941) | M18: =(([1]Consolidated!M18)*1000)*(1/0.79941) | N18: =(([1]Consolidated!N18)*1000)*(1/0.79941)
C19: Depreciation software | D19: =(([1]Consolidated!D19)*1000)*(1/0.79941) | E19: =(([1]Consolidated!E19)*1000)*(1/0.79941) | F19: =(([1]Consolidated!F19)*1000)*(1/0.79941) | G19: =(([1]Consolidated!G19)*1000)*(1/0.79941) | H19: =(([1]Consolidated!H19)*1000)*(1/0.79941) | I19: =(([1]Consolidated!I19)*1000)*(1/0.79941) | J19: =(([1]Consolidated!J19)*1000)*(1/0.79941) | L19: =(([1]Consolidated!L19)*1000)*(1/0.79941) | M19: =(([1]Consolidated!M19)*1000)*(1/0.79941) | N19: =(([1]Consolidated!N19)*1000)*(1/0.79941)
C20: Outsourcing IT activities | D20: =(([1]Consolidated!D20)*1000)*(1/0.79941) | E20: =(([1]Consolidated!E20)*1000)*(1/0.79941) | F20: =(([1]Consolidated!F20)*1000)*(1/0.79941) | G20: =(([1]Consolidated!G20)*1000)*(1/0.79941) | H20: =(([1]Consolidated!H20)*1000)*(1/0.79941) | I20: =(([1]Consolidated!I20)*1000)*(1/0.79941) | J20: =(([1]Consolidated!J20)*1000)*(1/0.79941) | L20: =(([1]Consolidated!L20)*1000)*(1/0.79941) | M20: =(([1]Consolidated!M20)*1000)*(1/0.79941) | N20: =(([1]Consolidated!N20)*1000)*(1/0.79941)
... C34: Operating expenses | D34: =(([1]Consolidated!D34)*1000)*(1/0.79941) | E34: =(([1]Consolidated!E34)*1000)*(1/0.79941) | F34: =(([1]Consolidated!F34)*1000)*(1/0.79941) | G34: =(([1]Consolidated!G34)*1000)*(1/0.79941) | H34: =(([1]Consolidated!H34)*1000)*(1/0.79941) | I34: =(([1]Consolidated!I34)*1000)*(1/0.79941) | J34: =(([1]Consolidated!J34)*1000)*(1/0.79941) | L34: =(([1]Consolidated!L34)*1000)*(1/0.79941) | M34: =(([1]Consolidated!M34)*1000)*(1/0.79941) | N34: =(([1]Consolidated!N34)*1000)*(1/0.79941)
D35: =0*(1/0.79941) | E35: =0*(1/0.79941) | F35: =0*(1/0.79941) | G35: =0*(1/0.79941) | H35: =0*(1/0.79941) | I35: =0*(1/0.79941) | J35: =0*(1/0.79941) | L35: =0*(1/0.79941) | M35: =0*(1/0.79941) | N35: =0*(1/0.79941)
C36: HR & Comms | D36: =(([1]Consolidated!D36)*1000)*(1/0.79941) | E36: =(([1]Consolidated!E36)*1000)*(1/0.79941) | F36: =(([1]Consolidated!F36)*1000)*(1/0.79941) | G36: =(([1]Consolidated!G36)*1000)*(1/0.79941) | H36: =(([1]Consolidated!H36)*1000)*(1/0.79941) | I36: =(([1]Consolidated!I36)*1000)*(1/0.79941) | J36: =(([1]Consolidated!J36)*1000)*(1/0.79941) | L36: =(([1]Consolidated!L36)*1000)*(1/0.79941) | M36: =(([1]Consolidated!M36)*1000)*(1/0.79941) | N36: =(([1]Consolidated!N36)*1000)*(1/0.79941)
C37: Finance & Business Support | D37: =(([1]Consolidated!D37)*1000)*(1/0.79941) | E37: =(([1]Consolidated!E37)*1000)*(1/0.79941) | F37: =(([1]Consolidated!F37)*1000)*(1/0.79941) | G37: =(([1]Consolidated!G37)*1000)*(1/0.79941) | H37: =(([1]Consolidated!H37)*1000)*(1/0.79941) | I37: =(([1]Consolidated!I37)*1000)*(1/0.79941) | J37: =(([1]Consolidated!J37)*1000)*(1/0.79941) | L37: =(([1]Consolidated!L37)*1000)*(1/0.79941) | M37: =(([1]Consolidated!M37)*1000)*(1/0.79941) | N37: =(([1]Consolidated!N37)*1000)*(1/0.79941)
C38: IT alloc | D38: =(([1]Consolidated!D38)*1000)*(1/0.79941) | E38: =(([1]Consolidated!E38)*1000)*(1/0.79941) | F38: =(([1]Consolidated!F38)*1000)*(1/0.79941) | G38: =(([1]Consolidated!G38)*1000)*(1/0.79941) | H38: =(([1]Consolidated!H38)*1000)*(1/0.79941) | I38: =(([1]Consolidated!I38)*1000)*(1/0.79941) | J38: =(([1]Consolidated!J38)*1000)*(1/0.79941) | L38: =(([1]Consolidated!L38)*1000)*(1/0.79941) | M38: =(([1]Consolidated!M38)*1000)*(1/0.79941) | N38: =(([1]Consolidated!N38)*1000)*(1/0.79941)
C39: Facilities Management | D39: =(([1]Consolidated!D39)*1000)*(1/0.79941) | E39: =(([1]Consolidated!E39)*1000)*(1/0.79941) | F39: =(([1]Consolidated!F39)*1000)*(1/0.79941) | G39: =(([1]Consolidated!G39)*1000)*(1/0.79941) | H39: =(([1]Consolidated!H39)*1000)*(1/0.79941) | I39: =(([1]Consolidated!I39)*1000)*(1/0.79941) | J39: =(([1]Consolidated!J39)*1000)*(1/0.79941) | L39: =(([1]Consolidated!L39)*1000)*(1/0.79941) | M39: =(([1]Consolidated!M39)*1000)*(1/0.79941) | N39: =(([1]Consolidated!N39)*1000)*(1/0.79941)
C40: Overheads | D40: =(([1]Consolidated!D40)*1000)*(1/0.79941) | E40: =(([1]Consolidated!E40)*1000)*(1/0.79941) | F40: =(([1]Consolidated!F40)*1000)*(1/0.79941) | G40: =(([1]Consolidated!G40)*1000)*(1/0.79941) | H40: =(([1]Consolidated!H40)*1000)*(1/0.79941) | I40: =(([1]Consolidated!I40)*1000)*(1/0.79941) | J40: =(([1]Consolidated!J40)*1000)*(1/0.79941) | L40: =(([1]Consolidated!L40)*1000)*(1/0.79941) | M40: =(([1]Consolidated!M40)*1000)*(1/0.79941) | N40: =(([1]Consolidated!N40)*1000)*(1/0.79941)
C41: 0 | D41: =(([1]Consolidated!D41)*1000)*(1/0.79941) | E41: =(([1]Consolidated!E41)*1000)*(1/0.79941) | F41: =(([1]Consolidated!F41)*1000)*(1/0.79941) | G41: =(([1]Consolidated!G41)*1000)*(1/0.79941) | H41: =(([1]Consolidated!H41)*1000)*(1/0.79941) | I41: =(([1]Consolidated!I41)*1000)*(1/0.79941) | J41: =(([1]Consolidated!J41)*1000)*(1/0.79941) | L41: =(([1]Consolidated!L41)*1000)*(1/0.79941) | M41: =(([1]Consolidated!M41)*1000)*(1/0.79941) | N41: =(([1]Consolidated!N41)*1000)*(1/0.79941)
C42: Total Operating Costs (incl. O/H) | D42: =(([1]Consolidated!D42)*1000)*(1/0.79941) | E42: =(([1]Consolidated!E42)*1000)*(1/0.79941) | F42: =(([1]Consolidated!F42)*1000)*(1/0.79941) | G42: =(([1]Consolidated!G42)*1000)*(1/0.79941) | H42: =(([1]Consolidated!H42)*1000)*(1/0.79941) | I42: =(([1]Consolidated!I42)*1000)*(1/0.79941) | J42: =(([1]Consolidated!J42)*1000)*(1/0.79941) | L42: =(([1]Consolidated!L42)*1000)*(1/0.79941) | M42: =(([1]Consolidated!M42)*1000)*(1/0.79941) | N42: =(([1]Consolidated!N42)*1000)*(1/0.79941)
C45: SUPPLIER ASSUMED COSTS (US$ excl. VAT) | D45: =[1]Consolidated!D45 | E45: =[1]Consolidated!E45 | F45: =[1]Consolidated!F45 | G45: =[1]Consolidated!G45 | H45: =[1]Consolidated!H45 | I45: =[1]Consolidated!I45 | J45: =[1]Consolidated!J45 | L45: =[1]Consolidated!L45 | M45: =[1]Consolidated!M45 | N45: =[1]Consolidated!N45
C46: Internal FTE | D46: =[1]Consolidated!D46 | E46: =[1]Consolidated!E46 | F46: =[1]Consolidated!F46 | G46: =[1]Consolidated!G46 | H46: =[1]Consolidated!H46 | I46: =[1]Consolidated!I46 | L46: =[1]Consolidated!L46 | M46: =[1]Consolidated!M46 | N46: =[1]Consolidated!N46
C47: External FTE | D47: =[1]Consolidated!D47 | E47: =[1]Consolidated!E47 | F47: =[1]Consolidated!F47 | G47: =[1]Consolidated!G47 | H47: =[1]Consolidated!H47 | I47: =[1]Consolidated!I47 | L47: =[1]Consolidated!L47 | M47: =[1]Consolidated!M47 | N47: =[1]Consolidated!N47
C48: Total FTE | D48: =[1]Consolidated!D48 | E48: =[1]Consolidated!E48 | F48: =[1]Consolidated!F48 | G48: =[1]Consolidated!G48 | H48: =[1]Consolidated!H48 | I48: =[1]Consolidated!I48 | L48: =[1]Consolidated!L48 | M48: =[1]Consolidated!M48 | N48: =[1]Consolidated!N48
C50: Salaries | D50: =(([1]Consolidated!D50)*1000)*(1/0.79941) | E50: =(([1]Consolidated!E50)*1000)*(1/0.79941) | F50: =(([1]Consolidated!F50)*1000)*(1/0.79941) | G50: =(([1]Consolidated!G50)*1000)*(1/0.79941) | H50: =(([1]Consolidated!H50)*1000)*(1/0.79941) | I50: =(([1]Consolidated!I50)*1000)*(1/0.79941) | J50: =(([1]Consolidated!J50)*1000)*(1/0.79941) | L50: =(([1]Consolidated!L50)*1000)*(1/0.79941) | M50: =(([1]Consolidated!M50)*1000)*(1/0.79941) | N50: =(([1]Consolidated!N50)*1000)*(1/0.79941)
C51: Bonuses | D51: =(([1]Consolidated!D51)*1000)*(1/0.79941) | E51: =(([1]Consolidated!E51)*1000)*(1/0.79941) | F51: =(([1]Consolidated!F51)*1000)*(1/0.79941) | G51: =(([1]Consolidated!G51)*1000)*(1/0.79941) | H51: =(([1]Consolidated!H51)*1000)*(1/0.79941) | I51: =(([1]Consolidated!I51)*1000)*(1/0.79941) | J51: =(([1]Consolidated!J51)*1000)*(1/0.79941) | L51: =(([1]Consolidated!L51)*1000)*(1/0.79941) | M51: =(([1]Consolidated!M51)*1000)*(1/0.79941) | N51: =(([1]Consolidated!N51)*1000)*(1/0.79941)
C52: Third party staff, ex IT | D52: =(([1]Consolidated!D52)*1000)*(1/0.79941) | E52: =(([1]Consolidated!E52)*1000)*(1/0.79941) | F52: =(([1]Consolidated!F52)*1000)*(1/0.79941) | G52: =(([1]Consolidated!G52)*1000)*(1/0.79941) | H52: =(([1]Consolidated!H52)*1000)*(1/0.79941) | I52: =(([1]Consolidated!I52)*1000)*(1/0.79941) | J52: =(([1]Consolidated!J52)*1000)*(1/0.79941) | L52: =(([1]Consolidated!L52)*1000)*(1/0.79941) | M52: =(([1]Consolidated!M52)*1000)*(1/0.79941) | N52: =(([1]Consolidated!N52)*1000)*(1/0.79941)
C53: Third party IT staff | D53: =(([1]Consolidated!D53)*1000)*(1/0.79941) | E53: =(([1]Consolidated!E53)*1000)*(1/0.79941) | F53: =(([1]Consolidated!F53)*1000)*(1/0.79941) | G53: =(([1]Consolidated!G53)*1000)*(1/0.79941) | H53: =(([1]Consolidated!H53)*1000)*(1/0.79941) | I53: =(([1]Consolidated!I53)*1000)*(1/0.79941) | J53: =(([1]Consolidated!J53)*1000)*(1/0.79941) | L53: =(([1]Consolidated!L53)*1000)*(1/0.79941) | M53: =(([1]Consolidated!M53)*1000)*(1/0.79941) | N53: =(([1]Consolidated!N53)*1000)*(1/0.79941)
C54: Employee education | D54: =(([1]Consolidated!D54)*1000)*(1/0.79941) | E54: =(([1]Consolidated!E54)*1000)*(1/0.79941) | F54: =(([1]Consolidated!F54)*1000)*(1/0.79941) | G54: =(([1]Consolidated!G54)*1000)*(1/0.79941) | H54: =(([1]Consolidated!H54)*1000)*(1/0.79941) | I54: =(([1]Consolidated!I54)*1000)*(1/0.79941) | J54: =(([1]Consolidated!J54)*1000)*(1/0.79941) | L54: =(([1]Consolidated!L54)*1000)*(1/0.79941) | M54: =(([1]Consolidated!M54)*1000)*(1/0.79941) | N54: =(([1]Consolidated!N54)*1000)*(1/0.79941)
C55: Other staff expenses | D55: =(([1]Consolidated!D55)*1000)*(1/0.79941) | E55: =(([1]Consolidated!E55)*1000)*(1/0.79941) | F55: =(([1]Consolidated!F55)*1000)*(1/0.79941) | G55: =(([1]Consolidated!G55)*1000)*(1/0.79941) | H55: =(([1]Consolidated!H55)*1000)*(1/0.79941) | I55: =(([1]Consolidated!I55)*1000)*(1/0.79941) | J55: =(([1]Consolidated!J55)*1000)*(1/0.79941) | L55: =(([1]Consolidated!L55)*1000)*(1/0.79941) | M55: =(([1]Consolidated!M55)*1000)*(1/0.79941) | N55: =(([1]Consolidated!N55)*1000)*(1/0.79941)
C56: Staff expenses | D56: =(([1]Consolidated!D56)*1000)*(1/0.79941) | E56: =(([1]Consolidated!E56)*1000)*(1/0.79941) | F56: =(([1]Consolidated!F56)*1000)*(1/0.79941) | G56: =(([1]Consolidated!G56)*1000)*(1/0.79941) | H56: =(([1]Consolidated!H56)*1000)*(1/0.79941) | I56: =(([1]Consolidated!I56)*1000)*(1/0.79941) | J56: =(([1]Consolidated!J56)*1000)*(1/0.79941) | L56: =(([1]Consolidated!L56)*1000)*(1/0.79941) | M56: =(([1]Consolidated!M56)*1000)*(1/0.79941) | N56: =(([1]Consolidated!N56)*1000)*(1/0.79941)
C57: Hardware expenses | D57: =(([1]Consolidated!D57)*1000)*(1/0.79941) | E57: =(([1]Consolidated!E57)*1000)*(1/0.79941) | F57: =(([1]Consolidated!F57)*1000)*(1/0.79941) | G57: =(([1]Consolidated!G57)*1000)*(1/0.79941) | H57: =(([1]Consolidated!H57)*1000)*(1/0.79941) | I57: =(([1]Consolidated!I57)*1000)*(1/0.79941) | J57: =(([1]Consolidated!J57)*1000)*(1/0.79941) | L57: =(([1]Consolidated!L57)*1000)*(1/0.79941) | M57: =(([1]Consolidated!M57)*1000)*(1/0.79941) | N57: =(([1]Consolidated!N57)*1000)*(1/0.79941)
...

Sheet US
C1: United States
C2: TOTAL COSTS (US$ excl. VAT) | D2: =[2]Consolidated!D2 | E2: =[2]Consolidated!E2 | F2: =[2]Consolidated!F2 | G2: =[2]Consolidated!G2 | H2: =[2]Consolidated!H2 | I2: =[2]Consolidated!I2 | J2: =[2]Consolidated!J2 | L2: =[2]Consolidated!L2 | M2: =[2]Consolidated!M2 | N2: =[2]Consolidated!N2
C3: Internal FTE | D3: =[2]Consolidated!D3 | E3: =[2]Consolidated!E3 | F3: =[2]Consolidated!F3 | G3: =[2]Consolidated!G3 | H3: =[2]Consolidated!H3 | I3: =[2]Consolidated!I3 | L3: =[2]Consolidated!L3 | M3: =[2]Consolidated!M3 | N3: =[2]Consolidated!N3
C4: External FTE | D4: =[2]Consolidated!D4 | E4: =[2]Consolidated!E4 | F4: =[2]Consolidated!F4 | G4: =[2]Consolidated!G4 | H4: =[2]Consolidated!H4 | I4: =[2]Consolidated!I4 | L4: =[2]Consolidated!L4 | M4: =[2]Consolidated!M4 | N4: =[2]Consolidated!N4
C5: Total FTE | D5: =[2]Consolidated!D5 | E5: =[2]Consolidated!E5 | F5: =[2]Consolidated!F5 | G5: =[2]Consolidated!G5 | H5: =[2]Consolidated!H5 | I5: =[2]Consolidated!I5 | L5: =[2]Consolidated!L5 | M5: =[2]Consolidated!M5 | N5: =[2]Consolidated!N5
C7: Salaries | D7: =[2]Consolidated!D7 | E7: =[2]Consolidated!E7 | F7: =[2]Consolidated!F7 | G7: =[2]Consolidated!G7 | H7: =[2]Consolidated!H7 | I7: =[2]Consolidated!I7 | J7: =[2]Consolidated!J7 | L7: =[2]Consolidated!L7 | M7: =[2]Consolidated!M7 | N7: =[2]Consolidated!N7
C8: Bonuses | D8: =[2]Consolidated!D8 | E8: =[2]Consolidated!E8 | F8: =[2]Consolidated!F8 | G8: =[2]Consolidated!G8 | H8: =[2]Consolidated!H8 | I8: =[2]Consolidated!I8 | J8: =[2]Consolidated!J8 | L8: =[2]Consolidated!L8 | M8: =[2]Consolidated!M8 | N8: =[2]Consolidated!N8
C9: Third party staff, ex IT | D9: =[2]Consolidated!D9 | E9: =[2]Consolidated!E9 | F9: =[2]Consolidated!F9 | G9: =[2]Consolidated!G9 | H9: =[2]Consolidated!H9 | I9: =[2]Consolidated!I9 | J9: =[2]Consolidated!J9 | L9: =[2]Consolidated!L9 | M9: =[2]Consolidated!M9 | N9: =[2]Consolidated!N9
C10: Third party IT staff | D10: =[2]Consolidated!D10 | E10: =[2]Consolidated!E10 | F10: =[2]Consolidated!F10 | G10: =[2]Consolidated!G10 | H10: =[2]Consolidated!H10 | I10: =[2]Consolidated!I10 | J10: =[2]Consolidated!J10 | L10: =[2]Consolidated!L10 | M10: =[2]Consolidated!M10 | N10: =[2]Consolidated!N10
C11: Employee education | D11: =[2]Consolidated!D11 | E11: =[2]Consolidated!E11 | F11: =[2]Consolidated!F11 | G11: =[2]Consolidated!G11 | H11: =[2]Consolidated!H11 | I11: =[2]Consolidated!I11 | J11: =[2]Consolidated!J11 | L11: =[2]Consolidated!L11 | M11: =[2]Consolidated!M11 | N11: =[2]Consolidated!N11
C12: Other staff expenses | D12: =[2]Consolidated!D12 | E12: =[2]Consolidated!E12 | F12: =[2]Consolidated!F12 | G12: =[2]Consolidated!G12 | H12: =[2]Consolidated!H12 | I12: =[2]Consolidated!I12 | J12: =[2]Consolidated!J12 | L12: =[2]Consolidated!L12 | M12: =[2]Consolidated!M12 | N12: =[2]Consolidated!N12
C13: Staff expenses | D13: =[2]Consolidated!D13 | E13: =[2]Consolidated!E13 | F13: =[2]Consolidated!F13 | G13: =[2]Consolidated!G13 | H13: =[2]Consolidated!H13 | I13: =[2]Consolidated!I13 | J13: =[2]Consolidated!J13 | L13: =[2]Consolidated!L13 | M13: =[2]Consolidated!M13 | N13: =[2]Consolidated!N13
C14: Hardware expenses | D14: =[2]Consolidated!D14 | E14: =[2]Consolidated!E14 | F14: =[2]Consolidated!F14 | G14: =[2]Consolidated!G14 | H14: =[2]Consolidated!H14 | I14: =[2]Consolidated!I14 | J14: =[2]Consolidated!J14 | L14: =[2]Consolidated!L14 | M14: =[2]Consolidated!M14 | N14: =[2]Consolidated!N14
C15: Leasing/renting hardware | D15: =[2]Consolidated!D15 | E15: =[2]Consolidated!E15 | F15: =[2]Consolidated!F15 | G15: =[2]Consolidated!G15 | H15: =[2]Consolidated!H15 | I15: =[2]Consolidated!I15 | J15: =[2]Consolidated!J15 | L15: =[2]Consolidated!L15 | M15: =[2]Consolidated!M15 | N15: =[2]Consolidated!N15
C16: Software expenses | D16: =[2]Consolidated!D16 | E16: =[2]Consolidated!E16 | F16: =[2]Consolidated!F16 | G16: =[2]Consolidated!G16 | H16: =[2]Consolidated!H16 | I16: =[2]Consolidated!I16 | J16: =[2]Consolidated!J16 | L16: =[2]Consolidated!L16 | M16: =[2]Consolidated!M16 | N16: =[2]Consolidated!N16
C17: Leasing/renting/licenses sw | D17: =[2]Consolidated!D17 | E17: =[2]Consolidated!E17 | F17: =[2]Consolidated!F17 | G17: =[2]Consolidated!G17 | H17: =[2]Consolidated!H17 | I17: =[2]Consolidated!I17 | J17: =[2]Consolidated!J17 | L17: =[2]Consolidated!L17 | M17: =[2]Consolidated!M17 | N17: =[2]Consolidated!N17
C18: Depreciation hardware | D18: =[2]Consolidated!D18 | E18: =[2]Consolidated!E18 | F18: =[2]Consolidated!F18 | G18: =[2]Consolidated!G18 | H18: =[2]Consolidated!H18 | I18: =[2]Consolidated!I18 | J18: =[2]Consolidated!J18 | L18: =[2]Consolidated!L18 | M18: =[2]Consolidated!M18 | N18: =[2]Consolidated!N18
... C40: Overheads | D40: =[2]Consolidated!D40 | E40: =[2]Consolidated!E40 | F40: =[2]Consolidated!F40 | G40: =[2]Consolidated!G40 | H40: =[2]Consolidated!H40 | I40: =[2]Consolidated!I40 | J40: =[2]Consolidated!J40 | L40: =[2]Consolidated!L40 | M40: =[2]Consolidated!M40 | N40: =[2]Consolidated!N40
C41: 0
C42: Total Operating Costs (incl. O/H) | D42: =[2]Consolidated!D42 | E42: =[2]Consolidated!E42 | F42: =[2]Consolidated!F42 | G42: =[2]Consolidated!G42 | H42: =[2]Consolidated!H42 | I42: =[2]Consolidated!I42 | J42: =[2]Consolidated!J42 | L42: =[2]Consolidated!L42 | M42: =[2]Consolidated!M42 | N42: =[2]Consolidated!N42
C45: SUPPLIER ASSUMED COSTS (US$ excl. VAT) | D45: =[2]Consolidated!D45 | E45: =[2]Consolidated!E45 | F45: =[2]Consolidated!F45 | G45: =[2]Consolidated!G45 | H45: =[2]Consolidated!H45 | I45: =[2]Consolidated!I45 | J45: =[2]Consolidated!J45 | L45: =[2]Consolidated!L45 | M45: =[2]Consolidated!M45 | N45: =[2]Consolidated!N45
C46: Internal FTE | D46: =[2]Consolidated!D46 | E46: =[2]Consolidated!E46 | F46: =[2]Consolidated!F46 | G46: =[2]Consolidated!G46 | H46: =[2]Consolidated!H46 | I46: =[2]Consolidated!I46 | L46: =[2]Consolidated!L46 | M46: =[2]Consolidated!M46 | N46: =[2]Consolidated!N46
C47: External FTE | D47: =[2]Consolidated!D47 | E47: =[2]Consolidated!E47 | F47: =[2]Consolidated!F47 | G47: =[2]Consolidated!G47 | H47: =[2]Consolidated!H47 | I47: =[2]Consolidated!I47 | L47: =[2]Consolidated!L47 | M47: =[2]Consolidated!M47 | N47: =[2]Consolidated!N47
C48: Total FTE | D48: =[2]Consolidated!D48 | E48: =[2]Consolidated!E48 | F48: =[2]Consolidated!F48 | G48: =[2]Consolidated!G48 | H48: =[2]Consolidated!H48 | I48: =[2]Consolidated!I48 | L48: =[2]Consolidated!L48 | M48: =[2]Consolidated!M48 | N48: =[2]Consolidated!N48
C50: Salaries | D50: =[2]Consolidated!D50 | E50: =[2]Consolidated!E50 | F50: =[2]Consolidated!F50 | G50: =[2]Consolidated!G50 | H50: =[2]Consolidated!H50 | I50: =[2]Consolidated!I50 | J50: =[2]Consolidated!J50 | L50: =[2]Consolidated!L50 | M50: =[2]Consolidated!M50 | N50: =[2]Consolidated!N50
C51: Bonuses | D51: =[2]Consolidated!D51 | E51: =[2]Consolidated!E51 | F51: =[2]Consolidated!F51 | G51: =[2]Consolidated!G51 | H51: =[2]Consolidated!H51 | I51: =[2]Consolidated!I51 | J51: =[2]Consolidated!J51 | L51: =[2]Consolidated!L51 | M51: =[2]Consolidated!M51 | N51: =[2]Consolidated!N51
C52: Third party staff, ex IT | D52: =[2]Consolidated!D52 | E52: =[2]Consolidated!E52 | F52: =[2]Consolidated!F52 | G52: =[2]Consolidated!G52 | H52: =[2]Consolidated!H52 | I52: =[2]Consolidated!I52 | J52: =[2]Consolidated!J52 | L52: =[2]Consolidated!L52 | M52: =[2]Consolidated!M52 | N52: =[2]Consolidated!N52
C53: Third party IT staff | D53: =[2]Consolidated!D53 | E53: =[2]Consolidated!E53 | F53: =[2]Consolidated!F53 | G53: =[2]Consolidated!G53 | H53: =[2]Consolidated!H53 | I53: =[2]Consolidated!I53 | J53: =[2]Consolidated!J53 | L53: =[2]Consolidated!L53 | M53: =[2]Consolidated!M53 | N53: =[2]Consolidated!N53
C54: Employee education | D54: =[2]Consolidated!D54 | E54: =[2]Consolidated!E54 | F54: =[2]Consolidated!F54 | G54: =[2]Consolidated!G54 | H54: =[2]Consolidated!H54 | I54: =[2]Consolidated!I54 | J54: =[2]Consolidated!J54 | L54: =[2]Consolidated!L54 | M54: =[2]Consolidated!M54 | N54: =[2]Consolidated!N54
C55: Other staff expenses | D55: =[2]Consolidated!D55 | E55: =[2]Consolidated!E55 | F55: =[2]Consolidated!F55 | G55: =[2]Consolidated!G55 | H55: =[2]Consolidated!H55 | I55: =[2]Consolidated!I55 | J55: =[2]Consolidated!J55 | L55: =[2]Consolidated!L55 | M55: =[2]Consolidated!M55 | N55: =[2]Consolidated!N55
C56: Staff expenses | D56: =[2]Consolidated!D56 | E56: =[2]Consolidated!E56 | F56: =[2]Consolidated!F56 | G56: =[2]Consolidated!G56 | H56: =[2]Consolidated!H56 | I56: =[2]Consolidated!I56 | J56: =[2]Consolidated!J56 | L56: =[2]Consolidated!L56 | M56: =[2]Consolidated!M56 | N56: =[2]Consolidated!N56
C57: Hardware expenses | D57: =[2]Consolidated!D57 | E57: =[2]Consolidated!E57 | F57: =[2]Consolidated!F57 | G57: =[2]Consolidated!G57 | H57: =[2]Consolidated!H57 | I57: =[2]Consolidated!I57 | J57: =[2]Consolidated!J57 | L57: =[2]Consolidated!L57 | M57: =[2]Consolidated!M57 | N57: =[2]Consolidated!N57
C58: Leasing/renting hardware | D58: =[2]Consolidated!D58 | E58: =[2]Consolidated!E58 | F58: =[2]Consolidated!F58 | G58: =[2]Consolidated!G58 | H58: =[2]Consolidated!H58 | I58: =[2]Consolidated!I58 | J58: =[2]Consolidated!J58 | L58: =[2]Consolidated!L58 | M58: =[2]Consolidated!M58 | N58: =[2]Consolidated!N58
C59: Software expenses | D59: =[2]Consolidated!D59 | E59: =[2]Consolidated!E59 | F59: =[2]Consolidated!F59 | G59: =[2]Consolidated!G59 | H59: =[2]Consolidated!H59 | I59: =[2]Consolidated!I59 | J59: =[2]Consolidated!J59 | L59: =[2]Consolidated!L59 | M59: =[2]Consolidated!M59 | N59: =[2]Consolidated!N59
C60: Leasing/renting/licenses sw | D60: =[2]Consolidated!D60 | E60: =[2]Consolidated!E60 | F60: =[2]Consolidated!F60 | G60: =[2]Consolidated!G60 | H60: =[2]Consolidated!H60 | I60: =[2]Consolidated!I60 | J60: =[2]Consolidated!J60 | L60: =[2]Consolidated!L60 | M60: =[2]Consolidated!M60 | N60: =[2]Consolidated!N60
C61: Depreciation hardware | D61: =[2]Consolidated!D61 | E61: =[2]Consolidated!E61 | F61: =[2]Consolidated!F61 | G61: =[2]Consolidated!G61 | H61: =[2]Consolidated!H61 | I61: =[2]Consolidated!I61 | J61: =[2]Consolidated!J61 | L61: =[2]Consolidated!L61 | M61: =[2]Consolidated!M61 | N61: =[2]Consolidated!N61
... C63: Outsourcing IT activities | D63: =[2]Consolidated!D63 | E63: =[2]Consolidated!E63 | F63: =[2]Consolidated!F63 | G63: =[2]Consolidated!G63 | H63: =[2]Consolidated!H63 | I63: =[2]Consolidated!I63 | J63: =[2]Consolidated!J63 | L63: =[2]Consolidated!L63 | M63: =[2]Consolidated!M63 | N63: =[2]Consolidated!N63
C64: Other IT expenses | D64: =D65 | E64: =E65 | F64: =F65 | G64: =G65 | H64: =H65 | I64: =I65 | J64: =J65 | L64: =L65 | M64: =M65 | N64: =N65 | P64: Adjusted
C65: EDP expenses | D65: =[2]Consolidated!D65 | E65: =[2]Consolidated!E65 | F65: =[2]Consolidated!F65 | G65: =[2]Consolidated!G65 | H65: =[2]Consolidated!H65 | I65: =[2]Consolidated!I65 | J65: =[2]Consolidated!J65 | L65: =[2]Consolidated!L65 | M65: =[2]Consolidated!M65 | N65: =[2]Consolidated!N65
C66: Telecom expenses | D66: =[2]Consolidated!D66 | E66: =[2]Consolidated!E66 | F66: =[2]Consolidated!F66 | G66: =[2]Consolidated!G66 | H66: =[2]Consolidated!H66 | I66: =[2]Consolidated!I66 | J66: =[2]Consolidated!J66 | L66: =[2]Consolidated!L66 | M66: =[2]Consolidated!M66 | N66: =[2]Consolidated!N66
...

Sheet France
C1: France
C2: TOTAL COSTS (US$ excl. VAT) | D2: =[3]Consolidated!D2 | E2: =[3]Consolidated!E2 | F2: =[3]Consolidated!F2 | G2: =[3]Consolidated!G2 | H2: =[3]Consolidated!H2 | I2: =[3]Consolidated!I2 | J2: =[3]Consolidated!J2 | L2: =[3]Consolidated!L2 | M2: =[3]Consolidated!M2 | N2: =[3]Consolidated!N2
C3: Internal FTE | D3: =[3]Consolidated!D3 | E3: =[3]Consolidated!E3 | F3: =[3]Consolidated!F3 | G3: =[3]Consolidated!G3 | H3: =[3]Consolidated!H3 | I3: =[3]Consolidated!I3 | L3: =[3]Consolidated!L3 | M3: =[3]Consolidated!M3 | N3: =[3]Consolidated!N3
C4: External FTE | D4: =[3]Consolidated!D4 | E4: =[3]Consolidated!E4 | F4: =[3]Consolidated!F4 | G4: =[3]Consolidated!G4 | H4: =[3]Consolidated!H4 | I4: =[3]Consolidated!I4 | L4: =[3]Consolidated!L4 | M4: =[3]Consolidated!M4 | N4: =[3]Consolidated!N4
C5: Total FTE | D5: =[3]Consolidated!D5 | E5: =[3]Consolidated!E5 | F5: =[3]Consolidated!F5 | G5: =[3]Consolidated!G5 | H5: =[3]Consolidated!H5 | I5: =[3]Consolidated!I5 | L5: =[3]Consolidated!L5 | M5: =[3]Consolidated!M5 | N5: =[3]Consolidated!N5
C7: Salaries | D7: =(([3]Consolidated!D7)*1000)*(1/0.79941) | E7: =(([3]Consolidated!E7)*1000)*(1/0.79941) | F7: =(([3]Consolidated!F7)*1000)*(1/0.79941) | G7: =(([3]Consolidated!G7)*1000)*(1/0.79941) | H7: =(([3]Consolidated!H7)*1000)*(1/0.79941) | I7: =(([3]Consolidated!I7)*1000)*(1/0.79941) | J7: =(([3]Consolidated!J7)*1000)*(1/0.79941) | L7: =(([3]Consolidated!L7)*1000)*(1/0.79941) | M7: =(([3]Consolidated!M7)*1000)*(1/0.79941) | N7: =(([3]Consolidated!N7)*1000)*(1/0.79941) | P7: 1000
C8: Bonuses | D8: =(([3]Consolidated!D8)*1000)*(1/0.79941) | E8: =(([3]Consolidated!E8)*1000)*(1/0.79941) | F8: =(([3]Consolidated!F8)*1000)*(1/0.79941) | G8: =(([3]Consolidated!G8)*1000)*(1/0.79941) | H8: =(([3]Consolidated!H8)*1000)*(1/0.79941) | I8: =(([3]Consolidated!I8)*1000)*(1/0.79941) | J8: =(([3]Consolidated!J8)*1000)*(1/0.79941) | L8: =(([3]Consolidated!L8)*1000)*(1/0.79941) | M8: =(([3]Consolidated!M8)*1000)*(1/0.79941) | N8: =(([3]Consolidated!N8)*1000)*(1/0.79941) | P8: =1/0.79941 | Q8: Euro to Dollar Rate
C9: Third party staff, ex IT | D9: =(([3]Consolidated!D9)*1000)*(1/0.79941) | E9: =(([3]Consolidated!E9)*1000)*(1/0.79941) | F9: =(([3]Consolidated!F9)*1000)*(1/0.79941) | G9: =(([3]Consolidated!G9)*1000)*(1/0.79941) | H9: =(([3]Consolidated!H9)*1000)*(1/0.79941) | I9: =(([3]Consolidated!I9)*1000)*(1/0.79941) | J9: =(([3]Consolidated!J9)*1000)*(1/0.79941) | L9: =(([3]Consolidated!L9)*1000)*(1/0.79941) | M9: =(([3]Consolidated!M9)*1000)*(1/0.79941) | N9: =(([3]Consolidated!N9)*1000)*(1/0.79941)
C10: Third party IT staff | D10: =(([3]Consolidated!D10)*1000)*(1/0.79941) | E10: =(([3]Consolidated!E10)*1000)*(1/0.79941) | F10: =(([3]Consolidated!F10)*1000)*(1/0.79941) | G10: =(([3]Consolidated!G10)*1000)*(1/0.79941) | H10: =(([3]Consolidated!H10)*1000)*(1/0.79941) | I10: =(([3]Consolidated!I10)*1000)*(1/0.79941) | J10: =(([3]Consolidated!J10)*1000)*(1/0.79941) | L10: =(([3]Consolidated!L10)*1000)*(1/0.79941) | M10: =(([3]Consolidated!M10)*1000)*(1/0.79941) | N10: =(([3]Consolidated!N10)*1000)*(1/0.79941)
C11: Employee education | D11: =(([3]Consolidated!D11)*1000)*(1/0.79941) | E11: =(([3]Consolidated!E11)*1000)*(1/0.79941) | F11: =(([3]Consolidated!F11)*1000)*(1/0.79941) | G11: =(([3]Consolidated!G11)*1000)*(1/0.79941) | H11: =(([3]Consolidated!H11)*1000)*(1/0.79941) | I11: =(([3]Consolidated!I11)*1000)*(1/0.79941) | J11: =(([3]Consolidated!J11)*1000)*(1/0.79941) | L11: =(([3]Consolidated!L11)*1000)*(1/0.79941) | M11: =(([3]Consolidated!M11)*1000)*(1/0.79941) | N11: =(([3]Consolidated!N11)*1000)*(1/0.79941)
C12: Other staff expenses | D12: =(([3]Consolidated!D12)*1000)*(1/0.79941) | E12: =(([3]Consolidated!E12)*1000)*(1/0.79941) | F12: =(([3]Consolidated!F12)*1000)*(1/0.79941) | G12: =(([3]Consolidated!G12)*1000)*(1/0.79941) | H12: =(([3]Consolidated!H12)*1000)*(1/0.79941) | I12: =(([3]Consolidated!I12)*1000)*(1/0.79941) | J12: =(([3]Consolidated!J12)*1000)*(1/0.79941) | L12: =(([3]Consolidated!L12)*1000)*(1/0.79941) | M12: =(([3]Consolidated!M12)*1000)*(1/0.79941) | N12: =(([3]Consolidated!N12)*1000)*(1/0.79941)
C13: Staff expenses | D13: =(([3]Consolidated!D13)*1000)*(1/0.79941) | E13: =(([3]Consolidated!E13)*1000)*(1/0.79941) | F13: =(([3]Consolidated!F13)*1000)*(1/0.79941) | G13: =(([3]Consolidated!G13)*1000)*(1/0.79941) | H13: =(([3]Consolidated!H13)*1000)*(1/0.79941) | I13: =(([3]Consolidated!I13)*1000)*(1/0.79941) | J13: =(([3]Consolidated!J13)*1000)*(1/0.79941) | L13: =(([3]Consolidated!L13)*1000)*(1/0.79941) | M13: =(([3]Consolidated!M13)*1000)*(1/0.79941) | N13: =(([3]Consolidated!N13)*1000)*(1/0.79941)
C14: Hardware expenses | D14: =(([3]Consolidated!D14)*1000)*(1/0.79941) | E14: =(([3]Consolidated!E14)*1000)*(1/0.79941) | F14: =(([3]Consolidated!F14)*1000)*(1/0.79941) | G14: =(([3]Consolidated!G14)*1000)*(1/0.79941) | H14: =(([3]Consolidated!H14)*1000)*(1/0.79941) | I14: =(([3]Consolidated!I14)*1000)*(1/0.79941) | J14: =(([3]Consolidated!J14)*1000)*(1/0.79941) | L14: =(([3]Consolidated!L14)*1000)*(1/0.79941) | M14: =(([3]Consolidated!M14)*1000)*(1/0.79941) | N14: =(([3]Consolidated!N14)*1000)*(1/0.79941)
C15: Leasing/renting hardware | D15: =(([3]Consolidated!D15)*1000)*(1/0.79941) | E15: =(([3]Consolidated!E15)*1000)*(1/0.79941) | F15: =(([3]Consolidated!F15)*1000)*(1/0.79941) | G15: =(([3]Consolidated!G15)*1000)*(1/0.79941) | H15: =(([3]Consolidated!H15)*1000)*(1/0.79941) | I15: =(([3]Consolidated!I15)*1000)*(1/0.79941) | J15: =(([3]Consolidated!J15)*1000)*(1/0.79941) | L15: =(([3]Consolidated!L15)*1000)*(1/0.79941) | M15: =(([3]Consolidated!M15)*1000)*(1/0.79941) | N15: =(([3]Consolidated!N15)*1000)*(1/0.79941)
C16: Software expenses | D16: =(([3]Consolidated!D16)*1000)*(1/0.79941) | E16: =(([3]Consolidated!E16)*1000)*(1/0.79941) | F16: =(([3]Consolidated!F16)*1000)*(1/0.79941) | G16: =(([3]Consolidated!G16)*1000)*(1/0.79941) | H16: =(([3]Consolidated!H16)*1000)*(1/0.79941) | I16: =(([3]Consolidated!I16)*1000)*(1/0.79941) | J16: =(([3]Consolidated!J16)*1000)*(1/0.79941) | L16: =(([3]Consolidated!L16)*1000)*(1/0.79941) | M16: =(([3]Consolidated!M16)*1000)*(1/0.79941) | N16: =(([3]Consolidated!N16)*1000)*(1/0.79941)
C17: Leasing/renting/licenses sw | D17: =(([3]Consolidated!D17)*1000)*(1/0.79941) | E17: =(([3]Consolidated!E17)*1000)*(1/0.79941) | F17: =(([3]Consolidated!F17)*1000)*(1/0.79941) | G17: =(([3]Consolidated!G17)*1000)*(1/0.79941) | H17: =(([3]Consolidated!H17)*1000)*(1/0.79941) | I17: =(([3]Consolidated!I17)*1000)*(1/0.79941) | J17: =(([3]Consolidated!J17)*1000)*(1/0.79941) | L17: =(([3]Consolidated!L17)*1000)*(1/0.79941) | M17: =(([3]Consolidated!M17)*1000)*(1/0.79941) | N17: =(([3]Consolidated!N17)*1000)*(1/0.79941)
C18: Depreciation hardware | D18: =(([3]Consolidated!D18)*1000)*(1/0.79941) | E18: =(([3]Consolidated!E18)*1000)*(1/0.79941) | F18: =(([3]Consolidated!F18)*1000)*(1/0.79941) | G18: =(([3]Consolidated!G18)*1000)*(1/0.79941) | H18: =(([3]Consolidated!H18)*1000)*(1/0.79941) | I18: =(([3]Consolidated!I18)*1000)*(1/0.79941) | J18: =(([3]Consolidated!J18)*1000)*(1/0.79941) | L18: =(([3]Consolidated!L18)*1000)*(1/0.79941) | M18: =(([3]Consolidated!M18)*1000)*(1/0.79941) | N18: =(([3]Consolidated!N18)*1000)*(1/0.79941)
C19: Depreciation software | D19: =(([3]Consolidated!D19)*1000)*(1/0.79941) | E19: =(([3]Consolidated!E19)*1000)*(1/0.79941) | F19: =(([3]Consolidated!F19)*1000)*(1/0.79941) | G19: =(([3]Consolidated!G19)*1000)*(1/0.79941) | H19: =(([3]Consolidated!H19)*1000)*(1/0.79941) | I19: =(([3]Consolidated!I19)*1000)*(1/0.79941) | J19: =(([3]Consolidated!J19)*1000)*(1/0.79941) | L19: =(([3]Consolidated!L19)*1000)*(1/0.79941) | M19: =(([3]Consolidated!M19)*1000)*(1/0.79941) | N19: =(([3]Consolidated!N19)*1000)*(1/0.79941)
C20: Outsourcing IT activities | D20: =(([3]Consolidated!D20)*1000)*(1/0.79941) | E20: =(([3]Consolidated!E20)*1000)*(1/0.79941) | F20: =(([3]Consolidated!F20)*1000)*(1/0.79941) | G20: =(([3]Consolidated!G20)*1000)*(1/0.79941) | H20: =(([3]Consolidated!H20)*1000)*(1/0.79941) | I20: =(([3]Consolidated!I20)*1000)*(1/0.79941) | J20: =(([3]Consolidated!J20)*1000)*(1/0.79941) | L20: =(([3]Consolidated!L20)*1000)*(1/0.79941) | M20: =(([3]Consolidated!M20)*1000)*(1/0.79941) | N20: =(([3]Consolidated!N20)*1000)*(1/0.79941)
... C34: Operating expenses | D34: =(([3]Consolidated!D34)*1000)*(1/0.79941) | E34: =(([3]Consolidated!E34)*1000)*(1/0.79941) | F34: =(([3]Consolidated!F34)*1000)*(1/0.79941) | G34: =(([3]Consolidated!G34)*1000)*(1/0.79941) | H34: =(([3]Consolidated!H34)*1000)*(1/0.79941) | I34: =(([3]Consolidated!I34)*1000)*(1/0.79941) | J34: =(([3]Consolidated!J34)*1000)*(1/0.79941) | L34: =(([3]Consolidated!L34)*1000)*(1/0.79941) | M34: =(([3]Consolidated!M34)*1000)*(1/0.79941) | N34: =(([3]Consolidated!N34)*1000)*(1/0.79941)
D35: =0*(1/0.79941) | E35: =0*(1/0.79941) | F35: =0*(1/0.79941) | G35: =0*(1/0.79941) | H35: =0*(1/0.79941) | I35: =0*(1/0.79941) | J35: =0*(1/0.79941) | L35: =0*(1/0.79941) | M35: =0*(1/0.79941) | N35: =0*(1/0.79941)
C36: HR & Comms | D36: =(([3]Consolidated!D36)*1000)*(1/0.79941) | E36: =(([3]Consolidated!E36)*1000)*(1/0.79941) | F36: =(([3]Consolidated!F36)*1000)*(1/0.79941) | G36: =(([3]Consolidated!G36)*1000)*(1/0.79941) | H36: =(([3]Consolidated!H36)*1000)*(1/0.79941) | I36: =(([3]Consolidated!I36)*1000)*(1/0.79941) | J36: =(([3]Consolidated!J36)*1000)*(1/0.79941) | L36: =(([3]Consolidated!L36)*1000)*(1/0.79941) | M36: =(([3]Consolidated!M36)*1000)*(1/0.79941) | N36: =(([3]Consolidated!N36)*1000)*(1/0.79941)
C37: Finance & Business Support | D37: =(([3]Consolidated!D37)*1000)*(1/0.79941) | E37: =(([3]Consolidated!E37)*1000)*(1/0.79941) | F37: =(([3]Consolidated!F37)*1000)*(1/0.79941) | G37: =(([3]Consolidated!G37)*1000)*(1/0.79941) | H37: =(([3]Consolidated!H37)*1000)*(1/0.79941) | I37: =(([3]Consolidated!I37)*1000)*(1/0.79941) | J37: =(([3]Consolidated!J37)*1000)*(1/0.79941) | L37: =(([3]Consolidated!L37)*1000)*(1/0.79941) | M37: =(([3]Consolidated!M37)*1000)*(1/0.79941) | N37: =(([3]Consolidated!N37)*1000)*(1/0.79941)
C38: IT alloc | D38: =(([3]Consolidated!D38)*1000)*(1/0.79941) | E38: =(([3]Consolidated!E38)*1000)*(1/0.79941) | F38: =(([3]Consolidated!F38)*1000)*(1/0.79941) | G38: =(([3]Consolidated!G38)*1000)*(1/0.79941) | H38: =(([3]Consolidated!H38)*1000)*(1/0.79941) | I38: =(([3]Consolidated!I38)*1000)*(1/0.79941) | J38: =(([3]Consolidated!J38)*1000)*(1/0.79941) | L38: =(([3]Consolidated!L38)*1000)*(1/0.79941) | M38: =(([3]Consolidated!M38)*1000)*(1/0.79941) | N38: =(([3]Consolidated!N38)*1000)*(1/0.79941)
C39: Facilities Management | D39: =(([3]Consolidated!D39)*1000)*(1/0.79941) | E39: =(([3]Consolidated!E39)*1000)*(1/0.79941) | F39: =(([3]Consolidated!F39)*1000)*(1/0.79941) | G39: =(([3]Consolidated!G39)*1000)*(1/0.79941) | H39: =(([3]Consolidated!H39)*1000)*(1/0.79941) | I39: =(([3]Consolidated!I39)*1000)*(1/0.79941) | J39: =(([3]Consolidated!J39)*1000)*(1/0.79941) | L39: =(([3]Consolidated!L39)*1000)*(1/0.79941) | M39: =(([3]Consolidated!M39)*1000)*(1/0.79941) | N39: =(([3]Consolidated!N39)*1000)*(1/0.79941)
C40: Overheads | D40: =(([3]Consolidated!D40)*1000)*(1/0.79941) | E40: =(([3]Consolidated!E40)*1000)*(1/0.79941) | F40: =(([3]Consolidated!F40)*1000)*(1/0.79941) | G40: =(([3]Consolidated!G40)*1000)*(1/0.79941) | H40: =(([3]Consolidated!H40)*1000)*(1/0.79941) | I40: =(([3]Consolidated!I40)*1000)*(1/0.79941) | J40: =(([3]Consolidated!J40)*1000)*(1/0.79941) | L40: =(([3]Consolidated!L40)*1000)*(1/0.79941) | M40: =(([3]Consolidated!M40)*1000)*(1/0.79941) | N40: =(([3]Consolidated!N40)*1000)*(1/0.79941)
C41: 0 | D41: =0*(1/0.79941) | E41: =0*(1/0.79941) | F41: =0*(1/0.79941) | G41: =0*(1/0.79941) | H41: =0*(1/0.79941) | I41: =0*(1/0.79941) | J41: =0*(1/0.79941) | L41: =0*(1/0.79941) | M41: =0*(1/0.79941) | N41: =0*(1/0.79941)
C42: Total Operating Costs (incl. O/H) | D42: =(([3]Consolidated!D42)*1000)*(1/0.79941) | E42: =(([3]Consolidated!E42)*1000)*(1/0.79941) | F42: =(([3]Consolidated!F42)*1000)*(1/0.79941) | G42: =(([3]Consolidated!G42)*1000)*(1/0.79941) | H42: =(([3]Consolidated!H42)*1000)*(1/0.79941) | I42: =(([3]Consolidated!I42)*1000)*(1/0.79941) | J42: =(([3]Consolidated!J42)*1000)*(1/0.79941) | L42: =(([3]Consolidated!L42)*1000)*(1/0.79941) | M42: =(([3]Consolidated!M42)*1000)*(1/0.79941) | N42: =(([3]Consolidated!N42)*1000)*(1/0.79941)
C45: SUPPLIER ASSUMED COSTS (US$ excl. VAT) | D45: =[3]Consolidated!D45 | E45: =[3]Consolidated!E45 | F45: =[3]Consolidated!F45 | G45: =[3]Consolidated!G45 | H45: =[3]Consolidated!H45 | I45: =[3]Consolidated!I45 | J45: =[3]Consolidated!J45 | L45: =[3]Consolidated!L45 | M45: =[3]Consolidated!M45 | N45: =[3]Consolidated!N45
C46: Internal FTE | D46: =[3]Consolidated!D46 | E46: =[3]Consolidated!E46 | F46: =[3]Consolidated!F46 | G46: =[3]Consolidated!G46 | H46: =[3]Consolidated!H46 | I46: =[3]Consolidated!I46 | L46: =[3]Consolidated!L46 | M46: =[3]Consolidated!M46
C47: External FTE | D47: =[3]Consolidated!D47 | E47: =[3]Consolidated!E47 | F47: =[3]Consolidated!F47 | G47: =[3]Consolidated!G47 | H47: =[3]Consolidated!H47 | I47: =[3]Consolidated!I47 | L47: =[3]Consolidated!L47 | M47: =[3]Consolidated!M47
C48: Total FTE | D48: =[3]Consolidated!D48 | E48: =[3]Consolidated!E48 | F48: =[3]Consolidated!F48 | G48: =[3]Consolidated!G48 | H48: =[3]Consolidated!H48 | I48: =[3]Consolidated!I48 | L48: =[3]Consolidated!L48 | M48: =[3]Consolidated!M48
C50: Salaries | D50: =(([3]Consolidated!D50)*1000)*(1/0.79941) | E50: =(([3]Consolidated!E50)*1000)*(1/0.79941) | F50: =(([3]Consolidated!F50)*1000)*(1/0.79941) | G50: =(([3]Consolidated!G50)*1000)*(1/0.79941) | H50: =(([3]Consolidated!H50)*1000)*(1/0.79941) | I50: =(([3]Consolidated!I50)*1000)*(1/0.79941) | J50: =(([3]Consolidated!J50)*1000)*(1/0.79941) | L50: =(([3]Consolidated!L50)*1000)*(1/0.79941) | M50: =(([3]Consolidated!M50)*1000)*(1/0.79941) | N50: =(([3]Consolidated!N50)*1000)*(1/0.79941)
C51: Bonuses | D51: =(([3]Consolidated!D51)*1000)*(1/0.79941) | E51: =(([3]Consolidated!E51)*1000)*(1/0.79941) | F51: =(([3]Consolidated!F51)*1000)*(1/0.79941) | G51: =(([3]Consolidated!G51)*1000)*(1/0.79941) | H51: =(([3]Consolidated!H51)*1000)*(1/0.79941) | I51: =(([3]Consolidated!I51)*1000)*(1/0.79941) | J51: =(([3]Consolidated!J51)*1000)*(1/0.79941) | L51: =(([3]Consolidated!L51)*1000)*(1/0.79941) | M51: =(([3]Consolidated!M51)*1000)*(1/0.79941) | N51: =(([3]Consolidated!N51)*1000)*(1/0.79941)
C52: Third party staff, ex IT | D52: =(([3]Consolidated!D52)*1000)*(1/0.79941) | E52: =(([3]Consolidated!E52)*1000)*(1/0.79941) | F52: =(([3]Consolidated!F52)*1000)*(1/0.79941) | G52: =(([3]Consolidated!G52)*1000)*(1/0.79941) | H52: =(([3]Consolidated!H52)*1000)*(1/0.79941) | I52: =(([3]Consolidated!I52)*1000)*(1/0.79941) | J52: =(([3]Consolidated!J52)*1000)*(1/0.79941) | L52: =(([3]Consolidated!L52)*1000)*(1/0.79941) | M52: =(([3]Consolidated!M52)*1000)*(1/0.79941) | N52: =(([3]Consolidated!N52)*1000)*(1/0.79941)
C53: Third party IT staff | D53: =(([3]Consolidated!D53)*1000)*(1/0.79941) | E53: =(([3]Consolidated!E53)*1000)*(1/0.79941) | F53: =(([3]Consolidated!F53)*1000)*(1/0.79941) | G53: =(([3]Consolidated!G53)*1000)*(1/0.79941) | H53: =(([3]Consolidated!H53)*1000)*(1/0.79941) | I53: =(([3]Consolidated!I53)*1000)*(1/0.79941) | J53: =(([3]Consolidated!J53)*1000)*(1/0.79941) | L53: =(([3]Consolidated!L53)*1000)*(1/0.79941) | M53: =(([3]Consolidated!M53)*1000)*(1/0.79941) | N53: =(([3]Consolidated!N53)*1000)*(1/0.79941)
C54: Employee education | D54: =(([3]Consolidated!D54)*1000)*(1/0.79941) | E54: =(([3]Consolidated!E54)*1000)*(1/0.79941) | F54: =(([3]Consolidated!F54)*1000)*(1/0.79941) | G54: =(([3]Consolidated!G54)*1000)*(1/0.79941) | H54: =(([3]Consolidated!H54)*1000)*(1/0.79941) | I54: =(([3]Consolidated!I54)*1000)*(1/0.79941) | J54: =(([3]Consolidated!J54)*1000)*(1/0.79941) | L54: =(([3]Consolidated!L54)*1000)*(1/0.79941) | M54: =(([3]Consolidated!M54)*1000)*(1/0.79941) | N54: =(([3]Consolidated!N54)*1000)*(1/0.79941)
C55: Other staff expenses | D55: =(([3]Consolidated!D55)*1000)*(1/0.79941) | E55: =(([3]Consolidated!E55)*1000)*(1/0.79941) | F55: =(([3]Consolidated!F55)*1000)*(1/0.79941) | G55: =(([3]Consolidated!G55)*1000)*(1/0.79941) | H55: =(([3]Consolidated!H55)*1000)*(1/0.79941) | I55: =(([3]Consolidated!I55)*1000)*(1/0.79941) | J55: =(([3]Consolidated!J55)*1000)*(1/0.79941) | L55: =(([3]Consolidated!L55)*1000)*(1/0.79941) | M55: =(([3]Consolidated!M55)*1000)*(1/0.79941) | N55: =(([3]Consolidated!N55)*1000)*(1/0.79941)
C56: Staff expenses | D56: =(([3]Consolidated!D56)*1000)*(1/0.79941) | E56: =(([3]Consolidated!E56)*1000)*(1/0.79941) | F56: =(([3]Consolidated!F56)*1000)*(1/0.79941) | G56: =(([3]Consolidated!G56)*1000)*(1/0.79941) | H56: =(([3]Consolidated!H56)*1000)*(1/0.79941) | I56: =(([3]Consolidated!I56)*1000)*(1/0.79941) | J56: =(([3]Consolidated!J56)*1000)*(1/0.79941) | L56: =(([3]Consolidated!L56)*1000)*(1/0.79941) | M56: =(([3]Consolidated!M56)*1000)*(1/0.79941) | N56: =(([3]Consolidated!N56)*1000)*(1/0.79941)
C57: Hardware expenses | D57: =(([3]Consolidated!D57)*1000)*(1/0.79941) | E57: =(([3]Consolidated!E57)*1000)*(1/0.79941) | F57: =(([3]Consolidated!F57)*1000)*(1/0.79941) | G57: =(([3]Consolidated!G57)*1000)*(1/0.79941) | H57: =(([3]Consolidated!H57)*1000)*(1/0.79941) | I57: =(([3]Consolidated!I57)*1000)*(1/0.79941) | J57: =(([3]Consolidated!J57)*1000)*(1/0.79941) | L57: =(([3]Consolidated!L57)*1000)*(1/0.79941) | M57: =(([3]Consolidated!M57)*1000)*(1/0.79941) | N57: =(([3]Consolidated!N57)*1000)*(1/0.79941)
...

Sheet Spain
C1: Spain (ES)
C2: TOTAL COSTS (US$ excl. VAT) | D2: =[4]Consolidated!D2 | E2: =[4]Consolidated!E2 | F2: =[4]Consolidated!F2 | G2: =[4]Consolidated!G2 | H2: =[4]Consolidated!H2 | I2: =[4]Consolidated!I2 | J2: =[4]Consolidated!J2 | L2: =[4]Consolidated!L2 | M2: =[4]Consolidated!M2 | N2: =[4]Consolidated!N2
C3: Internal FTE | D3: =[4]Consolidated!D3 | E3: =[4]Consolidated!E3 | F3: =[4]Consolidated!F3 | G3: =[4]Consolidated!G3 | H3: =[4]Consolidated!H3 | I3: =[4]Consolidated!I3 | L3: =[4]Consolidated!L3 | M3: =[4]Consolidated!M3 | N3: =[4]Consolidated!N3
C4: External FTE | D4: =[4]Consolidated!D4 | E4: =[4]Consolidated!E4 | F4: =[4]Consolidated!F4 | G4: =[4]Consolidated!G4 | H4: =[4]Consolidated!H4 | I4: =[4]Consolidated!I4 | L4: =[4]Consolidated!L4 | M4: =[4]Consolidated!M4 | N4: =[4]Consolidated!N4
C5: Total FTE | D5: =[4]Consolidated!D5 | E5: =[4]Consolidated!E5 | F5: =[4]Consolidated!F5 | G5: =[4]Consolidated!G5 | H5: =[4]Consolidated!H5 | I5: =[4]Consolidated!I5 | L5: =[4]Consolidated!L5 | M5: =[4]Consolidated!M5 | N5: =[4]Consolidated!N5
C7: Salaries | D7: =([4]Consolidated!D7)*(1/0.79941) | E7: =([4]Consolidated!E7)*(1/0.79941) | F7: =([4]Consolidated!F7)*(1/0.79941) | G7: =([4]Consolidated!G7)*(1/0.79941) | H7: =([4]Consolidated!H7)*(1/0.79941) | I7: =([4]Consolidated!I7)*(1/0.79941) | J7: =([4]Consolidated!J7)*(1/0.79941) | L7: =([4]Consolidated!L7)*(1/0.79941) | M7: =([4]Consolidated!M7)*(1/0.79941) | N7: =([4]Consolidated!N7)*(1/0.79941) | P7: 1000
C8: Bonuses | D8: =([4]Consolidated!D8)*(1/0.79941) | E8: =([4]Consolidated!E8)*(1/0.79941) | F8: =([4]Consolidated!F8)*(1/0.79941) | G8: =([4]Consolidated!G8)*(1/0.79941) | H8: =([4]Consolidated!H8)*(1/0.79941) | I8: =([4]Consolidated!I8)*(1/0.79941) | J8: =([4]Consolidated!J8)*(1/0.79941) | L8: =([4]Consolidated!L8)*(1/0.79941) | M8: =([4]Consolidated!M8)*(1/0.79941) | N8: =([4]Consolidated!N8)*(1/0.79941) | P8: =1/0.79941 | Q8: Euro to Dollar Rate
C9: Third party staff, ex IT | D9: =([4]Consolidated!D9)*(1/0.79941) | E9: =([4]Consolidated!E9)*(1/0.79941) | F9: =([4]Consolidated!F9)*(1/0.79941) | G9: =([4]Consolidated!G9)*(1/0.79941) | H9: =([4]Consolidated!H9)*(1/0.79941) | I9: =([4]Consolidated!I9)*(1/0.79941) | J9: =([4]Consolidated!J9)*(1/0.79941) | L9: =([4]Consolidated!L9)*(1/0.79941) | M9: =([4]Consolidated!M9)*(1/0.79941) | N9: =([4]Consolidated!N9)*(1/0.79941)
C10: Third party IT staff | D10: =([4]Consolidated!D10)*(1/0.79941) | E10: =([4]Consolidated!E10)*(1/0.79941) | F10: =([4]Consolidated!F10)*(1/0.79941) | G10: =([4]Consolidated!G10)*(1/0.79941) | H10: =([4]Consolidated!H10)*(1/0.79941) | I10: =([4]Consolidated!I10)*(1/0.79941) | J10: =([4]Consolidated!J10)*(1/0.79941) | L10: =([4]Consolidated!L10)*(1/0.79941) | M10: =([4]Consolidated!M10)*(1/0.79941) | N10: =([4]Consolidated!N10)*(1/0.79941)
C11: Employee education | D11: =([4]Consolidated!D11)*(1/0.79941) | E11: =([4]Consolidated!E11)*(1/0.79941) | F11: =([4]Consolidated!F11)*(1/0.79941) | G11: =([4]Consolidated!G11)*(1/0.79941) | H11: =([4]Consolidated!H11)*(1/0.79941) | I11: =([4]Consolidated!I11)*(1/0.79941) | J11: =([4]Consolidated!J11)*(1/0.79941) | L11: =([4]Consolidated!L11)*(1/0.79941) | M11: =([4]Consolidated!M11)*(1/0.79941) | N11: =([4]Consolidated!N11)*(1/0.79941)
C12: Other staff expenses | D12: =([4]Consolidated!D12)*(1/0.79941) | E12: =([4]Consolidated!E12)*(1/0.79941) | F12: =([4]Consolidated!F12)*(1/0.79941) | G12: =([4]Consolidated!G12)*(1/0.79941) | H12: =([4]Consolidated!H12)*(1/0.79941) | I12: =([4]Consolidated!I12)*(1/0.79941) | J12: =([4]Consolidated!J12)*(1/0.79941) | L12: =([4]Consolidated!L12)*(1/0.79941) | M12: =([4]Consolidated!M12)*(1/0.79941) | N12: =([4]Consolidated!N12)*(1/0.79941)
C13: Staff expenses | D13: =([4]Consolidated!D13)*(1/0.79941) | E13: =([4]Consolidated!E13)*(1/0.79941) | F13: =([4]Consolidated!F13)*(1/0.79941) | G13: =([4]Consolidated!G13)*(1/0.79941) | H13: =([4]Consolidated!H13)*(1/0.79941) | I13: =([4]Consolidated!I13)*(1/0.79941) | J13: =([4]Consolidated!J13)*(1/0.79941) | L13: =([4]Consolidated!L13)*(1/0.79941) | M13: =([4]Consolidated!M13)*(1/0.79941) | N13: =([4]Consolidated!N13)*(1/0.79941)
