Workbook

Sheet Cover Page
B2: GlobalPharma AG
B5: ATTACHMENT 4-A
B7: SERVICE PROVIDER PRICING FORMS
B8: Attachment to Exhibit 4 (Pricing and Financial Provisions)
B15: This document contains confidential and proprietary information of GlobalPharma AG. It is furnished for the performance of The Agreements only. Except with the express prior written permission of GlobalPharma AG, this document and the information contained herein may not be published, disclosed, or used for any other purpose.

Sheet Summary Charges
A1: SUMMARY CHARGES (US$)
B3: Category of Services
A4: BASE CHARGES | C4: Year 1 | D4: Year 2 | E4: Year 3 | F4: Year 4 | G4: Year 5 | H4: Year 6 | I4: Year 7 | J4: Year 8 | K4: Total
B5: General Accounting & Sox | C5: ='Consolidated Base Charges'!C37 | D5: ='Consolidated Base Charges'!D37 | E5: ='Consolidated Base Charges'!E37 | F5: ='Consolidated Base Charges'!F37 | G5: ='Consolidated Base Charges'!G37 | H5: ='Consolidated Base Charges'!H37 | I5: ='Consolidated Base Charges'!I37 | J5: ='Consolidated Base Charges'!J37 | K5: =SUM(C5:J5)
B7: Fixed Assets | C7: ='Consolidated Base Charges'!C41 | D7: ='Consolidated Base Charges'!D41 | E7: ='Consolidated Base Charges'!E41 | F7: ='Consolidated Base Charges'!F41 | G7: ='Consolidated Base Charges'!G41 | H7: ='Consolidated Base Charges'!H41 | I7: ='Consolidated Base Charges'!I41 | J7: ='Consolidated Base Charges'!J41 | K7: =SUM(C7:J7)
B9: Accounts Payable | C9: ='Consolidated Base Charges'!C45 | D9: ='Consolidated Base Charges'!D45 | E9: ='Consolidated Base Charges'!E45 | F9: ='Consolidated Base Charges'!F45 | G9: ='Consolidated Base Charges'!G45 | H9: ='Consolidated Base Charges'!H45 | I9: ='Consolidated Base Charges'!I45 | J9: ='Consolidated Base Charges'!J45 | K9: =SUM(C9:J9)
B11: T&E | C11: ='Consolidated Base Charges'!C49 | D11: ='Consolidated Base Charges'!D49 | E11: ='Consolidated Base Charges'!E49 | F11: ='Consolidated Base Charges'!F49 | G11: ='Consolidated Base Charges'!G49 | H11: ='Consolidated Base Charges'!H49 | I11: ='Consolidated Base Charges'!I49 | J11: ='Consolidated Base Charges'!J49 | K11: =SUM(C11:J11)
B13: Order to Cash | C13: ='Consolidated Base Charges'!C53 | D13: ='Consolidated Base Charges'!D53 | E13: ='Consolidated Base Charges'!E53 | F13: ='Consolidated Base Charges'!F53 | G13: ='Consolidated Base Charges'!G53 | H13: ='Consolidated Base Charges'!H53 | I13: ='Consolidated Base Charges'!I53 | J13: ='Consolidated Base Charges'!J53 | K13: =SUM(C13:J13)
B15: Requistion to Pay | C15: ='Consolidated Base Charges'!C57 | D15: ='Consolidated Base Charges'!D57 | E15: ='Consolidated Base Charges'!E57 | F15: ='Consolidated Base Charges'!F57 | G15: ='Consolidated Base Charges'!G57 | H15: ='Consolidated Base Charges'!H57 | I15: ='Consolidated Base Charges'!I57 | J15: ='Consolidated Base Charges'!J57 | K15: =SUM(C15:J15)
A17: TOTAL BASE CHARGES | C17: =SUM(C5:C16) | D17: =SUM(D5:D16) | E17: =SUM(E5:E16) | F17: =SUM(F5:F16) | G17: =SUM(G5:G16) | H17: =SUM(H5:H16) | I17: =SUM(I5:I16) | J17: =SUM(J5:J16) | K17: =SUM(K5:K16)
A19: TRANSITION CHARGES | C19: Year 1 | D19: Year 2 | E19: Year 3 | F19: Year 4 | G19: Year 5 | H19: Year 6 | I19: Year 7 | J19: Year 8 | K19: Total
B20: General Accounting & Sox | C20: ='Transition Charges'!F13 | D20: ='Transition Charges'!K13 | E20: ='Transition Charges'!L13 | F20: ='Transition Charges'!M13 | G20: ='Transition Charges'!N13 | H20: ='Transition Charges'!O13 | I20: ='Transition Charges'!P13 | K20: =SUM(C20:J20)
B22: Fixed Assets | C22: ='Transition Charges'!F24 | D22: ='Transition Charges'!K24 | E22: ='Transition Charges'!L24 | F22: ='Transition Charges'!M24 | G22: ='Transition Charges'!N24 | H22: ='Transition Charges'!O24 | I22: ='Transition Charges'!P24 | K22: =SUM(C22:J22)
B24: Accounts Payable | C24: ='Transition Charges'!F35 | D24: ='Transition Charges'!K35 | E24: ='Transition Charges'!L35 | F24: ='Transition Charges'!M35 | G24: ='Transition Charges'!N35 | H24: ='Transition Charges'!O35 | I24: ='Transition Charges'!P35 | K24: =SUM(C24:J24)
B26: T&E | C26: ='Transition Charges'!F46 | D26: ='Transition Charges'!K46 | E26: ='Transition Charges'!L46 | F26: ='Transition Charges'!M46 | G26: ='Transition Charges'!N46 | H26: ='Transition Charges'!O46 | I26: ='Transition Charges'!P46 | K26: =SUM(C26:J26)
B28: Order to Cash | C28: ='Transition Charges'!F57 | D28: ='Transition Charges'!K57 | E28: ='Transition Charges'!L57 | F28: ='Transition Charges'!M57 | G28: ='Transition Charges'!N57 | H28: ='Transition Charges'!O57 | I28: ='Transition Charges'!P57 | K28: =SUM(C28:J28)
B30: Requistion to Pay | C30: ='Transition Charges'!F68 | D30: ='Transition Charges'!K68 | E30: ='Transition Charges'!L68 | F30: ='Transition Charges'!M68 | G30: ='Transition Charges'!N68 | H30: ='Transition Charges'!O68 | I30: ='Transition Charges'!P68 | K30: =SUM(C30:J30)
A32: TOTAL TRANSITION CHARGES | C32: =SUM(C20:C31) | D32: =SUM(D20:D31) | E32: =SUM(E20:E31) | F32: =SUM(F20:F31) | G32: =SUM(G20:G31) | H32: =SUM(H20:H31) | I32: =SUM(I20:I31) | J32: =SUM(J20:J31) | K32: =SUM(K20:K31)
A34: TRANSFORMATION CHARGES | C34: Year 1 | D34: Year 2 | E34: Year 3 | F34: Year 4 | G34: Year 5 | H34: Year 6 | I34: Year 7 | J34: Year 8 | K34: Total
B35: General Accounting & Sox | K35: =SUM(C35:J35)
B37: Fixed Assets | K37: =SUM(C37:J37)
B39: Accounts Payable | K39: =SUM(C39:J39)
B41: T&E | K41: =SUM(C41:J41)
B43: Order to Cash | K43: =SUM(C43:J43)
B45: Requistion to Pay | K45: =SUM(C45:J45)
A47: TOTAL TRANSFORMATION CHARGES | C47: =SUM(C35:C46) | D47: =SUM(D35:D46) | E47: =SUM(E35:E46) | F47: =SUM(F35:F46) | G47: =SUM(G35:G46) | H47: =SUM(H35:H46) | I47: =SUM(I35:I46) | J47: =SUM(J35:J46) | K47: =SUM(K35:K46)
A49: TOTAL SUPPLIER CHARGES | C49: =C47+C32+C17 | D49: =D47+D32+D17 | E49: =E47+E32+E17 | F49: =F47+F32+F17 | G49: =G47+G32+G17 | H49: =H47+H32+H17 | I49: =I47+I32+I17 | J49: =J47+J32+J17 | K49: =K47+K32+K17
A51: PASS THROUGH CHARGES | C51: Year 1 | D51: Year 2 | E51: Year 3 | F51: Year 4 | G51: Year 5 | H51: Year 6 | I51: Year 7 | J51: Year 8 | K51: Total
B52: General Accounting & Sox | C52: ='Pass-Thro-Charges'!C5 | D52: ='Pass-Thro-Charges'!D5 | E52: ='Pass-Thro-Charges'!E5 | F52: ='Pass-Thro-Charges'!F5 | G52: ='Pass-Thro-Charges'!G5 | H52: ='Pass-Thro-Charges'!H5 | I52: ='Pass-Thro-Charges'!I5 | J52: ='Pass-Thro-Charges'!J5 | K52: =SUM(C52:J52)
B54: Fixed Assets | C54: ='Pass-Thro-Charges'!C7 | D54: ='Pass-Thro-Charges'!D7 | E54: ='Pass-Thro-Charges'!E7 | F54: ='Pass-Thro-Charges'!F7 | G54: ='Pass-Thro-Charges'!G7 | H54: ='Pass-Thro-Charges'!H7 | I54: ='Pass-Thro-Charges'!I7 | J54: ='Pass-Thro-Charges'!J7 | K54: =SUM(C54:J54)
B56: Accounts Payable | C56: ='Pass-Thro-Charges'!C9 | D56: ='Pass-Thro-Charges'!D9 | E56: ='Pass-Thro-Charges'!E9 | F56: ='Pass-Thro-Charges'!F9 | G56: ='Pass-Thro-Charges'!G9 | H56: ='Pass-Thro-Charges'!H9 | I56: ='Pass-Thro-Charges'!I9 | J56: ='Pass-Thro-Charges'!J9 | K56: =SUM(C56:J56)
B58: T&E | C58: ='Pass-Thro-Charges'!C11 | D58: ='Pass-Thro-Charges'!D11 | E58: ='Pass-Thro-Charges'!E11 | F58: ='Pass-Thro-Charges'!F11 | G58: ='Pass-Thro-Charges'!G11 | H58: ='Pass-Thro-Charges'!H11 | I58: ='Pass-Thro-Charges'!I11 | J58: ='Pass-Thro-Charges'!J11 | K58: =SUM(C58:J58)
B60: Order to Cash | C60: ='Pass-Thro-Charges'!C13 | D60: ='Pass-Thro-Charges'!D13 | E60: ='Pass-Thro-Charges'!E13 | F60: ='Pass-Thro-Charges'!F13 | G60: ='Pass-Thro-Charges'!G13 | H60: ='Pass-Thro-Charges'!H13 | I60: ='Pass-Thro-Charges'!I13 | J60: ='Pass-Thro-Charges'!J13 | K60: =SUM(C60:J60)
B62: Requistion to Pay | C62: ='Pass-Thro-Charges'!C15 | D62: ='Pass-Thro-Charges'!D15 | E62: ='Pass-Thro-Charges'!E15 | F62: ='Pass-Thro-Charges'!F15 | G62: ='Pass-Thro-Charges'!G15 | H62: ='Pass-Thro-Charges'!H15 | I62: ='Pass-Thro-Charges'!I15 | J62: ='Pass-Thro-Charges'!J15 | K62: =SUM(C62:J62)
A64: TOTAL PASS THROUGH | C64: =SUM(C52:C63) | D64: =SUM(D52:D63) | E64: =SUM(E52:E63) | F64: =SUM(F52:F63) | G64: =SUM(G52:G63) | H64: =SUM(H52:H63) | I64: =SUM(I52:I63) | J64: =SUM(J52:J63) | K64: =SUM(K52:K63)
A66: GRAND TOTAL CHARGES | C66: =SUM(C64,C49) | D66: =SUM(D64,D49) | E66: =SUM(E64,E49) | F66: =SUM(F64,F49) | G66: =SUM(G64,G49) | H66: =SUM(H64,H49) | I66: =SUM(I64,I49) | J66: =SUM(J64,J49) | K66: =SUM(K64,K49)
A68: Walk from Nov 21 submission to Jan 17 Submission
A69: Submission as of Nov 21, 2006 | C69: 6423126 | D69: 6050465.6 | E69: 5673577.3 | F69: 5523567.4 | G69: 5467632 | H69: 5289616 | I69: 5192511.4 | J69: 432093.45 | K69: =SUM(C69:J69)
A70: Including Cognos reporting tool and customer portal | C70: 20604.101 | D70: 39473.472 | E70: 37285.654 | F70: 36230.246 | G70: 35568.224 | H70: 34642.202 | I70: 33969.258 | J70: 2826.2749 | K70: =SUM(C70:J70)
A71: Change in workflow solutions | C71: -63615.534 | D71: -157139.73 | E71: -149105.09 | F71: -143393.51 | G71: -143581.23 | H71: -137851.43 | I71: -131535.83 | J71: -10917.461 | K71: =SUM(C71:J71)
...

Sheet Consolidated Base Charges
A1: CONSOLIDATED BASE CHARGE SUMMARY (US$)
A2: Consolidated | C2: Year 1 | D2: Year 2 | E2: Year 3 | F2: Year 4 | G2: Year 5 | H2: Year 6 | I2: Year 7 | J2: Year 8
B3: Consolidated Summary
B4: Switzerland | C4: =C14+C24 | D4: =D14+D24 | E4: =E14+E24 | F4: =F14+F24 | G4: =G14+G24 | H4: =H14+H24 | I4: =I14+I24 | J4: =J14+J24
B5: United States | C5: =C15+C25 | D5: =D15+D25 | E5: =E15+E25 | F5: =F15+F25 | G5: =G15+G25 | H5: =H15+H25 | I5: =I15+I25 | J5: =J15+J25
B6: France | C6: =C16+C26 | D6: =D16+D26 | E6: =E16+E26 | F6: =F16+F26 | G6: =G16+G26 | H6: =H16+H26 | I6: =I16+I26 | J6: =J16+J26
B7: Germany | C7: =C17+C27 | D7: =D17+D27 | E7: =E17+E27 | F7: =F17+F27 | G7: =G17+G27 | H7: =H17+H27 | I7: =I17+I27 | J7: =J17+J27
B8: Germany Production | C8: =C18+C28 | D8: =D18+D28 | E8: =E18+E28 | F8: =F18+F28 | G8: =G18+G28 | H8: =H18+H28 | I8: =I18+I28 | J8: =J18+J28
B9: Spain | C9: =C19+C29 | D9: =D19+D29 | E9: =E19+E29 | F9: =F19+F29 | G9: =G19+G29 | H9: =H19+H29 | I9: =I19+I29 | J9: =J19+J29
B10: Italy | C10: =C20+C30 | D10: =D20+D30 | E10: =E20+E30 | F10: =F20+F30 | G10: =G20+G30 | H10: =H20+H30 | I10: =I20+I30 | J10: =J20+J30
B11: United Kingdom | C11: =C21+C31 | D11: =D21+D31 | E11: =E21+E31 | F11: =F21+F31 | G11: =G21+G31 | H11: =H21+H31 | I11: =I21+I31 | J11: =J21+J31
B12: Total Base Charges All Countries | C12: =SUM(C4:C11) | D12: =SUM(D4:D11) | E12: =SUM(E4:E11) | F12: =SUM(F4:F11) | G12: =SUM(G4:G11) | H12: =SUM(H4:H11) | I12: =SUM(I4:I11) | J12: =SUM(J4:J11)
B13: Centre One Summary
B14: Switzerland | C14: =+'Centre One-BC'!C73 | D14: =+'Centre One-BC'!D73 | E14: =+'Centre One-BC'!E73 | F14: =+'Centre One-BC'!F73 | G14: =+'Centre One-BC'!G73 | H14: =+'Centre One-BC'!H73 | I14: =+'Centre One-BC'!I73 | J14: =+'Centre One-BC'!J73
B15: United States | C15: =+'Centre One-BC'!C74 | D15: =+'Centre One-BC'!D74 | E15: =+'Centre One-BC'!E74 | F15: =+'Centre One-BC'!F74 | G15: =+'Centre One-BC'!G74 | H15: =+'Centre One-BC'!H74 | I15: =+'Centre One-BC'!I74 | J15: =+'Centre One-BC'!J74
B16: France | C16: =+'Centre One-BC'!C75 | D16: =+'Centre One-BC'!D75 | E16: =+'Centre One-BC'!E75 | F16: =+'Centre One-BC'!F75 | G16: =+'Centre One-BC'!G75 | H16: =+'Centre One-BC'!H75 | I16: =+'Centre One-BC'!I75 | J16: =+'Centre One-BC'!J75
B17: Germany | C17: =+'Centre One-BC'!C76 | D17: =+'Centre One-BC'!D76 | E17: =+'Centre One-BC'!E76 | F17: =+'Centre One-BC'!F76 | G17: =+'Centre One-BC'!G76 | H17: =+'Centre One-BC'!H76 | I17: =+'Centre One-BC'!I76 | J17: =+'Centre One-BC'!J76
B18: Germany Production | C18: =+'Centre One-BC'!C77 | D18: =+'Centre One-BC'!D77 | E18: =+'Centre One-BC'!E77 | F18: =+'Centre One-BC'!F77 | G18: =+'Centre One-BC'!G77 | H18: =+'Centre One-BC'!H77 | I18: =+'Centre One-BC'!I77 | J18: =+'Centre One-BC'!J77
B19: Spain | C19: =+'Centre One-BC'!C78 | D19: =+'Centre One-BC'!D78 | E19: =+'Centre One-BC'!E78 | F19: =+'Centre One-BC'!F78 | G19: =+'Centre One-BC'!G78 | H19: =+'Centre One-BC'!H78 | I19: =+'Centre One-BC'!I78 | J19: =+'Centre One-BC'!J78
B20: Italy | C20: =+'Centre One-BC'!C79 | D20: =+'Centre One-BC'!D79 | E20: =+'Centre One-BC'!E79 | F20: =+'Centre One-BC'!F79 | G20: =+'Centre One-BC'!G79 | H20: =+'Centre One-BC'!H79 | I20: =+'Centre One-BC'!I79 | J20: =+'Centre One-BC'!J79
B21: United Kingdom | C21: =+'Centre One-BC'!C80 | D21: =+'Centre One-BC'!D80 | E21: =+'Centre One-BC'!E80 | F21: =+'Centre One-BC'!F80 | G21: =+'Centre One-BC'!G80 | H21: =+'Centre One-BC'!H80 | I21: =+'Centre One-BC'!I80 | J21: =+'Centre One-BC'!J80
B22: Total Base Charges - Centre One | C22: =SUM(C14:C21) | D22: =SUM(D14:D21) | E22: =SUM(E14:E21) | F22: =SUM(F14:F21) | G22: =SUM(G14:G21) | H22: =SUM(H14:H21) | I22: =SUM(I14:I21) | J22: =SUM(J14:J21)
B23: Centre Two Summary
B24: Switzerland | C24: =+'Centre Two-BC'!C73 | D24: =+'Centre Two-BC'!D73 | E24: =+'Centre Two-BC'!E73 | F24: =+'Centre Two-BC'!F73 | G24: =+'Centre Two-BC'!G73 | H24: =+'Centre Two-BC'!H73 | I24: =+'Centre Two-BC'!I73 | J24: =+'Centre Two-BC'!J73
B25: United States | C25: =+'Centre Two-BC'!C74 | D25: =+'Centre Two-BC'!D74 | E25: =+'Centre Two-BC'!E74 | F25: =+'Centre Two-BC'!F74 | G25: =+'Centre Two-BC'!G74 | H25: =+'Centre Two-BC'!H74 | I25: =+'Centre Two-BC'!I74 | J25: =+'Centre Two-BC'!J74
B26: France | C26: =+'Centre Two-BC'!C75 | D26: =+'Centre Two-BC'!D75 | E26: =+'Centre Two-BC'!E75 | F26: =+'Centre Two-BC'!F75 | G26: =+'Centre Two-BC'!G75 | H26: =+'Centre Two-BC'!H75 | I26: =+'Centre Two-BC'!I75 | J26: =+'Centre Two-BC'!J75
B27: Germany | C27: =+'Centre Two-BC'!C76 | D27: =+'Centre Two-BC'!D76 | E27: =+'Centre Two-BC'!E76 | F27: =+'Centre Two-BC'!F76 | G27: =+'Centre Two-BC'!G76 | H27: =+'Centre Two-BC'!H76 | I27: =+'Centre Two-BC'!I76 | J27: =+'Centre Two-BC'!J76
B28: Germany Production | C28: =+'Centre Two-BC'!C77 | D28: =+'Centre Two-BC'!D77 | E28: =+'Centre Two-BC'!E77 | F28: =+'Centre Two-BC'!F77 | G28: =+'Centre Two-BC'!G77 | H28: =+'Centre Two-BC'!H77 | I28: =+'Centre Two-BC'!I77 | J28: =+'Centre Two-BC'!J77
B29: Spain | C29: =+'Centre Two-BC'!C78 | D29: =+'Centre Two-BC'!D78 | E29: =+'Centre Two-BC'!E78 | F29: =+'Centre Two-BC'!F78 | G29: =+'Centre Two-BC'!G78 | H29: =+'Centre Two-BC'!H78 | I29: =+'Centre Two-BC'!I78 | J29: =+'Centre Two-BC'!J78
B30: Italy | C30: =+'Centre Two-BC'!C79 | D30: =+'Centre Two-BC'!D79 | E30: =+'Centre Two-BC'!E79 | F30: =+'Centre Two-BC'!F79 | G30: =+'Centre Two-BC'!G79 | H30: =+'Centre Two-BC'!H79 | I30: =+'Centre Two-BC'!I79 | J30: =+'Centre Two-BC'!J79
B31: United Kingdom | C31: =+'Centre Two-BC'!C80 | D31: =+'Centre Two-BC'!D80 | E31: =+'Centre Two-BC'!E80 | F31: =+'Centre Two-BC'!F80 | G31: =+'Centre Two-BC'!G80 | H31: =+'Centre Two-BC'!H80 | I31: =+'Centre Two-BC'!I80 | J31: =+'Centre Two-BC'!J80
B32: Total Base Charges - Centre Two | C32: =SUM(C24:C31) | D32: =SUM(D24:D31) | E32: =SUM(E24:E31) | F32: =SUM(F24:F31) | G32: =SUM(G24:G31) | H32: =SUM(H24:H31) | I32: =SUM(I24:I31) | J32: =SUM(J24:J31)
B33: Process Summary
B34: General Accounting & Sox
B35: Centre One | C35: ='Centre One-BC'!$C$20 | D35: ='Centre One-BC'!$D$20 | E35: ='Centre One-BC'!$E$20 | F35: ='Centre One-BC'!$F$20 | G35: ='Centre One-BC'!$G$20 | H35: ='Centre One-BC'!$H$20 | I35: ='Centre One-BC'!$I$20 | J35: ='Centre One-BC'!$J$20
B36: Centre Two | C36: ='Centre Two-BC'!$C$20 | D36: ='Centre Two-BC'!$D$20 | E36: ='Centre Two-BC'!$E$20 | F36: ='Centre Two-BC'!$F$20 | G36: ='Centre Two-BC'!$G$20 | H36: ='Centre Two-BC'!$H$20 | I36: ='Centre Two-BC'!$I$20 | J36: ='Centre Two-BC'!$J$20
B37: Sub Total | C37: =SUM(C35:C36) | D37: =SUM(D35:D36) | E37: =SUM(E35:E36) | F37: =SUM(F35:F36) | G37: =SUM(G35:G36) | H37: =SUM(H35:H36) | I37: =SUM(I35:I36) | J37: =SUM(J35:J36)
B38: Fixed Assets
B39: Centre One | C39: ='Centre One-BC'!$C$30 | D39: ='Centre One-BC'!$D$30 | E39: ='Centre One-BC'!$E$30 | F39: ='Centre One-BC'!$F$30 | G39: ='Centre One-BC'!$G$30 | H39: ='Centre One-BC'!$H$30 | I39: ='Centre One-BC'!$I$30 | J39: ='Centre One-BC'!$J$30
B40: Centre Two | C40: ='Centre Two-BC'!$C$30 | D40: ='Centre Two-BC'!$D$30 | E40: ='Centre Two-BC'!$E$30 | F40: ='Centre Two-BC'!$F$30 | G40: ='Centre Two-BC'!$G$30 | H40: ='Centre Two-BC'!$H$30 | I40: ='Centre Two-BC'!$I$30 | J40: ='Centre Two-BC'!$J$30
...

Sheet Pass-Thro-Charges
A1: PASS THROUGH CHARGES (US$)
B3: Category of Service | C3: Year 1 | D3: Year 2 | E3: Year 3 | F3: Year 4 | G3: Year 5 | H3: Year 6 | I3: Year 7 | J3: Year 8 | K3: Total
B5: General Accounting & Sox | C5: =SUM(C23,C41,C59,C77,C95) | D5: =SUM(D23,D41,D59,D77,D95) | E5: =SUM(E23,E41,E59,E77,E95) | F5: =SUM(F23,F41,F59,F77,F95) | G5: =SUM(G23,G41,G59,G77,G95) | H5: =SUM(H23,H41,H59,H77,H95) | I5: =SUM(I23,I41,I59,I77,I95) | J5: =SUM(J23,J41,J59,J77,J95) | K5: =SUM(C5:J5)
B7: Fixed Assets | C7: =SUM(C25,C43,C61,C79,C97) | D7: =SUM(D25,D43,D61,D79,D97) | E7: =SUM(E25,E43,E61,E79,E97) | F7: =SUM(F25,F43,F61,F79,F97) | G7: =SUM(G25,G43,G61,G79,G97) | H7: =SUM(H25,H43,H61,H79,H97) | I7: =SUM(I25,I43,I61,I79,I97) | J7: =SUM(J25,J43,J61,J79,J97) | K7: =SUM(C7:J7)
B9: Accounts Payable | C9: =SUM(C27,C45,C63,C81,C99) | D9: =SUM(D27,D45,D63,D81,D99) | E9: =SUM(E27,E45,E63,E81,E99) | F9: =SUM(F27,F45,F63,F81,F99) | G9: =SUM(G27,G45,G63,G81,G99) | H9: =SUM(H27,H45,H63,H81,H99) | I9: =SUM(I27,I45,I63,I81,I99) | J9: =SUM(J27,J45,J63,J81,J99) | K9: =SUM(C9:J9)
B11: T&E | C11: =SUM(C29,C47,C65,C83,C101) | D11: =SUM(D29,D47,D65,D83,D101) | E11: =SUM(E29,E47,E65,E83,E101) | F11: =SUM(F29,F47,F65,F83,F101) | G11: =SUM(G29,G47,G65,G83,G101) | H11: =SUM(H29,H47,H65,H83,H101) | I11: =SUM(I29,I47,I65,I83,I101) | J11: =SUM(J29,J47,J65,J83,J101) | K11: =SUM(C11:J11)
B13: Order to Cash | C13: =SUM(C31,C49,C67,C85,C103) | D13: =SUM(D31,D49,D67,D85,D103) | E13: =SUM(E31,E49,E67,E85,E103) | F13: =SUM(F31,F49,F67,F85,F103) | G13: =SUM(G31,G49,G67,G85,G103) | H13: =SUM(H31,H49,H67,H85,H103) | I13: =SUM(I31,I49,I67,I85,I103) | J13: =SUM(J31,J49,J67,J85,J103) | K13: =SUM(C13:J13)
B15: Requistion to Pay | C15: =SUM(C33,C51,C69,C87,C105) | D15: =SUM(D33,D51,D69,D87,D105) | E15: =SUM(E33,E51,E69,E87,E105) | F15: =SUM(F33,F51,F69,F87,F105) | G15: =SUM(G33,G51,G69,G87,G105) | H15: =SUM(H33,H51,H69,H87,H105) | I15: =SUM(I33,I51,I69,I87,I105) | J15: =SUM(J33,J51,J69,J87,J105) | K15: =SUM(C15:J15)
A17: TOTAL INVESTMENTS | C17: =SUM(C4:C16) | D17: =SUM(D4:D16) | E17: =SUM(E4:E16) | F17: =SUM(F4:F16) | G17: =SUM(G4:G16) | H17: =SUM(H4:H16) | I17: =SUM(I4:I16) | J17: =SUM(J4:J16) | K17: =SUM(K4:K16)
A20: Pass through -PSTN
B21: Category of Service | C21: Year 1 | D21: Year 2 | E21: Year 3 | F21: Year 4 | G21: Year 5 | H21: Year 6 | I21: Year 7 | J21: Year 8 | K21: Total
B23: General Accounting & Sox | C23: ='Pass-Thro-Charges'!$F174*'Consolidated FTE '!C37 | D23: ='Pass-Thro-Charges'!$F174*'Consolidated FTE '!D37 | E23: ='Pass-Thro-Charges'!$F174*'Consolidated FTE '!E37 | F23: ='Pass-Thro-Charges'!$F174*'Consolidated FTE '!F37 | G23: ='Pass-Thro-Charges'!$F174*'Consolidated FTE '!G37 | H23: ='Pass-Thro-Charges'!$F174*'Consolidated FTE '!H37 | I23: ='Pass-Thro-Charges'!$F174*'Consolidated FTE '!I37 | J23: ='Pass-Thro-Charges'!$F174*'Consolidated FTE '!J37/12 | K23: =SUM(C23:J23)
B25: Fixed Assets | C25: ='Pass-Thro-Charges'!$F176*'Consolidated FTE '!C41 | D25: ='Pass-Thro-Charges'!$F176*'Consolidated FTE '!D41 | E25: ='Pass-Thro-Charges'!$F176*'Consolidated FTE '!E41 | F25: ='Pass-Thro-Charges'!$F176*'Consolidated FTE '!F41 | G25: ='Pass-Thro-Charges'!$F176*'Consolidated FTE '!G41 | H25: ='Pass-Thro-Charges'!$F176*'Consolidated FTE '!H41 | I25: ='Pass-Thro-Charges'!$F176*'Consolidated FTE '!I41 | J25: ='Pass-Thro-Charges'!$F176*'Consolidated FTE '!J41/12 | K25: =SUM(C25:J25)
B27: Accounts Payable | C27: ='Pass-Thro-Charges'!$F178*'Consolidated FTE '!C45 | D27: ='Pass-Thro-Charges'!$F178*'Consolidated FTE '!D45 | E27: ='Pass-Thro-Charges'!$F178*'Consolidated FTE '!E45 | F27: ='Pass-Thro-Charges'!$F178*'Consolidated FTE '!F45 | G27: ='Pass-Thro-Charges'!$F178*'Consolidated FTE '!G45 | H27: ='Pass-Thro-Charges'!$F178*'Consolidated FTE '!H45 | I27: ='Pass-Thro-Charges'!$F178*'Consolidated FTE '!I45 | J27: ='Pass-Thro-Charges'!$F178*'Consolidated FTE '!J45/12 | K27: =SUM(C27:J27)
B29: T&E | C29: ='Pass-Thro-Charges'!$F180*'Consolidated FTE '!C49 | D29: ='Pass-Thro-Charges'!$F180*'Consolidated FTE '!D49 | E29: ='Pass-Thro-Charges'!$F180*'Consolidated FTE '!E49 | F29: ='Pass-Thro-Charges'!$F180*'Consolidated FTE '!F49 | G29: ='Pass-Thro-Charges'!$F180*'Consolidated FTE '!G49 | H29: ='Pass-Thro-Charges'!$F180*'Consolidated FTE '!H49 | I29: ='Pass-Thro-Charges'!$F180*'Consolidated FTE '!I49 | J29: ='Pass-Thro-Charges'!$F180*'Consolidated FTE '!J49/12 | K29: =SUM(C29:J29)
B31: Order to Cash | C31: ='Pass-Thro-Charges'!$F182*'Consolidated FTE '!C53 | D31: ='Pass-Thro-Charges'!$F182*'Consolidated FTE '!D53 | E31: ='Pass-Thro-Charges'!$F182*'Consolidated FTE '!E53 | F31: ='Pass-Thro-Charges'!$F182*'Consolidated FTE '!F53 | G31: ='Pass-Thro-Charges'!$F182*'Consolidated FTE '!G53 | H31: ='Pass-Thro-Charges'!$F182*'Consolidated FTE '!H53 | I31: ='Pass-Thro-Charges'!$F182*'Consolidated FTE '!I53 | J31: ='Pass-Thro-Charges'!$F182*'Consolidated FTE '!J53/12 | K31: =SUM(C31:J31)
B33: Requistion to Pay | C33: ='Pass-Thro-Charges'!$F184*'Consolidated FTE '!C57 | D33: ='Pass-Thro-Charges'!$F184*'Consolidated FTE '!D57 | E33: ='Pass-Thro-Charges'!$F184*'Consolidated FTE '!E57 | F33: ='Pass-Thro-Charges'!$F184*'Consolidated FTE '!F57 | G33: ='Pass-Thro-Charges'!$F184*'Consolidated FTE '!G57 | H33: ='Pass-Thro-Charges'!$F184*'Consolidated FTE '!H57 | I33: ='Pass-Thro-Charges'!$F184*'Consolidated FTE '!I57 | J33: ='Pass-Thro-Charges'!$F184*'Consolidated FTE '!J57/12 | K33: =SUM(C33:J33)
A35: TOTAL INVESTMENTS | C35: =SUM(C22:C34) | D35: =SUM(D22:D34) | E35: =SUM(E22:E34) | F35: =SUM(F22:F34) | G35: =SUM(G22:G34) | H35: =SUM(H22:H34) | I35: =SUM(I22:I34) | J35: =SUM(J22:J34) | K35: =SUM(K22:K34)
A38: Pass through -Workflow
B39: Category of Service | C39: Year 1 | D39: Year 2 | E39: Year 3 | F39: Year 4 | G39: Year 5 | H39: Year 6 | I39: Year 7 | J39: Year 8 | K39: Total
B41: General Accounting & Sox | C41: 0 | D41: 0 | E41: 0 | F41: 0 | G41: 0 | H41: 0 | I41: 0 | J41: 0 | K41: =SUM(C41:J41)
B43: Fixed Assets | C43: 0 | D43: 0 | E43: 0 | F43: 0 | G43: 0 | H43: 0 | I43: 0 | J43: 0 | K43: =SUM(C43:J43)
B45: Accounts Payable | C45: =C110 | D45: =D110 | E45: =E110 | F45: =F110 | G45: =G110 | H45: =H110 | I45: =I110 | J45: =J110 | K45: =SUM(C45:J45)
B47: T&E | C47: 0 | D47: 0 | E47: 0 | F47: 0 | G47: 0 | H47: 0 | I47: 0 | J47: 0 | K47: =SUM(C47:J47)
B49: Order to Cash | C49: 0 | D49: 0 | E49: 0 | F49: 0 | G49: 0 | H49: 0 | I49: 0 | J49: 0 | K49: =SUM(C49:J49)
B51: Requistion to Pay | C51: 0 | D51: 0 | E51: 0 | F51: 0 | G51: 0 | H51: 0 | I51: 0 | J51: 0 | K51: =SUM(C51:J51)
A53: TOTAL INVESTMENTS | C53: =SUM(C40:C52) | D53: =SUM(D40:D52) | E53: =SUM(E40:E52) | F53: =SUM(F40:F52) | G53: =SUM(G40:G52) | H53: =SUM(H40:H52) | I53: =SUM(I40:I52) | J53: =SUM(J40:J52) | K53: =SUM(K40:K52)
A56: Pass through -Scanning and Archiving
B57: Category of Service | C57: Year 1 | D57: Year 2 | E57: Year 3 | F57: Year 4 | G57: Year 5 | H57: Year 6 | I57: Year 7 | J57: Year 8 | K57: Total
B59: General Accounting & Sox | C59: 0 | D59: 0 | E59: 0 | F59: 0 | G59: 0 | H59: 0 | I59: 0 | J59: 0 | K59: =SUM(C59:J59)
B61: Fixed Assets | C61: 0 | D61: 0 | E61: 0 | F61: 0 | G61: 0 | H61: 0 | I61: 0 | J61: 0 | K61: =SUM(C61:J61)
B63: Accounts Payable | C63: =C143+C152+C126 | D63: =D143+D152 | E63: =E143+E152 | F63: =F143+F152 | G63: =G143+G152 | H63: =H143+H152 | I63: =I143+I152 | J63: =J143+J152 | K63: =SUM(C63:J63)
B65: T&E | C65: =C146 | D65: =D146 | E65: =E146 | F65: =F146 | G65: =G146 | H65: =H146 | I65: =I146 | J65: =J146 | K65: =SUM(C65:J65)
B67: Order to Cash | C67: 0 | D67: 0 | E67: 0 | F67: 0 | G67: 0 | H67: 0 | I67: 0 | J67: 0 | K67: =SUM(C67:J67)
B69: Requistion to Pay | C69: 0 | D69: 0 | E69: 0 | F69: 0 | G69: 0 | H69: 0 | I69: 0 | J69: 0 | K69: =SUM(C69:J69)
A71: TOTAL INVESTMENTS | C71: =SUM(C58:C70) | D71: =SUM(D58:D70) | E71: =SUM(E58:E70) | F71: =SUM(F58:F70) | G71: =SUM(G58:G70) | H71: =SUM(H58:H70) | I71: =SUM(I58:I70) | J71: =SUM(J58:J70) | K71: =SUM(K58:K70)
A74: Pass through -MPLS connection
B75: Category of Service | C75: Year 1 | D75: Year 2 | E75: Year 3 | F75: Year 4 | G75: Year 5 | H75: Year 6 | I75: Year 7 | J75: Year 8 | K75: Total
B77: General Accounting & Sox | C77: =$C$156*$C$158*'Centre One-FTE'!C4+'Pass-Thro-Charges'!$C$157*'Pass-Thro-Charges'!$C$158*'Centre Two-FTE'!C4 | D77: =$C$156*$C$158*'Centre One-FTE'!D4+'Pass-Thro-Charges'!$C$157*'Pass-Thro-Charges'!$C$158*'Centre Two-FTE'!D4 | E77: =$C$156*$C$158*'Centre One-FTE'!E4+'Pass-Thro-Charges'!$C$157*'Pass-Thro-Charges'!$C$158*'Centre Two-FTE'!E4 | F77: =$C$156*$C$158*'Centre One-FTE'!F4+'Pass-Thro-Charges'!$C$157*'Pass-Thro-Charges'!$C$158*'Centre Two-FTE'!F4 | G77: =$C$156*$C$158*'Centre One-FTE'!G4+'Pass-Thro-Charges'!$C$157*'Pass-Thro-Charges'!$C$158*'Centre Two-FTE'!G4 | H77: =$C$156*$C$158*'Centre One-FTE'!H4+'Pass-Thro-Charges'!$C$157*'Pass-Thro-Charges'!$C$158*'Centre Two-FTE'!H4 | I77: =$C$156*$C$158*'Centre One-FTE'!I4+'Pass-Thro-Charges'!$C$157*'Pass-Thro-Charges'!$C$158*'Centre Two-FTE'!I4 | J77: =($C$156*$C$158*'Centre One-FTE'!J4+'Pass-Thro-Charges'!$C$157*'Pass-Thro-Charges'!$C$158*'Centre Two-FTE'!J4)/12 | K77: =SUM(C77:J77)
J78: 0
...

Sheet Transition Charges
A1: TRANSITION CHARGES (US$)
A3: Description | B3: Q1 | C3: Q2 | D3: Q3 | E3: Q4 | F3: Year 1 | G3: Q1 | H3: Q2 | I3: Q3 | J3: Q4 | K3: Year 2 | L3: Year 3 | M3: Year 4 | N3: Year 5 | O3: Year 6 | P3: Year 7 | Q3: Year 8 | R3: Total
A4: General Accounting & Sox - TRANSITION ONLY
A5: General Accounting & Sox
A6: Labor | B6: 0 | C6: 0 | D6: 8505.8669 | E6: 12244.823 | F6: 20750.69 | G6: 12109.237 | H6: 11973.652 | I6: 11838.066 | J6: 11702.48 | K6: 47623.435 | L6: 45454.065 | M6: 25282.685 | R6: =SUM(K6:Q6)+F6
A7: Hardware/Ship | B7: 0 | C7: 0 | D7: 0 | E7: 0 | F7: 0 | G7: 0 | H7: 0 | I7: 0 | J7: 0 | K7: 0 | L7: 0 | M7: 0 | R7: =SUM(K7:Q7)+F7
A8: Software | B8: 0 | C8: 0 | D8: 0 | E8: 0 | F8: 0 | G8: 0 | H8: 0 | I8: 0 | J8: 0 | K8: 0 | L8: 0 | M8: 0 | R8: =SUM(K8:Q8)+F8
A9: Travel | B9: 1783.4947 | C9: 1763.8958 | D9: 16277.039 | E9: 21431.356 | F9: 41255.785 | G9: 21193.446 | H9: 20955.535 | I9: 20717.625 | J9: 20479.714 | K9: 83346.32 | L9: 79539.752 | M9: 39954.289 | R9: =SUM(K9:Q9)+F9
A10: Hires / M&Ls | B10: 0 | C10: 0 | D10: 0 | E10: 0 | F10: 0 | G10: 0 | H10: 0 | I10: 0 | J10: 0 | K10: 0 | L10: 0 | M10: 0 | R10: =SUM(K10:Q10)+F10
A11: Consulting | B11: 784.66435 | C11: 776.04167 | D11: 4886.5557 | E11: 6863.6671 | F11: 13310.929 | G11: 6787.4605 | H11: 6711.2539 | I11: 6635.0473 | J11: 6558.8407 | K11: 26692.602 | L11: 25473.297 | M11: 12711.141 | R11: =SUM(K11:Q11)+F11
A12: Communications | B12: 0 | C12: 0 | D12: 0 | E12: 0 | F12: 0 | G12: 0 | H12: 0 | I12: 0 | J12: 0 | K12: 0 | L12: 0 | M12: 0 | R12: =SUM(K12:Q12)+F12
A13: TOTAL General Accounting & Sox | B13: 2568.159 | C13: 2539.9375 | D13: 29669.461 | E13: 40539.846 | F13: 75317.404 | G13: 40090.143 | H13: 39640.441 | I13: 39190.738 | J13: 38741.035 | K13: 157662.36 | L13: 150467.11 | M13: 77948.115 | N13: =SUM(N6:N12) | O13: =SUM(O6:O12) | P13: =SUM(P6:P12) | Q13: =SUM(Q6:Q12) | R13: =SUM(R6:R12)
A15: Fixed Assets - TRANSITION ONLY
A16: Fixed Assets
A17: Labor | B17: 0 | C17: 0 | D17: 2175.5816 | E17: 2254.6585 | F17: 4430.2401 | G17: 2229.6193 | H17: 2204.5801 | I17: 2179.5409 | J17: 2154.5017 | K17: 8768.2421 | L17: 8367.6151 | M17: 4124.1081 | R17: =SUM(K17:Q17)+F17
A18: Hardware/Ship | B18: 0 | C18: 0 | D18: 0 | E18: 0 | F18: 0 | G18: 0 | H18: 0 | I18: 0 | J18: 0 | K18: 0 | L18: 0 | M18: 0 | R18: =SUM(K18:Q18)+F18
A19: Software | B19: 0 | C19: 0 | D19: 0 | E19: 0 | F19: 0 | G19: 0 | H19: 0 | I19: 0 | J19: 0 | K19: 0 | L19: 0 | M19: 0 | R19: =SUM(K19:Q19)+F19
A20: Travel | B20: 382.17743 | C20: 377.97768 | D20: 4292.4202 | E20: 4426.8888 | F20: 9479.4641 | G20: 4377.63 | H20: 4328.3712 | I20: 4279.1125 | J20: 4229.8537 | K20: 17214.967 | L20: 16426.827 | M20: 7418.2626 | R20: =SUM(K20:Q20)+F20
A21: Hires / M&Ls | B21: 0 | C21: 0 | D21: 0 | E21: 0 | F21: 0 | G21: 0 | H21: 0 | I21: 0 | J21: 0 | K21: 0 | L21: 0 | M21: 0 | R21: =SUM(K21:Q21)+F21
A22: Consulting | B22: 168.14236 | C22: 166.29464 | D22: 1047.1191 | E22: 1470.7858 | F22: 2852.3419 | G22: 1454.4558 | H22: 1438.1258 | I22: 1421.7958 | J22: 1405.4659 | K22: 5719.8433 | L22: 5458.5636 | M22: 2723.8159 | R22: =SUM(K22:Q22)+F22
A23: Communications | B23: 0 | C23: 0 | D23: 0 | E23: 0 | F23: 0 | G23: 0 | H23: 0 | I23: 0 | J23: 0 | K23: 0 | L23: 0 | M23: 0 | R23: =SUM(K23:Q23)+F23
A24: TOTAL Fixed Assets | B24: 550.31979 | C24: 544.27232 | D24: 7515.1208 | E24: 8152.3331 | F24: 16762.046 | G24: 8061.7051 | H24: 7971.0772 | I24: 7880.4492 | J24: 7789.8213 | K24: 31703.053 | L24: 30253.005 | M24: 14266.187 | N24: =SUM(N17:N23) | O24: =SUM(O17:O23) | P24: =SUM(P17:P23) | Q24: =SUM(Q17:Q23) | R24: =SUM(R17:R23)
A26: Accounts Payable - TRANSITION ONLY
A27: Accounts Payable
A28: Labor | B28: 0 | C28: 0 | D28: 26911.249 | E28: 37669.177 | F28: 64580.426 | G28: 37251.98 | H28: 36834.784 | I28: 36417.587 | J28: 36000.39 | K28: 146504.74 | L28: 139829.59 | M28: 77129.116 | R28: =SUM(K28:Q28)+F28
A29: Hardware/Ship | B29: 0 | C29: 0 | D29: 0 | E29: 0 | F29: 0 | G29: 0 | H29: 0 | I29: 0 | J29: 0 | K29: 0 | L29: 0 | M29: 0 | R29: =SUM(K29:Q29)+F29
A30: Software | B30: 0 | C30: 0 | D30: 0 | E30: 0 | F30: 0 | G30: 0 | H30: 0 | I30: 0 | J30: 0 | K30: 0 | L30: 0 | M30: 0 | R30: =SUM(K30:Q30)+F30
A31: Travel | B31: 7133.9787 | C31: 7055.5833 | D31: 50214.677 | E31: 64267.3 | F31: 128671.54 | G31: 63553.26 | H31: 62839.22 | I31: 62125.18 | J31: 61411.141 | K31: 249928.8 | L31: 238504.16 | M31: 115500.35 | R31: =SUM(K31:Q31)+F31
A32: Hires / M&Ls | B32: 0 | C32: 0 | D32: 0 | E32: 0 | F32: 0 | G32: 0 | H32: 0 | I32: 0 | J32: 0 | K32: 0 | L32: 0 | M32: 0 | R32: =SUM(K32:Q32)+F32
A33: Consulting | B33: 3138.6574 | C33: 3104.1667 | D33: 19546.223 | E33: 27454.668 | F33: 53243.715 | G33: 27149.842 | H33: 26845.015 | I33: 26540.189 | J33: 26235.363 | K33: 106770.41 | L33: 101893.19 | M33: 50844.564 | R33: =SUM(K33:Q33)+F33
A34: Communications | B34: 0 | C34: 0 | D34: 0 | E34: 0 | F34: 0 | G34: 0 | H34: 0 | I34: 0 | J34: 0 | K34: 0 | L34: 0 | M34: 0 | R34: =SUM(K34:Q34)+F34
A35: TOTAL Accounts Payable | B35: 10272.636 | C35: 10159.75 | D35: 96672.149 | E35: 129391.15 | F35: 246495.68 | G35: 127955.08 | H35: 126519.02 | I35: 125082.96 | J35: 123646.89 | K35: 503203.95 | L35: 480226.94 | M35: 243474.03 | N35: =SUM(N28:N34) | O35: =SUM(O28:O34) | P35: =SUM(P28:P34) | Q35: =SUM(Q28:Q34) | R35: =SUM(R28:R34)
A37: T&E - TRANSITION ONLY
A38: T&E
A39: Labor | B39: 0 | C39: 0 | D39: 4424.6192 | E39: 7528.9033 | F39: 11953.522 | G39: 7445.6338 | H39: 7362.3643 | I39: 7279.0947 | J39: 7195.8252 | K39: 29282.918 | L39: 27950.606 | M39: 16247.472 | R39: =SUM(K39:Q39)+F39
A40: Hardware/Ship | B40: 0 | C40: 0 | D40: 0 | E40: 0 | F40: 0 | G40: 0 | H40: 0 | I40: 0 | J40: 0 | K40: 0 | L40: 0 | M40: 0 | R40: =SUM(K40:Q40)+F40
A41: Software | B41: 0 | C41: 0 | D41: 0 | E41: 0 | F41: 0 | G41: 0 | H41: 0 | I41: 0 | J41: 0 | K41: 0 | L41: 0 | M41: 0 | R41: =SUM(K41:Q41)+F41
A42: Travel | B42: 1273.9248 | C42: 1259.9256 | D42: 9306.4165 | E42: 13260.025 | F42: 25100.292 | G42: 13112.876 | H42: 12965.726 | I42: 12818.577 | J42: 12671.427 | K42: 51568.607 | L42: 49214.215 | M42: 25092.218 | R42: =SUM(K42:Q42)+F42
A43: Hires / M&Ls | B43: 0 | C43: 0 | D43: 0 | E43: 0 | F43: 0 | G43: 0 | H43: 0 | I43: 0 | J43: 0 | K43: 0 | L43: 0 | M43: 0 | R43: =SUM(K43:Q43)+F43
A44: Consulting | B44: 560.47454 | C44: 554.31548 | D44: 3490.397 | E44: 4902.6193 | F44: 9507.8063 | G44: 4848.186 | H44: 4793.7528 | I44: 4739.3195 | J44: 4684.8862 | K44: 19066.144 | L44: 18195.212 | M44: 9079.3864 | R44: =SUM(K44:Q44)+F44
...

Sheet Service Provider Investments
A1: SERVICE PROVIDER INVESTMENTS (US$)
B3: Category of Service | C3: Initial Asset Purchase | D3: Year 1 | E3: Year 2 | F3: Year 3 | G3: Year 4 | H3: Year 5 | I3: Year 6 | J3: Year 7 | K3: Total
B5: General Accounting & Sox | K5: =SUM(C5:J5)
B7: Fixed Assets | K7: =SUM(C7:J7)
B9: Accounts Payable | K9: =SUM(C9:J9)
B11: T&E | K11: =SUM(C11:J11)
B13: Order to Cash | K13: =SUM(C13:J13)
B15: Requistion to Pay | K15: =SUM(C15:J15)
A17: TOTAL INVESTMENTS | C17: =SUM(C4:C16) | D17: =SUM(D4:D16) | E17: =SUM(E4:E16) | F17: =SUM(F4:F16) | G17: =SUM(G4:G16) | H17: =SUM(H4:H16) | I17: =SUM(I4:I16) | J17: =SUM(J4:J16) | K17: =SUM(K4:K16)

Sheet Termination Charges
A1: TERMINATION CHARGES (US$)
B2: Category of Services | C2: Year 1 | D2: Year 2 | E2: Year 3 | F2: Year 4 | G2: Year 5 | H2: Year 6 | I2: Year 7 | J2: Year 8
A3: TERMINATION FOR CAUSE
B4: General Accounting & Sox
B5: Fixed Assets
B6: Accounts Payable
B7: T&E
B8: Order to Cash
B9: Requistion to Pay
A10: TOTAL TERMINATION CHARGES
A13: TERMINATION FOR CHANGE OF CONTROL
B14: General Accounting & Sox | C14: 45709.246 | D14: 180755.73 | E14: 167560.56 | F14: 153411.01 | G14: 138261.67 | H14: 122065.3 | I14: 118473.77 | J14: 122027.98
B15: Fixed Assets | C15: 9641.9197 | D15: 22507.469 | E15: 20864.424 | F15: 19102.539 | G15: 17216.163 | H15: 15199.413 | I15: 14752.199 | J15: 15194.765
B16: Accounts Payable | C16: 171143.32 | D16: 610974.51 | E16: 566373.37 | F16: 518546.28 | G16: 467339.84 | H16: 412594.31 | I16: 353650.17 | J16: 363466.78
B17: T&E | C17: 26499.033 | D17: 100771.69 | E17: 93415.352 | F17: 85526.945 | G17: 77081.159 | H17: 68051.652 | I17: 66049.363 | J17: 68030.844
B18: Order to Cash | C18: 39002.952 | D18: 159172.68 | E18: 147553.08 | F18: 135093.04 | G18: 121752.6 | H18: 107490.16 | I18: 104327.46 | J18: 107457.29
B19: Requistion to Pay | C19: 117826.73 | D19: 339146.48 | E19: 314388.79 | F19: 287840.4 | G19: 259416.16 | H19: 229027.41 | I19: 210243.52 | J19: 216550.82
A20: TOTAL TERMINATION CHARGES | C20: =SUM(C14:C19) | D20: =SUM(D14:D19) | E20: =SUM(E14:E19) | F20: =SUM(F14:F19) | G20: =SUM(G14:G19) | H20: =SUM(H14:H19) | I20: =SUM(I14:I19) | J20: =SUM(J14:J19)
A23: TERMINATION FOR CONVENIENCE
B24: General Accounting & Sox | C24: 45709.246 | D24: 278085.74 | E24: 257785.48 | F24: 236016.93 | G24: 212710.26 | H24: 187792.77 | I24: 161188.8 | J24: 132819.57
B25: Fixed Assets | C25: 9641.9197 | D25: 34626.875 | E25: 32099.113 | F25: 29388.521 | G25: 26486.405 | H25: 23383.712 | I25: 20071.019 | J25: 16538.52
B26: Accounts Payable | C26: 171143.32 | D26: 939960.78 | E26: 871343.64 | F26: 797763.51 | G26: 718984.37 | H26: 634760.48 | I26: 544836.08 | J26: 448944.93
B27: T&E | C27: 26499.033 | D27: 155033.36 | E27: 143715.93 | F27: 131579.91 | G27: 118586.4 | H27: 104694.85 | I27: 89863.079 | J27: 74047.177
B28: Order to Cash | C28: 39002.952 | D28: 244881.05 | E28: 227004.74 | F28: 207835.45 | G28: 187311.7 | H28: 165369.47 | I28: 141942.13 | J28: 116960.31
B29: Requistion to Pay | C29: 117826.73 | D29: 521763.81 | E29: 483675.05 | F29: 442831.38 | G29: 399101.78 | H29: 352349.86 | I29: 302433.63 | J29: 249205.31
A30: TOTAL TERMINATION CHARGES | C30: =SUM(C24:C29) | D30: =SUM(D24:D29) | E30: =SUM(E24:E29) | F30: =SUM(F24:F29) | G30: =SUM(G24:G29) | H30: =SUM(H24:H29) | I30: =SUM(I24:I29) | J30: =SUM(J24:J29)
A34: ALGORITHM FOR CALCULATING FEES ON ANY DATE OTHER THAN THE CONTRACT ANNIVERSARY
A35: =A3
A36: =A13 | C36: Termination charges above have been calculated for the given year, i.e. at any point in that year a termination would result in the highligted charges
A37: =A23

Sheet Unit Rates (ARCs & RRCs)
A1: ARC/RRC RATES INPUT FORM
A2: $ RATE CHARGE PER FTE | B2: Year 1 | C2: Year 2 | D2: Year 3 | E2: Year 4 | F2: Year 5 | G2: Year 6 | H2: Year 7 | I2: Year 8
A3: Process Summary
A4: General Accounting & Sox
A5: Centre One | B5: ='Centre One-BC'!C$20/'Centre One-FTE'!C4 | C5: ='Centre One-BC'!D$20/'Centre One-FTE'!D4 | D5: ='Centre One-BC'!E$20/'Centre One-FTE'!E4 | E5: ='Centre One-BC'!F$20/'Centre One-FTE'!F4 | F5: ='Centre One-BC'!G$20/'Centre One-FTE'!G4 | G5: ='Centre One-BC'!H$20/'Centre One-FTE'!H4 | H5: ='Centre One-BC'!I$20/'Centre One-FTE'!I4 | I5: =('Centre One-BC'!J$20/'Centre One-FTE'!J4)*12
A6: Centre Two | B6: ='Centre Two-BC'!C$20/'Centre Two-FTE'!C4 | C6: ='Centre Two-BC'!D$20/'Centre Two-FTE'!D4 | D6: ='Centre Two-BC'!E$20/'Centre Two-FTE'!E4 | E6: ='Centre Two-BC'!F$20/'Centre Two-FTE'!F4 | F6: ='Centre Two-BC'!G$20/'Centre Two-FTE'!G4 | G6: ='Centre Two-BC'!H$20/'Centre Two-FTE'!H4 | H6: ='Centre Two-BC'!I$20/'Centre Two-FTE'!I4 | I6: =('Centre Two-BC'!J$20/'Centre Two-FTE'!J4)*12
A8: Fixed Assets
A9: Centre One | B9: ='Centre One-BC'!C$30/'Centre One-FTE'!C30 | C9: ='Centre One-BC'!D$30/'Centre One-FTE'!D30 | D9: ='Centre One-BC'!E$30/'Centre One-FTE'!E30 | E9: ='Centre One-BC'!F$30/'Centre One-FTE'!F30 | F9: ='Centre One-BC'!G$30/'Centre One-FTE'!G30 | G9: ='Centre One-BC'!H$30/'Centre One-FTE'!H30 | H9: ='Centre One-BC'!I$30/'Centre One-FTE'!I30 | I9: =('Centre One-BC'!J$30/'Centre One-FTE'!J30)*12
A10: Centre Two | B10: ='Centre Two-BC'!C$30/'Centre Two-FTE'!C30 | C10: ='Centre Two-BC'!D$30/'Centre Two-FTE'!D30 | D10: ='Centre Two-BC'!E$30/'Centre Two-FTE'!E30 | E10: ='Centre Two-BC'!F$30/'Centre Two-FTE'!F30 | F10: ='Centre Two-BC'!G$30/'Centre Two-FTE'!G30 | G10: ='Centre Two-BC'!H$30/'Centre Two-FTE'!H30 | H10: ='Centre Two-BC'!I$30/'Centre Two-FTE'!I30 | I10: =('Centre Two-BC'!J$30/'Centre Two-FTE'!J30)*12
A12: Accounts Payable
A13: Centre One | B13: ='Centre One-BC'!C$40/'Centre One-FTE'!C40 | C13: ='Centre One-BC'!D$40/'Centre One-FTE'!D40 | D13: ='Centre One-BC'!E$40/'Centre One-FTE'!E40 | E13: ='Centre One-BC'!F$40/'Centre One-FTE'!F40 | F13: ='Centre One-BC'!G$40/'Centre One-FTE'!G40 | G13: ='Centre One-BC'!H$40/'Centre One-FTE'!H40 | H13: ='Centre One-BC'!I$40/'Centre One-FTE'!I40 | I13: =('Centre One-BC'!J$40/'Centre One-FTE'!J40)*12
A14: Centre Two | B14: ='Centre Two-BC'!C$40/'Centre Two-FTE'!C40 | C14: ='Centre Two-BC'!D$40/'Centre Two-FTE'!D40 | D14: ='Centre Two-BC'!E$40/'Centre Two-FTE'!E40 | E14: ='Centre Two-BC'!F$40/'Centre Two-FTE'!F40 | F14: ='Centre Two-BC'!G$40/'Centre Two-FTE'!G40 | G14: ='Centre Two-BC'!H$40/'Centre Two-FTE'!H40 | H14: ='Centre Two-BC'!I$40/'Centre Two-FTE'!I40 | I14: =('Centre Two-BC'!J$40/'Centre Two-FTE'!J40)*12
A16: T&E
A17: Centre One | B17: ='Centre One-BC'!C$50/'Centre One-FTE'!C50 | C17: ='Centre One-BC'!D$50/'Centre One-FTE'!D50 | D17: ='Centre One-BC'!E$50/'Centre One-FTE'!E50 | E17: ='Centre One-BC'!F$50/'Centre One-FTE'!F50 | F17: ='Centre One-BC'!G$50/'Centre One-FTE'!G50 | G17: ='Centre One-BC'!H$50/'Centre One-FTE'!H50 | H17: ='Centre One-BC'!I$50/'Centre One-FTE'!I50 | I17: =('Centre One-BC'!J$50/'Centre One-FTE'!J50)*12
A18: Centre Two | B18: ='Centre Two-BC'!C$50/'Centre Two-FTE'!C50 | C18: ='Centre Two-BC'!D$50/'Centre Two-FTE'!D50 | D18: ='Centre Two-BC'!E$50/'Centre Two-FTE'!E50 | E18: ='Centre Two-BC'!F$50/'Centre Two-FTE'!F50 | F18: ='Centre Two-BC'!G$50/'Centre Two-FTE'!G50 | G18: ='Centre Two-BC'!H$50/'Centre Two-FTE'!H50 | H18: ='Centre Two-BC'!I$50/'Centre Two-FTE'!I50 | I18: =('Centre Two-BC'!J$50/'Centre Two-FTE'!J50)*12
A20: Order to Cash
A21: Centre One | B21: ='Centre One-BC'!C$60/'Centre One-FTE'!C60 | C21: ='Centre One-BC'!D$60/'Centre One-FTE'!D60 | D21: ='Centre One-BC'!E$60/'Centre One-FTE'!E60 | E21: ='Centre One-BC'!F$60/'Centre One-FTE'!F60 | F21: ='Centre One-BC'!G$60/'Centre One-FTE'!G60 | G21: ='Centre One-BC'!H$60/'Centre One-FTE'!H60 | H21: ='Centre One-BC'!I$60/'Centre One-FTE'!I60 | I21: =('Centre One-BC'!J$60/'Centre One-FTE'!J60)*12
A22: Centre Two | B22: ='Centre Two-BC'!C$60/'Centre Two-FTE'!C60 | C22: ='Centre Two-BC'!D$60/'Centre Two-FTE'!D60 | D22: ='Centre Two-BC'!E$60/'Centre Two-FTE'!E60 | E22: ='Centre Two-BC'!F$60/'Centre Two-FTE'!F60 | F22: ='Centre Two-BC'!G$60/'Centre Two-FTE'!G60 | G22: ='Centre Two-BC'!H$60/'Centre Two-FTE'!H60 | H22: ='Centre Two-BC'!I$60/'Centre Two-FTE'!I60 | I22: =('Centre Two-BC'!J$60/'Centre Two-FTE'!J60)*12
A24: Requistion to Pay
A25: Centre One | B25: ='Centre One-BC'!C$70/'Centre One-FTE'!C70 | C25: ='Centre One-BC'!D$70/'Centre One-FTE'!D70 | D25: ='Centre One-BC'!E$70/'Centre One-FTE'!E70 | E25: ='Centre One-BC'!F$70/'Centre One-FTE'!F70 | F25: ='Centre One-BC'!G$70/'Centre One-FTE'!G70 | G25: ='Centre One-BC'!H$70/'Centre One-FTE'!H70 | H25: ='Centre One-BC'!I$70/'Centre One-FTE'!I70 | I25: =('Centre One-BC'!J$70/'Centre One-FTE'!J70)*12
A26: Centre Two | B26: ='Centre Two-BC'!C$70/'Centre Two-FTE'!C70 | C26: ='Centre Two-BC'!D$70/'Centre Two-FTE'!D70 | D26: ='Centre Two-BC'!E$70/'Centre Two-FTE'!E70 | E26: ='Centre Two-BC'!F$70/'Centre Two-FTE'!F70 | F26: ='Centre Two-BC'!G$70/'Centre Two-FTE'!G70 | G26: ='Centre Two-BC'!H$70/'Centre Two-FTE'!H70 | H26: ='Centre Two-BC'!I$70/'Centre Two-FTE'!I70 | I26: =('Centre Two-BC'!J$70/'Centre Two-FTE'!J70)*12
A28: DEAD BAND % | B28: Year 1 | C28: Year 2 | D28: Year 3 | E28: Year 4 | F28: Year 5 | G28: Year 6 | H28: Year 7 | I28: Year 8
A29: Process Summary
A30: General Accounting & Sox
A31: Centre One | B31: 0.05 | C31: 0.05 | D31: 0.05 | E31: 0.05 | F31: 0.05 | G31: 0.05 | H31: 0.05 | I31: 0.05
A32: Centre Two | B32: 0.05 | C32: 0.05 | D32: 0.05 | E32: 0.05 | F32: 0.05 | G32: 0.05 | H32: 0.05 | I32: 0.05
A34: Fixed Assets
A35: Centre One | B35: 0.05 | C35: 0.05 | D35: 0.05 | E35: 0.05 | F35: 0.05 | G35: 0.05 | H35: 0.05 | I35: 0.05
A36: Centre Two | B36: 0.05 | C36: 0.05 | D36: 0.05 | E36: 0.05 | F36: 0.05 | G36: 0.05 | H36: 0.05 | I36: 0.05
A38: Accounts Payable
A39: Centre One | B39: 0.05 | C39: 0.05 | D39: 0.05 | E39: 0.05 | F39: 0.05 | G39: 0.05 | H39: 0.05 | I39: 0.05
A40: Centre Two | B40: 0.05 | C40: 0.05 | D40: 0.05 | E40: 0.05 | F40: 0.05 | G40: 0.05 | H40: 0.05 | I40: 0.05
A42: T&E
A43: Centre One | B43: 0.05 | C43: 0.05 | D43: 0.05 | E43: 0.05 | F43: 0.05 | G43: 0.05 | H43: 0.05 | I43: 0.05
A44: Centre Two | B44: 0.05 | C44: 0.05 | D44: 0.05 | E44: 0.05 | F44: 0.05 | G44: 0.05 | H44: 0.05 | I44: 0.05
A46: Order to Cash
A47: Centre One | B47: 0.05 | C47: 0.05 | D47: 0.05 | E47: 0.05 | F47: 0.05 | G47: 0.05 | H47: 0.05 | I47: 0.05
A48: Centre Two | B48: 0.05 | C48: 0.05 | D48: 0.05 | E48: 0.05 | F48: 0.05 | G48: 0.05 | H48: 0.05 | I48: 0.05
A50: Requistion to Pay
A51: Centre One | B51: 0.05 | C51: 0.05 | D51: 0.05 | E51: 0.05 | F51: 0.05 | G51: 0.05 | H51: 0.05 | I51: 0.05
...

Sheet Productivity
A1: PRODUCTIVITY % (Change in Base Charge)
B3: Year 1 | C3: Year 2 | D3: Year 3 | E3: Year 4 | F3: Year 5 | G3: Year 6 | H3: Year 7 | I3: Year 8
A4: Process Summary
A6: General Accounting & Sox | B6: 0 | C6: 0 | D6: 0.022916667 | E6: 0.047916667 | F6: 0.072916667 | G6: 0.12083333 | H6: 0.125 | I6: 0.125
A8: Fixed Assets | B8: 0 | C8: 0 | D8: 0.022916667 | E8: 0.047916667 | F8: 0.072916667 | G8: 0.12083333 | H8: 0.125 | I8: 0.125
A10: Accounts Payable | B10: 0 | C10: 0.038277512 | D10: 0.10087719 | E10: 0.15350877 | F10: 0.19005848 | G10: 0.20906433 | H10: 0.22660819 | I10: 0.22807018
A12: T&E | B12: 0 | C12: 0 | D12: 0.022916667 | E12: 0.047916667 | F12: 0.072916667 | G12: 0.12083333 | H12: 0.125 | I12: 0.125
A14: Order to Cash | B14: 0 | C14: 0 | D14: 0.022916667 | E14: 0.047916667 | F14: 0.072916667 | G14: 0.12083333 | H14: 0.125 | I14: 0.125
A16: Requistion to Pay | B16: 0 | C16: 0.02507837 | D16: 0.066091954 | E16: 0.10057471 | F16: 0.13505747 | G16: 0.16954023 | H16: 0.17241379 | I16: 0.17241379
A18: Productivity Measures
B19: Description of Measure | C19: Details of Calculation | D19: Annual Target Level
A20: Process Area | D20: Year 1 | E20: Year 2 | F20: Year 3 | G20: Year 4 | H20: Year 5 | I20: Year 6 | J20: Year 7 | K20: Year 8
A21: General Accounting & Sox | B21: FTE | C21: # FTE to be released (avg. Figures) | D21: 0 | E21: 0 | F21: 0.33229167 | G21: 0.69479167 | H21: 1.0572917 | I21: 1.7520833 | J21: 1.8125 | K21: 1.8125
A25: Fixed Assets | B25: FTE | C25: # FTE to be released (avg. Figures) | D25: 0 | E25: 0 | F25: 0.057291667 | G25: 0.11979167 | H25: 0.18229167 | I25: 0.30208333 | J25: 0.3125 | K25: 0.3125
A29: Accounts Payable | B29: FTE | C29: # FTE to be released (avg. Figures) | D29: 0 | E29: 2 | F29: 5.75 | G29: 8.75 | H29: 10.833333 | I29: 11.916667 | J29: 12.916667 | K29: 13
A33: T&E | B33: FTE | C33: # FTE to be released (avg. Figures) | D33: 0 | E33: 0 | F33: 0.20625 | G33: 0.43125 | H33: 0.65625 | I33: 1.0875 | J33: 1.125 | K33: 1.125
A37: Order To Cash | B37: FTE | C37: # FTE to be released (avg. Figures) | D37: 0 | E37: 0 | F37: 0.32083333 | G37: 0.67083333 | H37: 1.0208333 | I37: 1.6916667 | J37: 1.75 | K37: 1.75
A41: Requistion To Pay | B41: FTE | C41: # FTE to be released (avg. Figures) | D41: 0 | E41: 0.66666667 | F41: 1.9166667 | G41: 2.9166667 | H41: 3.9166667 | I41: 4.9166667 | J41: 5 | K41: 5

Sheet Centre One-BC
A1: BASE CHARGE SUMMARY (US$)
A2: Centre One | C2: Year 1 | D2: Year 2 | E2: Year 3 | F2: Year 4 | G2: Year 5 | H2: Year 6 | I2: Year 7 | J2: Year 8
B3: Process Summary
B4: General Accounting & Sox | C4: =+SUM('Switzerland-BC:UK-BC'!$C3) | D4: =+SUM('Switzerland-BC:UK-BC'!$D3) | E4: =+SUM('Switzerland-BC:UK-BC'!$E3) | F4: =+SUM('Switzerland-BC:UK-BC'!$F3) | G4: =+SUM('Switzerland-BC:UK-BC'!$G3) | H4: =+SUM('Switzerland-BC:UK-BC'!$H3) | I4: =+SUM('Switzerland-BC:UK-BC'!$I3) | J4: =+SUM('Switzerland-BC:UK-BC'!$J3)
B5: Fixed Assets | C5: =+SUM('Switzerland-BC:UK-BC'!$C4) | D5: =+SUM('Switzerland-BC:UK-BC'!$D4) | E5: =+SUM('Switzerland-BC:UK-BC'!$E4) | F5: =+SUM('Switzerland-BC:UK-BC'!$F4) | G5: =+SUM('Switzerland-BC:UK-BC'!$G4) | H5: =+SUM('Switzerland-BC:UK-BC'!$H4) | I5: =+SUM('Switzerland-BC:UK-BC'!$I4) | J5: =+SUM('Switzerland-BC:UK-BC'!$J4)
B6: Accounts Payable | C6: =+SUM('Switzerland-BC:UK-BC'!$C5) | D6: =+SUM('Switzerland-BC:UK-BC'!$D5) | E6: =+SUM('Switzerland-BC:UK-BC'!$E5) | F6: =+SUM('Switzerland-BC:UK-BC'!$F5) | G6: =+SUM('Switzerland-BC:UK-BC'!$G5) | H6: =+SUM('Switzerland-BC:UK-BC'!$H5) | I6: =+SUM('Switzerland-BC:UK-BC'!$I5) | J6: =+SUM('Switzerland-BC:UK-BC'!$J5)
B7: T&E | C7: =+SUM('Switzerland-BC:UK-BC'!$C6) | D7: =+SUM('Switzerland-BC:UK-BC'!$D6) | E7: =+SUM('Switzerland-BC:UK-BC'!$E6) | F7: =+SUM('Switzerland-BC:UK-BC'!$F6) | G7: =+SUM('Switzerland-BC:UK-BC'!$G6) | H7: =+SUM('Switzerland-BC:UK-BC'!$H6) | I7: =+SUM('Switzerland-BC:UK-BC'!$I6) | J7: =+SUM('Switzerland-BC:UK-BC'!$J6)
B8: Order to Cash | C8: =+SUM('Switzerland-BC:UK-BC'!$C7) | D8: =+SUM('Switzerland-BC:UK-BC'!$D7) | E8: =+SUM('Switzerland-BC:UK-BC'!$E7) | F8: =+SUM('Switzerland-BC:UK-BC'!$F7) | G8: =+SUM('Switzerland-BC:UK-BC'!$G7) | H8: =+SUM('Switzerland-BC:UK-BC'!$H7) | I8: =+SUM('Switzerland-BC:UK-BC'!$I7) | J8: =+SUM('Switzerland-BC:UK-BC'!$J7)
B9: Requistion to Pay | C9: =+SUM('Switzerland-BC:UK-BC'!$C8) | D9: =+SUM('Switzerland-BC:UK-BC'!$D8) | E9: =+SUM('Switzerland-BC:UK-BC'!$E8) | F9: =+SUM('Switzerland-BC:UK-BC'!$F8) | G9: =+SUM('Switzerland-BC:UK-BC'!$G8) | H9: =+SUM('Switzerland-BC:UK-BC'!$H8) | I9: =+SUM('Switzerland-BC:UK-BC'!$I8) | J9: =+SUM('Switzerland-BC:UK-BC'!$J8)
B10: Total Base Charge All Countries | C10: =SUM(C4:C9) | D10: =SUM(D4:D9) | E10: =SUM(E4:E9) | F10: =SUM(F4:F9) | G10: =SUM(G4:G9) | H10: =SUM(H4:H9) | I10: =SUM(I4:I9) | J10: =SUM(J4:J9)
B11: General Accounting & Sox
B12: Switzerland | C12: ='Switzerland-BC'!$C$3 | D12: ='Switzerland-BC'!$D$3 | E12: ='Switzerland-BC'!$E$3 | F12: ='Switzerland-BC'!$F$3 | G12: ='Switzerland-BC'!$G$3 | H12: ='Switzerland-BC'!$H$3 | I12: ='Switzerland-BC'!$I$3 | J12: ='Switzerland-BC'!$J$3
B13: United States | C13: ='US-BC'!$C$3 | D13: ='US-BC'!$D$3 | E13: ='US-BC'!$E$3 | F13: ='US-BC'!$F$3 | G13: ='US-BC'!$G$3 | H13: ='US-BC'!$H$3 | I13: ='US-BC'!$I$3 | J13: ='US-BC'!$J$3
B14: France | C14: ='France-BC'!$C$3 | D14: ='France-BC'!$D$3 | E14: ='France-BC'!$E$3 | F14: ='France-BC'!$F$3 | G14: ='France-BC'!$G$3 | H14: ='France-BC'!$H$3 | I14: ='France-BC'!$I$3 | J14: ='France-BC'!$J$3
B15: Germany | C15: ='Germany-BC'!$C$3 | D15: ='Germany-BC'!$D$3 | E15: ='Germany-BC'!$E$3 | F15: ='Germany-BC'!$F$3 | G15: ='Germany-BC'!$G$3 | H15: ='Germany-BC'!$H$3 | I15: ='Germany-BC'!$I$3 | J15: ='Germany-BC'!$J$3
B16: Germany Production | C16: ='Germany Production-BC'!$C$3 | D16: ='Germany Production-BC'!$D$3 | E16: ='Germany Production-BC'!$E$3 | F16: ='Germany Production-BC'!$F$3 | G16: ='Germany Production-BC'!$G$3 | H16: ='Germany Production-BC'!$H$3 | I16: ='Germany Production-BC'!$I$3 | J16: ='Germany Production-BC'!$J$3
B17: Spain | C17: ='Spain-BC'!$C$3 | D17: ='Spain-BC'!$D$3 | E17: ='Spain-BC'!$E$3 | F17: ='Spain-BC'!$F$3 | G17: ='Spain-BC'!$G$3 | H17: ='Spain-BC'!$H$3 | I17: ='Spain-BC'!$I$3 | J17: ='Spain-BC'!$J$3
B18: Italy | C18: ='Italy-BC'!$C$3 | D18: ='Italy-BC'!$D$3 | E18: ='Italy-BC'!$E$3 | F18: ='Italy-BC'!$F$3 | G18: ='Italy-BC'!$G$3 | H18: ='Italy-BC'!$H$3 | I18: ='Italy-BC'!$I$3 | J18: ='Italy-BC'!$J$3
B19: United Kingdom | C19: ='UK-BC'!$C$3 | D19: ='UK-BC'!$D$3 | E19: ='UK-BC'!$E$3 | F19: ='UK-BC'!$F$3 | G19: ='UK-BC'!$G$3 | H19: ='UK-BC'!$H$3 | I19: ='UK-BC'!$I$3 | J19: ='UK-BC'!$J$3
B20: Sub Total | C20: =SUM(C12:C19) | D20: =SUM(D12:D19) | E20: =SUM(E12:E19) | F20: =SUM(F12:F19) | G20: =SUM(G12:G19) | H20: =SUM(H12:H19) | I20: =SUM(I12:I19) | J20: =SUM(J12:J19)
B21: Fixed Assets
B22: Switzerland | C22: ='Switzerland-BC'!$C$4 | D22: ='Switzerland-BC'!$D$4 | E22: ='Switzerland-BC'!$E$4 | F22: ='Switzerland-BC'!$F$4 | G22: ='Switzerland-BC'!$G$4 | H22: ='Switzerland-BC'!$H$4 | I22: ='Switzerland-BC'!$I$4 | J22: ='Switzerland-BC'!$J$4
B23: United States | C23: ='US-BC'!$C$4 | D23: ='US-BC'!$D$4 | E23: ='US-BC'!$E$4 | F23: ='US-BC'!$F$4 | G23: ='US-BC'!$G$4 | H23: ='US-BC'!$H$4 | I23: ='US-BC'!$I$4 | J23: ='US-BC'!$J$4
B24: France | C24: ='France-BC'!$C$4 | D24: ='France-BC'!$D$4 | E24: ='France-BC'!$E$4 | F24: ='France-BC'!$F$4 | G24: ='France-BC'!$G$4 | H24: ='France-BC'!$H$4 | I24: ='France-BC'!$I$4 | J24: ='France-BC'!$J$4
B25: Germany | C25: ='Germany-BC'!$C$4 | D25: ='Germany-BC'!$D$4 | E25: ='Germany-BC'!$E$4 | F25: ='Germany-BC'!$F$4 | G25: ='Germany-BC'!$G$4 | H25: ='Germany-BC'!$H$4 | I25: ='Germany-BC'!$I$4 | J25: ='Germany-BC'!$J$4
B26: Germany Production | C26: ='Germany Production-BC'!$C$4 | D26: ='Germany Production-BC'!$D$4 | E26: ='Germany Production-BC'!$E$4 | F26: ='Germany Production-BC'!$F$4 | G26: ='Germany Production-BC'!$G$4 | H26: ='Germany Production-BC'!$H$4 | I26: ='Germany Production-BC'!$I$4 | J26: ='Germany Production-BC'!$J$4
B27: Spain | C27: ='Spain-BC'!$C$4 | D27: ='Spain-BC'!$D$4 | E27: ='Spain-BC'!$E$4 | F27: ='Spain-BC'!$F$4 | G27: ='Spain-BC'!$G$4 | H27: ='Spain-BC'!$H$4 | I27: ='Spain-BC'!$I$4 | J27: ='Spain-BC'!$J$4
B28: Italy | C28: ='Italy-BC'!$C$4 | D28: ='Italy-BC'!$D$4 | E28: ='Italy-BC'!$E$4 | F28: ='Italy-BC'!$F$4 | G28: ='Italy-BC'!$G$4 | H28: ='Italy-BC'!$H$4 | I28: ='Italy-BC'!$I$4 | J28: ='Italy-BC'!$J$4
B29: United Kingdom | C29: ='UK-BC'!$C$4 | D29: ='UK-BC'!$D$4 | E29: ='UK-BC'!$E$4 | F29: ='UK-BC'!$F$4 | G29: ='UK-BC'!$G$4 | H29: ='UK-BC'!$H$4 | I29: ='UK-BC'!$I$4 | J29: ='UK-BC'!$J$4
B30: Sub Total | C30: =SUM(C22:C29) | D30: =SUM(D22:D29) | E30: =SUM(E22:E29) | F30: =SUM(F22:F29) | G30: =SUM(G22:G29) | H30: =SUM(H22:H29) | I30: =SUM(I22:I29) | J30: =SUM(J22:J29)
B31: Accounts Payable
B32: Switzerland | C32: ='Switzerland-BC'!$C$5 | D32: ='Switzerland-BC'!$D$5 | E32: ='Switzerland-BC'!$E$5 | F32: ='Switzerland-BC'!$F$5 | G32: ='Switzerland-BC'!$G$5 | H32: ='Switzerland-BC'!$H$5 | I32: ='Switzerland-BC'!$I$5 | J32: ='Switzerland-BC'!$J$5
B33: United States | C33: ='US-BC'!$C$5 | D33: ='US-BC'!$D$5 | E33: ='US-BC'!$E$5 | F33: ='US-BC'!$F$5 | G33: ='US-BC'!$G$5 | H33: ='US-BC'!$H$5 | I33: ='US-BC'!$I$5 | J33: ='US-BC'!$J$5
B34: France | C34: ='France-BC'!$C$5 | D34: ='France-BC'!$D$5 | E34: ='France-BC'!$E$5 | F34: ='France-BC'!$F$5 | G34: ='France-BC'!$G$5 | H34: ='France-BC'!$H$5 | I34: ='France-BC'!$I$5 | J34: ='France-BC'!$J$5
B35: Germany | C35: ='Germany-BC'!$C$5 | D35: ='Germany-BC'!$D$5 | E35: ='Germany-BC'!$E$5 | F35: ='Germany-BC'!$F$5 | G35: ='Germany-BC'!$G$5 | H35: ='Germany-BC'!$H$5 | I35: ='Germany-BC'!$I$5 | J35: ='Germany-BC'!$J$5
B36: Germany Production | C36: ='Germany Production-BC'!$C$5 | D36: ='Germany Production-BC'!$D$5 | E36: ='Germany Production-BC'!$E$5 | F36: ='Germany Production-BC'!$F$5 | G36: ='Germany Production-BC'!$G$5 | H36: ='Germany Production-BC'!$H$5 | I36: ='Germany Production-BC'!$I$5 | J36: ='Germany Production-BC'!$J$5
B37: Spain | C37: ='Spain-BC'!$C$5 | D37: ='Spain-BC'!$D$5 | E37: ='Spain-BC'!$E$5 | F37: ='Spain-BC'!$F$5 | G37: ='Spain-BC'!$G$5 | H37: ='Spain-BC'!$H$5 | I37: ='Spain-BC'!$I$5 | J37: ='Spain-BC'!$J$5
B38: Italy | C38: ='Italy-BC'!$C$5 | D38: ='Italy-BC'!$D$5 | E38: ='Italy-BC'!$E$5 | F38: ='Italy-BC'!$F$5 | G38: ='Italy-BC'!$G$5 | H38: ='Italy-BC'!$H$5 | I38: ='Italy-BC'!$I$5 | J38: ='Italy-BC'!$J$5
B39: United Kingdom | C39: ='UK-BC'!$C$5 | D39: ='UK-BC'!$D$5 | E39: ='UK-BC'!$E$5 | F39: ='UK-BC'!$F$5 | G39: ='UK-BC'!$G$5 | H39: ='UK-BC'!$H$5 | I39: ='UK-BC'!$I$5 | J39: ='UK-BC'!$J$5
B40: Sub Total | C40: =SUM(C32:C39) | D40: =SUM(D32:D39) | E40: =SUM(E32:E39) | F40: =SUM(F32:F39) | G40: =SUM(G32:G39) | H40: =SUM(H32:H39) | I40: =SUM(I32:I39) | J40: =SUM(J32:J39)
...

Sheet Switzerland-BC
A1: BASE CHARGES INPUT FORM - CENTRE ONE (US$)
A2: Country | B2: Process Area | C2: Year 1 | D2: Year 2 | E2: Year 3 | F2: Year 4 | G2: Year 5 | H2: Year 6 | I2: Year 7 | J2: Year 8
A3: Switzerland | B3: General Accounting & Sox | C3: =SUM('Appendix B - prod by country'!D2:O3,'Appendix B - prod by country'!D6:O6)*1.3*1000+SUM('Appendix A - pilot by country'!D2:O3,'Appendix A - pilot by country'!D6:O6)*1.3*1000 | D3: =SUM('Appendix B - prod by country'!P2:AA3,'Appendix B - prod by country'!P6:AA6)*1.3*1000 | E3: =SUM('Appendix B - prod by country'!AB2:AM3,'Appendix B - prod by country'!AB6:AM6)*1.3*1000 | F3: =SUM('Appendix B - prod by country'!AN2:AY3,'Appendix B - prod by country'!AN6:AY6)*1.3*1000 | G3: =SUM('Appendix B - prod by country'!AZ2:BK3,'Appendix B - prod by country'!AZ6:BK6)*1.3*1000 | H3: =SUM('Appendix B - prod by country'!BL2:BW3,'Appendix B - prod by country'!BL6:BW6)*1.3*1000 | I3: =SUM('Appendix B - prod by country'!BX2:CI3,'Appendix B - prod by country'!BX6:CI6)*1.3*1000 | J3: =SUM('Appendix B - prod by country'!CJ2:CJ3,'Appendix B - prod by country'!CJ6)*1.3*1000
B4: Fixed Assets | C4: =SUM('Appendix B - prod by country'!D4:O4)*1.3*1000+SUM('Appendix A - pilot by country'!D4:O4)*1.3*1000 | D4: =SUM('Appendix B - prod by country'!P4:AA4)*1.3*1000 | E4: =SUM('Appendix B - prod by country'!AB4:AM4)*1.3*1000 | F4: =SUM('Appendix B - prod by country'!AN4:AY4)*1.3*1000 | G4: =SUM('Appendix B - prod by country'!AZ4:BK4)*1.3*1000 | H4: =SUM('Appendix B - prod by country'!BL4:BW4)*1.3*1000 | I4: =SUM('Appendix B - prod by country'!BX4:CI4)*1.3*1000 | J4: =SUM('Appendix B - prod by country'!CJ4)*1.3*1000
B5: Accounts Payable | C5: =SUM('Appendix B - prod by country'!D5:O5)*1.3*1000+SUM('Appendix A - pilot by country'!D5:O5)*1.3*1000 | D5: =SUM('Appendix B - prod by country'!P5:AA5)*1.3*1000 | E5: =SUM('Appendix B - prod by country'!AB5:AM5)*1.3*1000 | F5: =SUM('Appendix B - prod by country'!AN5:AY5)*1.3*1000 | G5: =SUM('Appendix B - prod by country'!AZ5:BK5)*1.3*1000 | H5: =SUM('Appendix B - prod by country'!BL5:BW5)*1.3*1000 | I5: =SUM('Appendix B - prod by country'!BX5:CI5)*1.3*1000 | J5: =SUM('Appendix B - prod by country'!CJ5)*1.3*1000
B6: T&E | C6: =SUM('Appendix B - prod by country'!D7:O7)*1.3*1000+SUM('Appendix A - pilot by country'!D7:O7)*1.3*1000 | D6: =SUM('Appendix B - prod by country'!P7:AA7)*1.3*1000 | E6: =SUM('Appendix B - prod by country'!AB7:AM7)*1.3*1000 | F6: =SUM('Appendix B - prod by country'!AN7:AY7)*1.3*1000 | G6: =SUM('Appendix B - prod by country'!AZ7:BK7)*1.3*1000 | H6: =SUM('Appendix B - prod by country'!BL7:BW7)*1.3*1000 | I6: =SUM('Appendix B - prod by country'!BX7:CI7)*1.3*1000 | J6: =SUM('Appendix B - prod by country'!CJ7)*1.3*1000
B7: Order to Cash | C7: =SUM('Appendix B - prod by country'!D8:O8)*1.3*1000+SUM('Appendix A - pilot by country'!D8:O8)*1.3*1000 | D7: =SUM('Appendix B - prod by country'!P8:AA8)*1.3*1000 | E7: =SUM('Appendix B - prod by country'!AB8:AM8)*1.3*1000 | F7: =SUM('Appendix B - prod by country'!AN8:AY8)*1.3*1000 | G7: =SUM('Appendix B - prod by country'!AZ8:BK8)*1.3*1000 | H7: =SUM('Appendix B - prod by country'!BL8:BW8)*1.3*1000 | I7: =SUM('Appendix B - prod by country'!BX8:CI8)*1.3*1000 | J7: =SUM('Appendix B - prod by country'!CJ8)*1.3*1000
B8: Requistion to Pay | C8: =SUM('Appendix B - prod by country'!D9:O9)*1.3*1000+SUM('Appendix A - pilot by country'!D9:O9)*1.3*1000 | D8: =SUM('Appendix B - prod by country'!P9:AA9)*1.3*1000 | E8: =SUM('Appendix B - prod by country'!AB9:AM9)*1.3*1000 | F8: =SUM('Appendix B - prod by country'!AN9:AY9)*1.3*1000 | G8: =SUM('Appendix B - prod by country'!AZ9:BK9)*1.3*1000 | H8: =SUM('Appendix B - prod by country'!BL9:BW9)*1.3*1000 | I8: =SUM('Appendix B - prod by country'!BX9:CI9)*1.3*1000 | J8: =SUM('Appendix B - prod by country'!CJ9)*1.3*1000
B9: TOTAL BASE CHARGES | C9: =SUM(C3:C8) | D9: =SUM(D3:D8) | E9: =SUM(E3:E8) | F9: =SUM(F3:F8) | G9: =SUM(G3:G8) | H9: =SUM(H3:H8) | I9: =SUM(I3:I8) | J9: =SUM(J3:J8)

Sheet US-BC
A1: BASE CHARGES INPUT FORM - CENTRE ONE (US$)
A2: Country | B2: Process Area | C2: Year 1 | D2: Year 2 | E2: Year 3 | F2: Year 4 | G2: Year 5 | H2: Year 6 | I2: Year 7
A3: United States | B3: General Accounting & Sox
B4: Fixed Assets
B5: Accounts Payable
B6: T&E
B7: Order to Cash
B8: Requistion to Pay
B9: TOTAL BASE CHARGES | C9: =SUM(C3:C8) | D9: =SUM(D3:D8) | E9: =SUM(E3:E8) | F9: =SUM(F3:F8) | G9: =SUM(G3:G8) | H9: =SUM(H3:H8) | I9: =SUM(I3:I8)

Sheet France-BC
A1: BASE CHARGES INPUT FORM - CENTRE ONE (US$)
A2: Country | B2: Process Area | C2: Year 1 | D2: Year 2 | E2: Year 3 | F2: Year 4 | G2: Year 5 | H2: Year 6 | I2: Year 7 | J2: Year 8
A3: France | B3: General Accounting & Sox | C3: =SUM('Appendix B - prod by country'!D24:O25,'Appendix B - prod by country'!D28:O28)*1.3*1000+SUM('Appendix A - pilot by country'!D24:O25,'Appendix A - pilot by country'!D28:O28)*1.3*1000 | D3: =SUM('Appendix B - prod by country'!P24:AA25,'Appendix B - prod by country'!P28:AA28)*1.3*1000 | E3: =SUM('Appendix B - prod by country'!AB24:AM25,'Appendix B - prod by country'!AB28:AM28)*1.3*1000 | F3: =SUM('Appendix B - prod by country'!AN24:AY25,'Appendix B - prod by country'!AN28:AY28)*1.3*1000 | G3: =SUM('Appendix B - prod by country'!AZ24:BK25,'Appendix B - prod by country'!AZ28:BK28)*1.3*1000 | H3: =SUM('Appendix B - prod by country'!BL24:BW25,'Appendix B - prod by country'!BL28:BW28)*1.3*1000 | I3: =SUM('Appendix B - prod by country'!BX24:CI25,'Appendix B - prod by country'!BX28:CI28)*1.3*1000 | J3: =SUM('Appendix B - prod by country'!CJ24:CJ25,'Appendix B - prod by country'!CJ28)*1.3*1000
B4: Fixed Assets | C4: =SUM('Appendix B - prod by country'!D26:O26)*1.3*1000+SUM('Appendix A - pilot by country'!D26:O26)*1.3*1000 | D4: =SUM('Appendix B - prod by country'!P26:AA26)*1.3*1000 | E4: =SUM('Appendix B - prod by country'!AB26:AM26)*1.3*1000 | F4: =SUM('Appendix B - prod by country'!AN26:AY26)*1.3*1000 | G4: =SUM('Appendix B - prod by country'!AZ26:BK26)*1.3*1000 | H4: =SUM('Appendix B - prod by country'!BL26:BW26)*1.3*1000 | I4: =SUM('Appendix B - prod by country'!BX26:CI26)*1.3*1000 | J4: =SUM('Appendix B - prod by country'!CJ26)*1.3*1000
B5: Accounts Payable | C5: =SUM('Appendix B - prod by country'!D27:O27)*1.3*1000+SUM('Appendix A - pilot by country'!D27:O27)*1.3*1000 | D5: =SUM('Appendix B - prod by country'!P27:AA27)*1.3*1000 | E5: =SUM('Appendix B - prod by country'!AB27:AM27)*1.3*1000 | F5: =SUM('Appendix B - prod by country'!AN27:AY27)*1.3*1000 | G5: =SUM('Appendix B - prod by country'!AZ27:BK27)*1.3*1000 | H5: =SUM('Appendix B - prod by country'!BL27:BW27)*1.3*1000 | I5: =SUM('Appendix B - prod by country'!BX27:CI27)*1.3*1000 | J5: =SUM('Appendix B - prod by country'!CJ27)*1.3*1000
